Exception in thread Thread-1:
Traceback (most recent call last):
  File "/home/beast/anaconda3/envs/srikar/lib/python3.6/site-packages/redis/connection.py", line 185, in _read_from_socket
    raise socket.error(SERVER_CLOSED_CONNECTION_ERROR)
OSError: Connection closed by server.

During handling of the above exception, another exception occurred:

Traceback (most recent call last):
  File "/home/beast/anaconda3/envs/srikar/lib/python3.6/threading.py", line 916, in _bootstrap_inner
    self.run()
  File "/home/beast/anaconda3/envs/srikar/lib/python3.6/site-packages/ray/dashboard/dashboard.py", line 273, in run
    for x in p.listen():
  File "/home/beast/anaconda3/envs/srikar/lib/python3.6/site-packages/redis/client.py", line 3123, in listen
    response = self.handle_message(self.parse_response(block=True))
  File "/home/beast/anaconda3/envs/srikar/lib/python3.6/site-packages/redis/client.py", line 3036, in parse_response
    return self._execute(connection, connection.read_response)
  File "/home/beast/anaconda3/envs/srikar/lib/python3.6/site-packages/redis/client.py", line 3013, in _execute
    return command(*args)
  File "/home/beast/anaconda3/envs/srikar/lib/python3.6/site-packages/redis/connection.py", line 637, in read_response
    response = self._parser.read_response()
  File "/home/beast/anaconda3/envs/srikar/lib/python3.6/site-packages/redis/connection.py", line 290, in read_response
    response = self._buffer.readline()
  File "/home/beast/anaconda3/envs/srikar/lib/python3.6/site-packages/redis/connection.py", line 224, in readline
    self._read_from_socket()
  File "/home/beast/anaconda3/envs/srikar/lib/python3.6/site-packages/redis/connection.py", line 199, in _read_from_socket
    (e.args,))
redis.exceptions.ConnectionError: Error while reading from socket: ('Connection closed by server.',)

