Ray worker pid: 27737
WARNING:root:Setting up a new session...
Traceback (most recent call last):
  File "/home/beast/anaconda3/envs/srikar/lib/python3.6/site-packages/urllib3/connection.py", line 160, in _new_conn
    (self._dns_host, self.port), self.timeout, **extra_kw)
  File "/home/beast/anaconda3/envs/srikar/lib/python3.6/site-packages/urllib3/util/connection.py", line 80, in create_connection
    raise err
  File "/home/beast/anaconda3/envs/srikar/lib/python3.6/site-packages/urllib3/util/connection.py", line 70, in create_connection
    sock.connect(sa)
ConnectionRefusedError: [Errno 111] Connection refused

During handling of the above exception, another exception occurred:

Traceback (most recent call last):
  File "/home/beast/anaconda3/envs/srikar/lib/python3.6/site-packages/urllib3/connectionpool.py", line 603, in urlopen
    chunked=chunked)
  File "/home/beast/anaconda3/envs/srikar/lib/python3.6/site-packages/urllib3/connectionpool.py", line 355, in _make_request
    conn.request(method, url, **httplib_request_kw)
  File "/home/beast/anaconda3/envs/srikar/lib/python3.6/http/client.py", line 1239, in request
    self._send_request(method, url, body, headers, encode_chunked)
  File "/home/beast/anaconda3/envs/srikar/lib/python3.6/http/client.py", line 1285, in _send_request
    self.endheaders(body, encode_chunked=encode_chunked)
  File "/home/beast/anaconda3/envs/srikar/lib/python3.6/http/client.py", line 1234, in endheaders
    self._send_output(message_body, encode_chunked=encode_chunked)
  File "/home/beast/anaconda3/envs/srikar/lib/python3.6/http/client.py", line 1026, in _send_output
    self.send(msg)
  File "/home/beast/anaconda3/envs/srikar/lib/python3.6/http/client.py", line 964, in send
    self.connect()
  File "/home/beast/anaconda3/envs/srikar/lib/python3.6/site-packages/urllib3/connection.py", line 183, in connect
    conn = self._new_conn()
  File "/home/beast/anaconda3/envs/srikar/lib/python3.6/site-packages/urllib3/connection.py", line 169, in _new_conn
    self, "Failed to establish a new connection: %s" % e)
urllib3.exceptions.NewConnectionError: <urllib3.connection.HTTPConnection object at 0x7efabf5f8198>: Failed to establish a new connection: [Errno 111] Connection refused

During handling of the above exception, another exception occurred:

Traceback (most recent call last):
  File "/home/beast/anaconda3/envs/srikar/lib/python3.6/site-packages/requests/adapters.py", line 449, in send
    timeout=timeout
  File "/home/beast/anaconda3/envs/srikar/lib/python3.6/site-packages/urllib3/connectionpool.py", line 641, in urlopen
    _stacktrace=sys.exc_info()[2])
  File "/home/beast/anaconda3/envs/srikar/lib/python3.6/site-packages/urllib3/util/retry.py", line 399, in increment
    raise MaxRetryError(_pool, url, error or ResponseError(cause))
urllib3.exceptions.MaxRetryError: HTTPConnectionPool(host='localhost', port=8097): Max retries exceeded with url: /env/main (Caused by NewConnectionError('<urllib3.connection.HTTPConnection object at 0x7efabf5f8198>: Failed to establish a new connection: [Errno 111] Connection refused',))

During handling of the above exception, another exception occurred:

Traceback (most recent call last):
  File "/home/beast/anaconda3/envs/srikar/lib/python3.6/site-packages/visdom/__init__.py", line 548, in _send
    data=json.dumps(msg),
  File "/home/beast/anaconda3/envs/srikar/lib/python3.6/site-packages/requests/sessions.py", line 581, in post
    return self.request('POST', url, data=data, json=json, **kwargs)
  File "/home/beast/anaconda3/envs/srikar/lib/python3.6/site-packages/requests/sessions.py", line 533, in request
    resp = self.send(prep, **send_kwargs)
  File "/home/beast/anaconda3/envs/srikar/lib/python3.6/site-packages/requests/sessions.py", line 646, in send
    r = adapter.send(request, **kwargs)
  File "/home/beast/anaconda3/envs/srikar/lib/python3.6/site-packages/requests/adapters.py", line 516, in send
    raise ConnectionError(e, request=request)
requests.exceptions.ConnectionError: HTTPConnectionPool(host='localhost', port=8097): Max retries exceeded with url: /env/main (Caused by NewConnectionError('<urllib3.connection.HTTPConnection object at 0x7efabf5f8198>: Failed to establish a new connection: [Errno 111] Connection refused',))
ERROR:visdom:[Errno 111] Connection refused
Traceback (most recent call last):
  File "/home/beast/anaconda3/envs/srikar/lib/python3.6/site-packages/urllib3/connection.py", line 160, in _new_conn
    (self._dns_host, self.port), self.timeout, **extra_kw)
  File "/home/beast/anaconda3/envs/srikar/lib/python3.6/site-packages/urllib3/util/connection.py", line 80, in create_connection
    raise err
  File "/home/beast/anaconda3/envs/srikar/lib/python3.6/site-packages/urllib3/util/connection.py", line 70, in create_connection
    sock.connect(sa)
ConnectionRefusedError: [Errno 111] Connection refused

During handling of the above exception, another exception occurred:

Traceback (most recent call last):
  File "/home/beast/anaconda3/envs/srikar/lib/python3.6/site-packages/urllib3/connectionpool.py", line 603, in urlopen
    chunked=chunked)
  File "/home/beast/anaconda3/envs/srikar/lib/python3.6/site-packages/urllib3/connectionpool.py", line 355, in _make_request
    conn.request(method, url, **httplib_request_kw)
  File "/home/beast/anaconda3/envs/srikar/lib/python3.6/http/client.py", line 1239, in request
    self._send_request(method, url, body, headers, encode_chunked)
  File "/home/beast/anaconda3/envs/srikar/lib/python3.6/http/client.py", line 1285, in _send_request
    self.endheaders(body, encode_chunked=encode_chunked)
  File "/home/beast/anaconda3/envs/srikar/lib/python3.6/http/client.py", line 1234, in endheaders
    self._send_output(message_body, encode_chunked=encode_chunked)
  File "/home/beast/anaconda3/envs/srikar/lib/python3.6/http/client.py", line 1026, in _send_output
    self.send(msg)
  File "/home/beast/anaconda3/envs/srikar/lib/python3.6/http/client.py", line 964, in send
    self.connect()
  File "/home/beast/anaconda3/envs/srikar/lib/python3.6/site-packages/urllib3/connection.py", line 183, in connect
    conn = self._new_conn()
  File "/home/beast/anaconda3/envs/srikar/lib/python3.6/site-packages/urllib3/connection.py", line 169, in _new_conn
    self, "Failed to establish a new connection: %s" % e)
urllib3.exceptions.NewConnectionError: <urllib3.connection.HTTPConnection object at 0x7efabf657e10>: Failed to establish a new connection: [Errno 111] Connection refused

During handling of the above exception, another exception occurred:

Traceback (most recent call last):
  File "/home/beast/anaconda3/envs/srikar/lib/python3.6/site-packages/requests/adapters.py", line 449, in send
    timeout=timeout
  File "/home/beast/anaconda3/envs/srikar/lib/python3.6/site-packages/urllib3/connectionpool.py", line 641, in urlopen
    _stacktrace=sys.exc_info()[2])
  File "/home/beast/anaconda3/envs/srikar/lib/python3.6/site-packages/urllib3/util/retry.py", line 399, in increment
    raise MaxRetryError(_pool, url, error or ResponseError(cause))
urllib3.exceptions.MaxRetryError: HTTPConnectionPool(host='localhost', port=8097): Max retries exceeded with url: /events (Caused by NewConnectionError('<urllib3.connection.HTTPConnection object at 0x7efabf657e10>: Failed to establish a new connection: [Errno 111] Connection refused',))

During handling of the above exception, another exception occurred:

Traceback (most recent call last):
  File "/home/beast/anaconda3/envs/srikar/lib/python3.6/site-packages/visdom/__init__.py", line 548, in _send
    data=json.dumps(msg),
  File "/home/beast/anaconda3/envs/srikar/lib/python3.6/site-packages/requests/sessions.py", line 581, in post
    return self.request('POST', url, data=data, json=json, **kwargs)
  File "/home/beast/anaconda3/envs/srikar/lib/python3.6/site-packages/requests/sessions.py", line 533, in request
    resp = self.send(prep, **send_kwargs)
  File "/home/beast/anaconda3/envs/srikar/lib/python3.6/site-packages/requests/sessions.py", line 646, in send
    r = adapter.send(request, **kwargs)
  File "/home/beast/anaconda3/envs/srikar/lib/python3.6/site-packages/requests/adapters.py", line 516, in send
    raise ConnectionError(e, request=request)
requests.exceptions.ConnectionError: HTTPConnectionPool(host='localhost', port=8097): Max retries exceeded with url: /events (Caused by NewConnectionError('<urllib3.connection.HTTPConnection object at 0x7efabf657e10>: Failed to establish a new connection: [Errno 111] Connection refused',))
Traceback (most recent call last):
  File "/home/beast/anaconda3/envs/srikar/lib/python3.6/site-packages/urllib3/connection.py", line 160, in _new_conn
    (self._dns_host, self.port), self.timeout, **extra_kw)
  File "/home/beast/anaconda3/envs/srikar/lib/python3.6/site-packages/urllib3/util/connection.py", line 80, in create_connection
    raise err
  File "/home/beast/anaconda3/envs/srikar/lib/python3.6/site-packages/urllib3/util/connection.py", line 70, in create_connection
    sock.connect(sa)
ConnectionRefusedError: [Errno 111] Connection refused

During handling of the above exception, another exception occurred:

Traceback (most recent call last):
  File "/home/beast/anaconda3/envs/srikar/lib/python3.6/site-packages/urllib3/connectionpool.py", line 603, in urlopen
    chunked=chunked)
  File "/home/beast/anaconda3/envs/srikar/lib/python3.6/site-packages/urllib3/connectionpool.py", line 355, in _make_request
    conn.request(method, url, **httplib_request_kw)
  File "/home/beast/anaconda3/envs/srikar/lib/python3.6/http/client.py", line 1239, in request
    self._send_request(method, url, body, headers, encode_chunked)
  File "/home/beast/anaconda3/envs/srikar/lib/python3.6/http/client.py", line 1285, in _send_request
    self.endheaders(body, encode_chunked=encode_chunked)
  File "/home/beast/anaconda3/envs/srikar/lib/python3.6/http/client.py", line 1234, in endheaders
    self._send_output(message_body, encode_chunked=encode_chunked)
  File "/home/beast/anaconda3/envs/srikar/lib/python3.6/http/client.py", line 1026, in _send_output
    self.send(msg)
  File "/home/beast/anaconda3/envs/srikar/lib/python3.6/http/client.py", line 964, in send
    self.connect()
  File "/home/beast/anaconda3/envs/srikar/lib/python3.6/site-packages/urllib3/connection.py", line 183, in connect
    conn = self._new_conn()
  File "/home/beast/anaconda3/envs/srikar/lib/python3.6/site-packages/urllib3/connection.py", line 169, in _new_conn
    self, "Failed to establish a new connection: %s" % e)
urllib3.exceptions.NewConnectionError: <urllib3.connection.HTTPConnection object at 0x7efabf374668>: Failed to establish a new connection: [Errno 111] Connection refused

During handling of the above exception, another exception occurred:

Traceback (most recent call last):
  File "/home/beast/anaconda3/envs/srikar/lib/python3.6/site-packages/requests/adapters.py", line 449, in send
    timeout=timeout
  File "/home/beast/anaconda3/envs/srikar/lib/python3.6/site-packages/urllib3/connectionpool.py", line 641, in urlopen
    _stacktrace=sys.exc_info()[2])
  File "/home/beast/anaconda3/envs/srikar/lib/python3.6/site-packages/urllib3/util/retry.py", line 399, in increment
    raise MaxRetryError(_pool, url, error or ResponseError(cause))
urllib3.exceptions.MaxRetryError: HTTPConnectionPool(host='localhost', port=8097): Max retries exceeded with url: /events (Caused by NewConnectionError('<urllib3.connection.HTTPConnection object at 0x7efabf374668>: Failed to establish a new connection: [Errno 111] Connection refused',))

During handling of the above exception, another exception occurred:

Traceback (most recent call last):
  File "/home/beast/anaconda3/envs/srikar/lib/python3.6/site-packages/visdom/__init__.py", line 548, in _send
    data=json.dumps(msg),
  File "/home/beast/anaconda3/envs/srikar/lib/python3.6/site-packages/requests/sessions.py", line 581, in post
    return self.request('POST', url, data=data, json=json, **kwargs)
  File "/home/beast/anaconda3/envs/srikar/lib/python3.6/site-packages/requests/sessions.py", line 533, in request
    resp = self.send(prep, **send_kwargs)
  File "/home/beast/anaconda3/envs/srikar/lib/python3.6/site-packages/requests/sessions.py", line 646, in send
    r = adapter.send(request, **kwargs)
  File "/home/beast/anaconda3/envs/srikar/lib/python3.6/site-packages/requests/adapters.py", line 516, in send
    raise ConnectionError(e, request=request)
requests.exceptions.ConnectionError: HTTPConnectionPool(host='localhost', port=8097): Max retries exceeded with url: /events (Caused by NewConnectionError('<urllib3.connection.HTTPConnection object at 0x7efabf374668>: Failed to establish a new connection: [Errno 111] Connection refused',))
Traceback (most recent call last):
  File "/home/beast/anaconda3/envs/srikar/lib/python3.6/site-packages/urllib3/connection.py", line 160, in _new_conn
    (self._dns_host, self.port), self.timeout, **extra_kw)
  File "/home/beast/anaconda3/envs/srikar/lib/python3.6/site-packages/urllib3/util/connection.py", line 80, in create_connection
    raise err
  File "/home/beast/anaconda3/envs/srikar/lib/python3.6/site-packages/urllib3/util/connection.py", line 70, in create_connection
    sock.connect(sa)
ConnectionRefusedError: [Errno 111] Connection refused

During handling of the above exception, another exception occurred:

Traceback (most recent call last):
  File "/home/beast/anaconda3/envs/srikar/lib/python3.6/site-packages/urllib3/connectionpool.py", line 603, in urlopen
    chunked=chunked)
  File "/home/beast/anaconda3/envs/srikar/lib/python3.6/site-packages/urllib3/connectionpool.py", line 355, in _make_request
    conn.request(method, url, **httplib_request_kw)
  File "/home/beast/anaconda3/envs/srikar/lib/python3.6/http/client.py", line 1239, in request
    self._send_request(method, url, body, headers, encode_chunked)
  File "/home/beast/anaconda3/envs/srikar/lib/python3.6/http/client.py", line 1285, in _send_request
    self.endheaders(body, encode_chunked=encode_chunked)
  File "/home/beast/anaconda3/envs/srikar/lib/python3.6/http/client.py", line 1234, in endheaders
    self._send_output(message_body, encode_chunked=encode_chunked)
  File "/home/beast/anaconda3/envs/srikar/lib/python3.6/http/client.py", line 1026, in _send_output
    self.send(msg)
  File "/home/beast/anaconda3/envs/srikar/lib/python3.6/http/client.py", line 964, in send
    self.connect()
  File "/home/beast/anaconda3/envs/srikar/lib/python3.6/site-packages/urllib3/connection.py", line 183, in connect
    conn = self._new_conn()
  File "/home/beast/anaconda3/envs/srikar/lib/python3.6/site-packages/urllib3/connection.py", line 169, in _new_conn
    self, "Failed to establish a new connection: %s" % e)
urllib3.exceptions.NewConnectionError: <urllib3.connection.HTTPConnection object at 0x7eff89382eb8>: Failed to establish a new connection: [Errno 111] Connection refused

During handling of the above exception, another exception occurred:

Traceback (most recent call last):
  File "/home/beast/anaconda3/envs/srikar/lib/python3.6/site-packages/requests/adapters.py", line 449, in send
    timeout=timeout
  File "/home/beast/anaconda3/envs/srikar/lib/python3.6/site-packages/urllib3/connectionpool.py", line 641, in urlopen
    _stacktrace=sys.exc_info()[2])
  File "/home/beast/anaconda3/envs/srikar/lib/python3.6/site-packages/urllib3/util/retry.py", line 399, in increment
    raise MaxRetryError(_pool, url, error or ResponseError(cause))
urllib3.exceptions.MaxRetryError: HTTPConnectionPool(host='localhost', port=8097): Max retries exceeded with url: /events (Caused by NewConnectionError('<urllib3.connection.HTTPConnection object at 0x7eff89382eb8>: Failed to establish a new connection: [Errno 111] Connection refused',))

During handling of the above exception, another exception occurred:

Traceback (most recent call last):
  File "/home/beast/anaconda3/envs/srikar/lib/python3.6/site-packages/visdom/__init__.py", line 548, in _send
    data=json.dumps(msg),
  File "/home/beast/anaconda3/envs/srikar/lib/python3.6/site-packages/requests/sessions.py", line 581, in post
    return self.request('POST', url, data=data, json=json, **kwargs)
  File "/home/beast/anaconda3/envs/srikar/lib/python3.6/site-packages/requests/sessions.py", line 533, in request
    resp = self.send(prep, **send_kwargs)
  File "/home/beast/anaconda3/envs/srikar/lib/python3.6/site-packages/requests/sessions.py", line 646, in send
    r = adapter.send(request, **kwargs)
  File "/home/beast/anaconda3/envs/srikar/lib/python3.6/site-packages/requests/adapters.py", line 516, in send
    raise ConnectionError(e, request=request)
requests.exceptions.ConnectionError: HTTPConnectionPool(host='localhost', port=8097): Max retries exceeded with url: /events (Caused by NewConnectionError('<urllib3.connection.HTTPConnection object at 0x7eff89382eb8>: Failed to establish a new connection: [Errno 111] Connection refused',))
Traceback (most recent call last):
  File "/home/beast/anaconda3/envs/srikar/lib/python3.6/site-packages/urllib3/connection.py", line 160, in _new_conn
    (self._dns_host, self.port), self.timeout, **extra_kw)
  File "/home/beast/anaconda3/envs/srikar/lib/python3.6/site-packages/urllib3/util/connection.py", line 80, in create_connection
    raise err
  File "/home/beast/anaconda3/envs/srikar/lib/python3.6/site-packages/urllib3/util/connection.py", line 70, in create_connection
    sock.connect(sa)
ConnectionRefusedError: [Errno 111] Connection refused

During handling of the above exception, another exception occurred:

Traceback (most recent call last):
  File "/home/beast/anaconda3/envs/srikar/lib/python3.6/site-packages/urllib3/connectionpool.py", line 603, in urlopen
    chunked=chunked)
  File "/home/beast/anaconda3/envs/srikar/lib/python3.6/site-packages/urllib3/connectionpool.py", line 355, in _make_request
    conn.request(method, url, **httplib_request_kw)
  File "/home/beast/anaconda3/envs/srikar/lib/python3.6/http/client.py", line 1239, in request
    self._send_request(method, url, body, headers, encode_chunked)
  File "/home/beast/anaconda3/envs/srikar/lib/python3.6/http/client.py", line 1285, in _send_request
    self.endheaders(body, encode_chunked=encode_chunked)
  File "/home/beast/anaconda3/envs/srikar/lib/python3.6/http/client.py", line 1234, in endheaders
    self._send_output(message_body, encode_chunked=encode_chunked)
  File "/home/beast/anaconda3/envs/srikar/lib/python3.6/http/client.py", line 1026, in _send_output
    self.send(msg)
  File "/home/beast/anaconda3/envs/srikar/lib/python3.6/http/client.py", line 964, in send
    self.connect()
  File "/home/beast/anaconda3/envs/srikar/lib/python3.6/site-packages/urllib3/connection.py", line 183, in connect
    conn = self._new_conn()
  File "/home/beast/anaconda3/envs/srikar/lib/python3.6/site-packages/urllib3/connection.py", line 169, in _new_conn
    self, "Failed to establish a new connection: %s" % e)
urllib3.exceptions.NewConnectionError: <urllib3.connection.HTTPConnection object at 0x7efabf374e48>: Failed to establish a new connection: [Errno 111] Connection refused

During handling of the above exception, another exception occurred:

Traceback (most recent call last):
  File "/home/beast/anaconda3/envs/srikar/lib/python3.6/site-packages/requests/adapters.py", line 449, in send
    timeout=timeout
  File "/home/beast/anaconda3/envs/srikar/lib/python3.6/site-packages/urllib3/connectionpool.py", line 641, in urlopen
    _stacktrace=sys.exc_info()[2])
  File "/home/beast/anaconda3/envs/srikar/lib/python3.6/site-packages/urllib3/util/retry.py", line 399, in increment
    raise MaxRetryError(_pool, url, error or ResponseError(cause))
urllib3.exceptions.MaxRetryError: HTTPConnectionPool(host='localhost', port=8097): Max retries exceeded with url: /events (Caused by NewConnectionError('<urllib3.connection.HTTPConnection object at 0x7efabf374e48>: Failed to establish a new connection: [Errno 111] Connection refused',))

During handling of the above exception, another exception occurred:

Traceback (most recent call last):
  File "/home/beast/anaconda3/envs/srikar/lib/python3.6/site-packages/visdom/__init__.py", line 548, in _send
    data=json.dumps(msg),
  File "/home/beast/anaconda3/envs/srikar/lib/python3.6/site-packages/requests/sessions.py", line 581, in post
    return self.request('POST', url, data=data, json=json, **kwargs)
  File "/home/beast/anaconda3/envs/srikar/lib/python3.6/site-packages/requests/sessions.py", line 533, in request
    resp = self.send(prep, **send_kwargs)
  File "/home/beast/anaconda3/envs/srikar/lib/python3.6/site-packages/requests/sessions.py", line 646, in send
    r = adapter.send(request, **kwargs)
  File "/home/beast/anaconda3/envs/srikar/lib/python3.6/site-packages/requests/adapters.py", line 516, in send
    raise ConnectionError(e, request=request)
requests.exceptions.ConnectionError: HTTPConnectionPool(host='localhost', port=8097): Max retries exceeded with url: /events (Caused by NewConnectionError('<urllib3.connection.HTTPConnection object at 0x7efabf374e48>: Failed to establish a new connection: [Errno 111] Connection refused',))
Traceback (most recent call last):
  File "/home/beast/anaconda3/envs/srikar/lib/python3.6/site-packages/urllib3/connection.py", line 160, in _new_conn
    (self._dns_host, self.port), self.timeout, **extra_kw)
  File "/home/beast/anaconda3/envs/srikar/lib/python3.6/site-packages/urllib3/util/connection.py", line 80, in create_connection
    raise err
  File "/home/beast/anaconda3/envs/srikar/lib/python3.6/site-packages/urllib3/util/connection.py", line 70, in create_connection
    sock.connect(sa)
ConnectionRefusedError: [Errno 111] Connection refused

During handling of the above exception, another exception occurred:

Traceback (most recent call last):
  File "/home/beast/anaconda3/envs/srikar/lib/python3.6/site-packages/urllib3/connectionpool.py", line 603, in urlopen
    chunked=chunked)
  File "/home/beast/anaconda3/envs/srikar/lib/python3.6/site-packages/urllib3/connectionpool.py", line 355, in _make_request
    conn.request(method, url, **httplib_request_kw)
  File "/home/beast/anaconda3/envs/srikar/lib/python3.6/http/client.py", line 1239, in request
    self._send_request(method, url, body, headers, encode_chunked)
  File "/home/beast/anaconda3/envs/srikar/lib/python3.6/http/client.py", line 1285, in _send_request
    self.endheaders(body, encode_chunked=encode_chunked)
  File "/home/beast/anaconda3/envs/srikar/lib/python3.6/http/client.py", line 1234, in endheaders
    self._send_output(message_body, encode_chunked=encode_chunked)
  File "/home/beast/anaconda3/envs/srikar/lib/python3.6/http/client.py", line 1026, in _send_output
    self.send(msg)
  File "/home/beast/anaconda3/envs/srikar/lib/python3.6/http/client.py", line 964, in send
    self.connect()
  File "/home/beast/anaconda3/envs/srikar/lib/python3.6/site-packages/urllib3/connection.py", line 183, in connect
    conn = self._new_conn()
  File "/home/beast/anaconda3/envs/srikar/lib/python3.6/site-packages/urllib3/connection.py", line 169, in _new_conn
    self, "Failed to establish a new connection: %s" % e)
urllib3.exceptions.NewConnectionError: <urllib3.connection.HTTPConnection object at 0x7efabf3910b8>: Failed to establish a new connection: [Errno 111] Connection refused

During handling of the above exception, another exception occurred:

Traceback (most recent call last):
  File "/home/beast/anaconda3/envs/srikar/lib/python3.6/site-packages/requests/adapters.py", line 449, in send
    timeout=timeout
  File "/home/beast/anaconda3/envs/srikar/lib/python3.6/site-packages/urllib3/connectionpool.py", line 641, in urlopen
    _stacktrace=sys.exc_info()[2])
  File "/home/beast/anaconda3/envs/srikar/lib/python3.6/site-packages/urllib3/util/retry.py", line 399, in increment
    raise MaxRetryError(_pool, url, error or ResponseError(cause))
urllib3.exceptions.MaxRetryError: HTTPConnectionPool(host='localhost', port=8097): Max retries exceeded with url: /events (Caused by NewConnectionError('<urllib3.connection.HTTPConnection object at 0x7efabf3910b8>: Failed to establish a new connection: [Errno 111] Connection refused',))

During handling of the above exception, another exception occurred:

Traceback (most recent call last):
  File "/home/beast/anaconda3/envs/srikar/lib/python3.6/site-packages/visdom/__init__.py", line 548, in _send
    data=json.dumps(msg),
  File "/home/beast/anaconda3/envs/srikar/lib/python3.6/site-packages/requests/sessions.py", line 581, in post
    return self.request('POST', url, data=data, json=json, **kwargs)
  File "/home/beast/anaconda3/envs/srikar/lib/python3.6/site-packages/requests/sessions.py", line 533, in request
    resp = self.send(prep, **send_kwargs)
  File "/home/beast/anaconda3/envs/srikar/lib/python3.6/site-packages/requests/sessions.py", line 646, in send
    r = adapter.send(request, **kwargs)
  File "/home/beast/anaconda3/envs/srikar/lib/python3.6/site-packages/requests/adapters.py", line 516, in send
    raise ConnectionError(e, request=request)
requests.exceptions.ConnectionError: HTTPConnectionPool(host='localhost', port=8097): Max retries exceeded with url: /events (Caused by NewConnectionError('<urllib3.connection.HTTPConnection object at 0x7efabf3910b8>: Failed to establish a new connection: [Errno 111] Connection refused',))
Traceback (most recent call last):
  File "/home/beast/anaconda3/envs/srikar/lib/python3.6/site-packages/urllib3/connection.py", line 160, in _new_conn
    (self._dns_host, self.port), self.timeout, **extra_kw)
  File "/home/beast/anaconda3/envs/srikar/lib/python3.6/site-packages/urllib3/util/connection.py", line 80, in create_connection
    raise err
  File "/home/beast/anaconda3/envs/srikar/lib/python3.6/site-packages/urllib3/util/connection.py", line 70, in create_connection
    sock.connect(sa)
ConnectionRefusedError: [Errno 111] Connection refused

During handling of the above exception, another exception occurred:

Traceback (most recent call last):
  File "/home/beast/anaconda3/envs/srikar/lib/python3.6/site-packages/urllib3/connectionpool.py", line 603, in urlopen
    chunked=chunked)
  File "/home/beast/anaconda3/envs/srikar/lib/python3.6/site-packages/urllib3/connectionpool.py", line 355, in _make_request
    conn.request(method, url, **httplib_request_kw)
  File "/home/beast/anaconda3/envs/srikar/lib/python3.6/http/client.py", line 1239, in request
    self._send_request(method, url, body, headers, encode_chunked)
  File "/home/beast/anaconda3/envs/srikar/lib/python3.6/http/client.py", line 1285, in _send_request
    self.endheaders(body, encode_chunked=encode_chunked)
  File "/home/beast/anaconda3/envs/srikar/lib/python3.6/http/client.py", line 1234, in endheaders
    self._send_output(message_body, encode_chunked=encode_chunked)
  File "/home/beast/anaconda3/envs/srikar/lib/python3.6/http/client.py", line 1026, in _send_output
    self.send(msg)
  File "/home/beast/anaconda3/envs/srikar/lib/python3.6/http/client.py", line 964, in send
    self.connect()
  File "/home/beast/anaconda3/envs/srikar/lib/python3.6/site-packages/urllib3/connection.py", line 183, in connect
    conn = self._new_conn()
  File "/home/beast/anaconda3/envs/srikar/lib/python3.6/site-packages/urllib3/connection.py", line 169, in _new_conn
    self, "Failed to establish a new connection: %s" % e)
urllib3.exceptions.NewConnectionError: <urllib3.connection.HTTPConnection object at 0x7efabf391a58>: Failed to establish a new connection: [Errno 111] Connection refused

During handling of the above exception, another exception occurred:

Traceback (most recent call last):
  File "/home/beast/anaconda3/envs/srikar/lib/python3.6/site-packages/requests/adapters.py", line 449, in send
    timeout=timeout
  File "/home/beast/anaconda3/envs/srikar/lib/python3.6/site-packages/urllib3/connectionpool.py", line 641, in urlopen
    _stacktrace=sys.exc_info()[2])
  File "/home/beast/anaconda3/envs/srikar/lib/python3.6/site-packages/urllib3/util/retry.py", line 399, in increment
    raise MaxRetryError(_pool, url, error or ResponseError(cause))
urllib3.exceptions.MaxRetryError: HTTPConnectionPool(host='localhost', port=8097): Max retries exceeded with url: /events (Caused by NewConnectionError('<urllib3.connection.HTTPConnection object at 0x7efabf391a58>: Failed to establish a new connection: [Errno 111] Connection refused',))

During handling of the above exception, another exception occurred:

Traceback (most recent call last):
  File "/home/beast/anaconda3/envs/srikar/lib/python3.6/site-packages/visdom/__init__.py", line 548, in _send
    data=json.dumps(msg),
  File "/home/beast/anaconda3/envs/srikar/lib/python3.6/site-packages/requests/sessions.py", line 581, in post
    return self.request('POST', url, data=data, json=json, **kwargs)
  File "/home/beast/anaconda3/envs/srikar/lib/python3.6/site-packages/requests/sessions.py", line 533, in request
    resp = self.send(prep, **send_kwargs)
  File "/home/beast/anaconda3/envs/srikar/lib/python3.6/site-packages/requests/sessions.py", line 646, in send
    r = adapter.send(request, **kwargs)
  File "/home/beast/anaconda3/envs/srikar/lib/python3.6/site-packages/requests/adapters.py", line 516, in send
    raise ConnectionError(e, request=request)
requests.exceptions.ConnectionError: HTTPConnectionPool(host='localhost', port=8097): Max retries exceeded with url: /events (Caused by NewConnectionError('<urllib3.connection.HTTPConnection object at 0x7efabf391a58>: Failed to establish a new connection: [Errno 111] Connection refused',))
Traceback (most recent call last):
  File "/home/beast/anaconda3/envs/srikar/lib/python3.6/site-packages/urllib3/connection.py", line 160, in _new_conn
    (self._dns_host, self.port), self.timeout, **extra_kw)
  File "/home/beast/anaconda3/envs/srikar/lib/python3.6/site-packages/urllib3/util/connection.py", line 80, in create_connection
    raise err
  File "/home/beast/anaconda3/envs/srikar/lib/python3.6/site-packages/urllib3/util/connection.py", line 70, in create_connection
    sock.connect(sa)
ConnectionRefusedError: [Errno 111] Connection refused

During handling of the above exception, another exception occurred:

Traceback (most recent call last):
  File "/home/beast/anaconda3/envs/srikar/lib/python3.6/site-packages/urllib3/connectionpool.py", line 603, in urlopen
    chunked=chunked)
  File "/home/beast/anaconda3/envs/srikar/lib/python3.6/site-packages/urllib3/connectionpool.py", line 355, in _make_request
    conn.request(method, url, **httplib_request_kw)
  File "/home/beast/anaconda3/envs/srikar/lib/python3.6/http/client.py", line 1239, in request
    self._send_request(method, url, body, headers, encode_chunked)
  File "/home/beast/anaconda3/envs/srikar/lib/python3.6/http/client.py", line 1285, in _send_request
    self.endheaders(body, encode_chunked=encode_chunked)
  File "/home/beast/anaconda3/envs/srikar/lib/python3.6/http/client.py", line 1234, in endheaders
    self._send_output(message_body, encode_chunked=encode_chunked)
  File "/home/beast/anaconda3/envs/srikar/lib/python3.6/http/client.py", line 1026, in _send_output
    self.send(msg)
  File "/home/beast/anaconda3/envs/srikar/lib/python3.6/http/client.py", line 964, in send
    self.connect()
  File "/home/beast/anaconda3/envs/srikar/lib/python3.6/site-packages/urllib3/connection.py", line 183, in connect
    conn = self._new_conn()
  File "/home/beast/anaconda3/envs/srikar/lib/python3.6/site-packages/urllib3/connection.py", line 169, in _new_conn
    self, "Failed to establish a new connection: %s" % e)
urllib3.exceptions.NewConnectionError: <urllib3.connection.HTTPConnection object at 0x7efabf3745f8>: Failed to establish a new connection: [Errno 111] Connection refused

During handling of the above exception, another exception occurred:

Traceback (most recent call last):
  File "/home/beast/anaconda3/envs/srikar/lib/python3.6/site-packages/requests/adapters.py", line 449, in send
    timeout=timeout
  File "/home/beast/anaconda3/envs/srikar/lib/python3.6/site-packages/urllib3/connectionpool.py", line 641, in urlopen
    _stacktrace=sys.exc_info()[2])
  File "/home/beast/anaconda3/envs/srikar/lib/python3.6/site-packages/urllib3/util/retry.py", line 399, in increment
    raise MaxRetryError(_pool, url, error or ResponseError(cause))
urllib3.exceptions.MaxRetryError: HTTPConnectionPool(host='localhost', port=8097): Max retries exceeded with url: /events (Caused by NewConnectionError('<urllib3.connection.HTTPConnection object at 0x7efabf3745f8>: Failed to establish a new connection: [Errno 111] Connection refused',))

During handling of the above exception, another exception occurred:

Traceback (most recent call last):
  File "/home/beast/anaconda3/envs/srikar/lib/python3.6/site-packages/visdom/__init__.py", line 548, in _send
    data=json.dumps(msg),
  File "/home/beast/anaconda3/envs/srikar/lib/python3.6/site-packages/requests/sessions.py", line 581, in post
    return self.request('POST', url, data=data, json=json, **kwargs)
  File "/home/beast/anaconda3/envs/srikar/lib/python3.6/site-packages/requests/sessions.py", line 533, in request
    resp = self.send(prep, **send_kwargs)
  File "/home/beast/anaconda3/envs/srikar/lib/python3.6/site-packages/requests/sessions.py", line 646, in send
    r = adapter.send(request, **kwargs)
  File "/home/beast/anaconda3/envs/srikar/lib/python3.6/site-packages/requests/adapters.py", line 516, in send
    raise ConnectionError(e, request=request)
requests.exceptions.ConnectionError: HTTPConnectionPool(host='localhost', port=8097): Max retries exceeded with url: /events (Caused by NewConnectionError('<urllib3.connection.HTTPConnection object at 0x7efabf3745f8>: Failed to establish a new connection: [Errno 111] Connection refused',))
Traceback (most recent call last):
  File "/home/beast/anaconda3/envs/srikar/lib/python3.6/site-packages/urllib3/connection.py", line 160, in _new_conn
    (self._dns_host, self.port), self.timeout, **extra_kw)
  File "/home/beast/anaconda3/envs/srikar/lib/python3.6/site-packages/urllib3/util/connection.py", line 80, in create_connection
    raise err
  File "/home/beast/anaconda3/envs/srikar/lib/python3.6/site-packages/urllib3/util/connection.py", line 70, in create_connection
    sock.connect(sa)
ConnectionRefusedError: [Errno 111] Connection refused

During handling of the above exception, another exception occurred:

Traceback (most recent call last):
  File "/home/beast/anaconda3/envs/srikar/lib/python3.6/site-packages/urllib3/connectionpool.py", line 603, in urlopen
    chunked=chunked)
  File "/home/beast/anaconda3/envs/srikar/lib/python3.6/site-packages/urllib3/connectionpool.py", line 355, in _make_request
    conn.request(method, url, **httplib_request_kw)
  File "/home/beast/anaconda3/envs/srikar/lib/python3.6/http/client.py", line 1239, in request
    self._send_request(method, url, body, headers, encode_chunked)
  File "/home/beast/anaconda3/envs/srikar/lib/python3.6/http/client.py", line 1285, in _send_request
    self.endheaders(body, encode_chunked=encode_chunked)
  File "/home/beast/anaconda3/envs/srikar/lib/python3.6/http/client.py", line 1234, in endheaders
    self._send_output(message_body, encode_chunked=encode_chunked)
  File "/home/beast/anaconda3/envs/srikar/lib/python3.6/http/client.py", line 1026, in _send_output
    self.send(msg)
  File "/home/beast/anaconda3/envs/srikar/lib/python3.6/http/client.py", line 964, in send
    self.connect()
  File "/home/beast/anaconda3/envs/srikar/lib/python3.6/site-packages/urllib3/connection.py", line 183, in connect
    conn = self._new_conn()
  File "/home/beast/anaconda3/envs/srikar/lib/python3.6/site-packages/urllib3/connection.py", line 169, in _new_conn
    self, "Failed to establish a new connection: %s" % e)
urllib3.exceptions.NewConnectionError: <urllib3.connection.HTTPConnection object at 0x7efabf3742b0>: Failed to establish a new connection: [Errno 111] Connection refused

During handling of the above exception, another exception occurred:

Traceback (most recent call last):
  File "/home/beast/anaconda3/envs/srikar/lib/python3.6/site-packages/requests/adapters.py", line 449, in send
    timeout=timeout
  File "/home/beast/anaconda3/envs/srikar/lib/python3.6/site-packages/urllib3/connectionpool.py", line 641, in urlopen
    _stacktrace=sys.exc_info()[2])
  File "/home/beast/anaconda3/envs/srikar/lib/python3.6/site-packages/urllib3/util/retry.py", line 399, in increment
    raise MaxRetryError(_pool, url, error or ResponseError(cause))
urllib3.exceptions.MaxRetryError: HTTPConnectionPool(host='localhost', port=8097): Max retries exceeded with url: /events (Caused by NewConnectionError('<urllib3.connection.HTTPConnection object at 0x7efabf3742b0>: Failed to establish a new connection: [Errno 111] Connection refused',))

During handling of the above exception, another exception occurred:

Traceback (most recent call last):
  File "/home/beast/anaconda3/envs/srikar/lib/python3.6/site-packages/visdom/__init__.py", line 548, in _send
    data=json.dumps(msg),
  File "/home/beast/anaconda3/envs/srikar/lib/python3.6/site-packages/requests/sessions.py", line 581, in post
    return self.request('POST', url, data=data, json=json, **kwargs)
  File "/home/beast/anaconda3/envs/srikar/lib/python3.6/site-packages/requests/sessions.py", line 533, in request
    resp = self.send(prep, **send_kwargs)
  File "/home/beast/anaconda3/envs/srikar/lib/python3.6/site-packages/requests/sessions.py", line 646, in send
    r = adapter.send(request, **kwargs)
  File "/home/beast/anaconda3/envs/srikar/lib/python3.6/site-packages/requests/adapters.py", line 516, in send
    raise ConnectionError(e, request=request)
requests.exceptions.ConnectionError: HTTPConnectionPool(host='localhost', port=8097): Max retries exceeded with url: /events (Caused by NewConnectionError('<urllib3.connection.HTTPConnection object at 0x7efabf3742b0>: Failed to establish a new connection: [Errno 111] Connection refused',))
Traceback (most recent call last):
  File "/home/beast/anaconda3/envs/srikar/lib/python3.6/site-packages/urllib3/connection.py", line 160, in _new_conn
    (self._dns_host, self.port), self.timeout, **extra_kw)
  File "/home/beast/anaconda3/envs/srikar/lib/python3.6/site-packages/urllib3/util/connection.py", line 80, in create_connection
    raise err
  File "/home/beast/anaconda3/envs/srikar/lib/python3.6/site-packages/urllib3/util/connection.py", line 70, in create_connection
    sock.connect(sa)
ConnectionRefusedError: [Errno 111] Connection refused

During handling of the above exception, another exception occurred:

Traceback (most recent call last):
  File "/home/beast/anaconda3/envs/srikar/lib/python3.6/site-packages/urllib3/connectionpool.py", line 603, in urlopen
    chunked=chunked)
  File "/home/beast/anaconda3/envs/srikar/lib/python3.6/site-packages/urllib3/connectionpool.py", line 355, in _make_request
    conn.request(method, url, **httplib_request_kw)
  File "/home/beast/anaconda3/envs/srikar/lib/python3.6/http/client.py", line 1239, in request
    self._send_request(method, url, body, headers, encode_chunked)
  File "/home/beast/anaconda3/envs/srikar/lib/python3.6/http/client.py", line 1285, in _send_request
    self.endheaders(body, encode_chunked=encode_chunked)
  File "/home/beast/anaconda3/envs/srikar/lib/python3.6/http/client.py", line 1234, in endheaders
    self._send_output(message_body, encode_chunked=encode_chunked)
  File "/home/beast/anaconda3/envs/srikar/lib/python3.6/http/client.py", line 1026, in _send_output
    self.send(msg)
  File "/home/beast/anaconda3/envs/srikar/lib/python3.6/http/client.py", line 964, in send
    self.connect()
  File "/home/beast/anaconda3/envs/srikar/lib/python3.6/site-packages/urllib3/connection.py", line 183, in connect
    conn = self._new_conn()
  File "/home/beast/anaconda3/envs/srikar/lib/python3.6/site-packages/urllib3/connection.py", line 169, in _new_conn
    self, "Failed to establish a new connection: %s" % e)
urllib3.exceptions.NewConnectionError: <urllib3.connection.HTTPConnection object at 0x7efabf391b00>: Failed to establish a new connection: [Errno 111] Connection refused

During handling of the above exception, another exception occurred:

Traceback (most recent call last):
  File "/home/beast/anaconda3/envs/srikar/lib/python3.6/site-packages/requests/adapters.py", line 449, in send
    timeout=timeout
  File "/home/beast/anaconda3/envs/srikar/lib/python3.6/site-packages/urllib3/connectionpool.py", line 641, in urlopen
    _stacktrace=sys.exc_info()[2])
  File "/home/beast/anaconda3/envs/srikar/lib/python3.6/site-packages/urllib3/util/retry.py", line 399, in increment
    raise MaxRetryError(_pool, url, error or ResponseError(cause))
urllib3.exceptions.MaxRetryError: HTTPConnectionPool(host='localhost', port=8097): Max retries exceeded with url: /events (Caused by NewConnectionError('<urllib3.connection.HTTPConnection object at 0x7efabf391b00>: Failed to establish a new connection: [Errno 111] Connection refused',))

During handling of the above exception, another exception occurred:

Traceback (most recent call last):
  File "/home/beast/anaconda3/envs/srikar/lib/python3.6/site-packages/visdom/__init__.py", line 548, in _send
    data=json.dumps(msg),
  File "/home/beast/anaconda3/envs/srikar/lib/python3.6/site-packages/requests/sessions.py", line 581, in post
    return self.request('POST', url, data=data, json=json, **kwargs)
  File "/home/beast/anaconda3/envs/srikar/lib/python3.6/site-packages/requests/sessions.py", line 533, in request
    resp = self.send(prep, **send_kwargs)
  File "/home/beast/anaconda3/envs/srikar/lib/python3.6/site-packages/requests/sessions.py", line 646, in send
    r = adapter.send(request, **kwargs)
  File "/home/beast/anaconda3/envs/srikar/lib/python3.6/site-packages/requests/adapters.py", line 516, in send
    raise ConnectionError(e, request=request)
requests.exceptions.ConnectionError: HTTPConnectionPool(host='localhost', port=8097): Max retries exceeded with url: /events (Caused by NewConnectionError('<urllib3.connection.HTTPConnection object at 0x7efabf391b00>: Failed to establish a new connection: [Errno 111] Connection refused',))
Traceback (most recent call last):
  File "/home/beast/anaconda3/envs/srikar/lib/python3.6/site-packages/urllib3/connection.py", line 160, in _new_conn
    (self._dns_host, self.port), self.timeout, **extra_kw)
  File "/home/beast/anaconda3/envs/srikar/lib/python3.6/site-packages/urllib3/util/connection.py", line 80, in create_connection
    raise err
  File "/home/beast/anaconda3/envs/srikar/lib/python3.6/site-packages/urllib3/util/connection.py", line 70, in create_connection
    sock.connect(sa)
ConnectionRefusedError: [Errno 111] Connection refused

During handling of the above exception, another exception occurred:

Traceback (most recent call last):
  File "/home/beast/anaconda3/envs/srikar/lib/python3.6/site-packages/urllib3/connectionpool.py", line 603, in urlopen
    chunked=chunked)
  File "/home/beast/anaconda3/envs/srikar/lib/python3.6/site-packages/urllib3/connectionpool.py", line 355, in _make_request
    conn.request(method, url, **httplib_request_kw)
  File "/home/beast/anaconda3/envs/srikar/lib/python3.6/http/client.py", line 1239, in request
    self._send_request(method, url, body, headers, encode_chunked)
  File "/home/beast/anaconda3/envs/srikar/lib/python3.6/http/client.py", line 1285, in _send_request
    self.endheaders(body, encode_chunked=encode_chunked)
  File "/home/beast/anaconda3/envs/srikar/lib/python3.6/http/client.py", line 1234, in endheaders
    self._send_output(message_body, encode_chunked=encode_chunked)
  File "/home/beast/anaconda3/envs/srikar/lib/python3.6/http/client.py", line 1026, in _send_output
    self.send(msg)
  File "/home/beast/anaconda3/envs/srikar/lib/python3.6/http/client.py", line 964, in send
    self.connect()
  File "/home/beast/anaconda3/envs/srikar/lib/python3.6/site-packages/urllib3/connection.py", line 183, in connect
    conn = self._new_conn()
  File "/home/beast/anaconda3/envs/srikar/lib/python3.6/site-packages/urllib3/connection.py", line 169, in _new_conn
    self, "Failed to establish a new connection: %s" % e)
urllib3.exceptions.NewConnectionError: <urllib3.connection.HTTPConnection object at 0x7efabeb2f048>: Failed to establish a new connection: [Errno 111] Connection refused

During handling of the above exception, another exception occurred:

Traceback (most recent call last):
  File "/home/beast/anaconda3/envs/srikar/lib/python3.6/site-packages/requests/adapters.py", line 449, in send
    timeout=timeout
  File "/home/beast/anaconda3/envs/srikar/lib/python3.6/site-packages/urllib3/connectionpool.py", line 641, in urlopen
    _stacktrace=sys.exc_info()[2])
  File "/home/beast/anaconda3/envs/srikar/lib/python3.6/site-packages/urllib3/util/retry.py", line 399, in increment
    raise MaxRetryError(_pool, url, error or ResponseError(cause))
urllib3.exceptions.MaxRetryError: HTTPConnectionPool(host='localhost', port=8097): Max retries exceeded with url: /events (Caused by NewConnectionError('<urllib3.connection.HTTPConnection object at 0x7efabeb2f048>: Failed to establish a new connection: [Errno 111] Connection refused',))

During handling of the above exception, another exception occurred:

Traceback (most recent call last):
  File "/home/beast/anaconda3/envs/srikar/lib/python3.6/site-packages/visdom/__init__.py", line 548, in _send
    data=json.dumps(msg),
  File "/home/beast/anaconda3/envs/srikar/lib/python3.6/site-packages/requests/sessions.py", line 581, in post
    return self.request('POST', url, data=data, json=json, **kwargs)
  File "/home/beast/anaconda3/envs/srikar/lib/python3.6/site-packages/requests/sessions.py", line 533, in request
    resp = self.send(prep, **send_kwargs)
  File "/home/beast/anaconda3/envs/srikar/lib/python3.6/site-packages/requests/sessions.py", line 646, in send
    r = adapter.send(request, **kwargs)
  File "/home/beast/anaconda3/envs/srikar/lib/python3.6/site-packages/requests/adapters.py", line 516, in send
    raise ConnectionError(e, request=request)
requests.exceptions.ConnectionError: HTTPConnectionPool(host='localhost', port=8097): Max retries exceeded with url: /events (Caused by NewConnectionError('<urllib3.connection.HTTPConnection object at 0x7efabeb2f048>: Failed to establish a new connection: [Errno 111] Connection refused',))
Traceback (most recent call last):
  File "/home/beast/anaconda3/envs/srikar/lib/python3.6/site-packages/urllib3/connection.py", line 160, in _new_conn
    (self._dns_host, self.port), self.timeout, **extra_kw)
  File "/home/beast/anaconda3/envs/srikar/lib/python3.6/site-packages/urllib3/util/connection.py", line 80, in create_connection
    raise err
  File "/home/beast/anaconda3/envs/srikar/lib/python3.6/site-packages/urllib3/util/connection.py", line 70, in create_connection
    sock.connect(sa)
ConnectionRefusedError: [Errno 111] Connection refused

During handling of the above exception, another exception occurred:

Traceback (most recent call last):
  File "/home/beast/anaconda3/envs/srikar/lib/python3.6/site-packages/urllib3/connectionpool.py", line 603, in urlopen
    chunked=chunked)
  File "/home/beast/anaconda3/envs/srikar/lib/python3.6/site-packages/urllib3/connectionpool.py", line 355, in _make_request
    conn.request(method, url, **httplib_request_kw)
  File "/home/beast/anaconda3/envs/srikar/lib/python3.6/http/client.py", line 1239, in request
    self._send_request(method, url, body, headers, encode_chunked)
  File "/home/beast/anaconda3/envs/srikar/lib/python3.6/http/client.py", line 1285, in _send_request
    self.endheaders(body, encode_chunked=encode_chunked)
  File "/home/beast/anaconda3/envs/srikar/lib/python3.6/http/client.py", line 1234, in endheaders
    self._send_output(message_body, encode_chunked=encode_chunked)
  File "/home/beast/anaconda3/envs/srikar/lib/python3.6/http/client.py", line 1026, in _send_output
    self.send(msg)
  File "/home/beast/anaconda3/envs/srikar/lib/python3.6/http/client.py", line 964, in send
    self.connect()
  File "/home/beast/anaconda3/envs/srikar/lib/python3.6/site-packages/urllib3/connection.py", line 183, in connect
    conn = self._new_conn()
  File "/home/beast/anaconda3/envs/srikar/lib/python3.6/site-packages/urllib3/connection.py", line 169, in _new_conn
    self, "Failed to establish a new connection: %s" % e)
urllib3.exceptions.NewConnectionError: <urllib3.connection.HTTPConnection object at 0x7efabeb2f908>: Failed to establish a new connection: [Errno 111] Connection refused

During handling of the above exception, another exception occurred:

Traceback (most recent call last):
  File "/home/beast/anaconda3/envs/srikar/lib/python3.6/site-packages/requests/adapters.py", line 449, in send
    timeout=timeout
  File "/home/beast/anaconda3/envs/srikar/lib/python3.6/site-packages/urllib3/connectionpool.py", line 641, in urlopen
    _stacktrace=sys.exc_info()[2])
  File "/home/beast/anaconda3/envs/srikar/lib/python3.6/site-packages/urllib3/util/retry.py", line 399, in increment
    raise MaxRetryError(_pool, url, error or ResponseError(cause))
urllib3.exceptions.MaxRetryError: HTTPConnectionPool(host='localhost', port=8097): Max retries exceeded with url: /events (Caused by NewConnectionError('<urllib3.connection.HTTPConnection object at 0x7efabeb2f908>: Failed to establish a new connection: [Errno 111] Connection refused',))

During handling of the above exception, another exception occurred:

Traceback (most recent call last):
  File "/home/beast/anaconda3/envs/srikar/lib/python3.6/site-packages/visdom/__init__.py", line 548, in _send
    data=json.dumps(msg),
  File "/home/beast/anaconda3/envs/srikar/lib/python3.6/site-packages/requests/sessions.py", line 581, in post
    return self.request('POST', url, data=data, json=json, **kwargs)
  File "/home/beast/anaconda3/envs/srikar/lib/python3.6/site-packages/requests/sessions.py", line 533, in request
    resp = self.send(prep, **send_kwargs)
  File "/home/beast/anaconda3/envs/srikar/lib/python3.6/site-packages/requests/sessions.py", line 646, in send
    r = adapter.send(request, **kwargs)
  File "/home/beast/anaconda3/envs/srikar/lib/python3.6/site-packages/requests/adapters.py", line 516, in send
    raise ConnectionError(e, request=request)
requests.exceptions.ConnectionError: HTTPConnectionPool(host='localhost', port=8097): Max retries exceeded with url: /events (Caused by NewConnectionError('<urllib3.connection.HTTPConnection object at 0x7efabeb2f908>: Failed to establish a new connection: [Errno 111] Connection refused',))
Traceback (most recent call last):
  File "/home/beast/anaconda3/envs/srikar/lib/python3.6/site-packages/urllib3/connection.py", line 160, in _new_conn
    (self._dns_host, self.port), self.timeout, **extra_kw)
  File "/home/beast/anaconda3/envs/srikar/lib/python3.6/site-packages/urllib3/util/connection.py", line 80, in create_connection
    raise err
  File "/home/beast/anaconda3/envs/srikar/lib/python3.6/site-packages/urllib3/util/connection.py", line 70, in create_connection
    sock.connect(sa)
ConnectionRefusedError: [Errno 111] Connection refused

During handling of the above exception, another exception occurred:

Traceback (most recent call last):
  File "/home/beast/anaconda3/envs/srikar/lib/python3.6/site-packages/urllib3/connectionpool.py", line 603, in urlopen
    chunked=chunked)
  File "/home/beast/anaconda3/envs/srikar/lib/python3.6/site-packages/urllib3/connectionpool.py", line 355, in _make_request
    conn.request(method, url, **httplib_request_kw)
  File "/home/beast/anaconda3/envs/srikar/lib/python3.6/http/client.py", line 1239, in request
    self._send_request(method, url, body, headers, encode_chunked)
  File "/home/beast/anaconda3/envs/srikar/lib/python3.6/http/client.py", line 1285, in _send_request
    self.endheaders(body, encode_chunked=encode_chunked)
  File "/home/beast/anaconda3/envs/srikar/lib/python3.6/http/client.py", line 1234, in endheaders
    self._send_output(message_body, encode_chunked=encode_chunked)
  File "/home/beast/anaconda3/envs/srikar/lib/python3.6/http/client.py", line 1026, in _send_output
    self.send(msg)
  File "/home/beast/anaconda3/envs/srikar/lib/python3.6/http/client.py", line 964, in send
    self.connect()
  File "/home/beast/anaconda3/envs/srikar/lib/python3.6/site-packages/urllib3/connection.py", line 183, in connect
    conn = self._new_conn()
  File "/home/beast/anaconda3/envs/srikar/lib/python3.6/site-packages/urllib3/connection.py", line 169, in _new_conn
    self, "Failed to establish a new connection: %s" % e)
urllib3.exceptions.NewConnectionError: <urllib3.connection.HTTPConnection object at 0x7efabeb2fc88>: Failed to establish a new connection: [Errno 111] Connection refused

During handling of the above exception, another exception occurred:

Traceback (most recent call last):
  File "/home/beast/anaconda3/envs/srikar/lib/python3.6/site-packages/requests/adapters.py", line 449, in send
    timeout=timeout
  File "/home/beast/anaconda3/envs/srikar/lib/python3.6/site-packages/urllib3/connectionpool.py", line 641, in urlopen
    _stacktrace=sys.exc_info()[2])
  File "/home/beast/anaconda3/envs/srikar/lib/python3.6/site-packages/urllib3/util/retry.py", line 399, in increment
    raise MaxRetryError(_pool, url, error or ResponseError(cause))
urllib3.exceptions.MaxRetryError: HTTPConnectionPool(host='localhost', port=8097): Max retries exceeded with url: /events (Caused by NewConnectionError('<urllib3.connection.HTTPConnection object at 0x7efabeb2fc88>: Failed to establish a new connection: [Errno 111] Connection refused',))

During handling of the above exception, another exception occurred:

Traceback (most recent call last):
  File "/home/beast/anaconda3/envs/srikar/lib/python3.6/site-packages/visdom/__init__.py", line 548, in _send
    data=json.dumps(msg),
  File "/home/beast/anaconda3/envs/srikar/lib/python3.6/site-packages/requests/sessions.py", line 581, in post
    return self.request('POST', url, data=data, json=json, **kwargs)
  File "/home/beast/anaconda3/envs/srikar/lib/python3.6/site-packages/requests/sessions.py", line 533, in request
    resp = self.send(prep, **send_kwargs)
  File "/home/beast/anaconda3/envs/srikar/lib/python3.6/site-packages/requests/sessions.py", line 646, in send
    r = adapter.send(request, **kwargs)
  File "/home/beast/anaconda3/envs/srikar/lib/python3.6/site-packages/requests/adapters.py", line 516, in send
    raise ConnectionError(e, request=request)
requests.exceptions.ConnectionError: HTTPConnectionPool(host='localhost', port=8097): Max retries exceeded with url: /events (Caused by NewConnectionError('<urllib3.connection.HTTPConnection object at 0x7efabeb2fc88>: Failed to establish a new connection: [Errno 111] Connection refused',))
Traceback (most recent call last):
  File "/home/beast/anaconda3/envs/srikar/lib/python3.6/site-packages/urllib3/connection.py", line 160, in _new_conn
    (self._dns_host, self.port), self.timeout, **extra_kw)
  File "/home/beast/anaconda3/envs/srikar/lib/python3.6/site-packages/urllib3/util/connection.py", line 80, in create_connection
    raise err
  File "/home/beast/anaconda3/envs/srikar/lib/python3.6/site-packages/urllib3/util/connection.py", line 70, in create_connection
    sock.connect(sa)
ConnectionRefusedError: [Errno 111] Connection refused

During handling of the above exception, another exception occurred:

Traceback (most recent call last):
  File "/home/beast/anaconda3/envs/srikar/lib/python3.6/site-packages/urllib3/connectionpool.py", line 603, in urlopen
    chunked=chunked)
  File "/home/beast/anaconda3/envs/srikar/lib/python3.6/site-packages/urllib3/connectionpool.py", line 355, in _make_request
    conn.request(method, url, **httplib_request_kw)
  File "/home/beast/anaconda3/envs/srikar/lib/python3.6/http/client.py", line 1239, in request
    self._send_request(method, url, body, headers, encode_chunked)
  File "/home/beast/anaconda3/envs/srikar/lib/python3.6/http/client.py", line 1285, in _send_request
    self.endheaders(body, encode_chunked=encode_chunked)
  File "/home/beast/anaconda3/envs/srikar/lib/python3.6/http/client.py", line 1234, in endheaders
    self._send_output(message_body, encode_chunked=encode_chunked)
  File "/home/beast/anaconda3/envs/srikar/lib/python3.6/http/client.py", line 1026, in _send_output
    self.send(msg)
  File "/home/beast/anaconda3/envs/srikar/lib/python3.6/http/client.py", line 964, in send
    self.connect()
  File "/home/beast/anaconda3/envs/srikar/lib/python3.6/site-packages/urllib3/connection.py", line 183, in connect
    conn = self._new_conn()
  File "/home/beast/anaconda3/envs/srikar/lib/python3.6/site-packages/urllib3/connection.py", line 169, in _new_conn
    self, "Failed to establish a new connection: %s" % e)
urllib3.exceptions.NewConnectionError: <urllib3.connection.HTTPConnection object at 0x7eff89382eb8>: Failed to establish a new connection: [Errno 111] Connection refused

During handling of the above exception, another exception occurred:

Traceback (most recent call last):
  File "/home/beast/anaconda3/envs/srikar/lib/python3.6/site-packages/requests/adapters.py", line 449, in send
    timeout=timeout
  File "/home/beast/anaconda3/envs/srikar/lib/python3.6/site-packages/urllib3/connectionpool.py", line 641, in urlopen
    _stacktrace=sys.exc_info()[2])
  File "/home/beast/anaconda3/envs/srikar/lib/python3.6/site-packages/urllib3/util/retry.py", line 399, in increment
    raise MaxRetryError(_pool, url, error or ResponseError(cause))
urllib3.exceptions.MaxRetryError: HTTPConnectionPool(host='localhost', port=8097): Max retries exceeded with url: /events (Caused by NewConnectionError('<urllib3.connection.HTTPConnection object at 0x7eff89382eb8>: Failed to establish a new connection: [Errno 111] Connection refused',))

During handling of the above exception, another exception occurred:

Traceback (most recent call last):
  File "/home/beast/anaconda3/envs/srikar/lib/python3.6/site-packages/visdom/__init__.py", line 548, in _send
    data=json.dumps(msg),
  File "/home/beast/anaconda3/envs/srikar/lib/python3.6/site-packages/requests/sessions.py", line 581, in post
    return self.request('POST', url, data=data, json=json, **kwargs)
  File "/home/beast/anaconda3/envs/srikar/lib/python3.6/site-packages/requests/sessions.py", line 533, in request
    resp = self.send(prep, **send_kwargs)
  File "/home/beast/anaconda3/envs/srikar/lib/python3.6/site-packages/requests/sessions.py", line 646, in send
    r = adapter.send(request, **kwargs)
  File "/home/beast/anaconda3/envs/srikar/lib/python3.6/site-packages/requests/adapters.py", line 516, in send
    raise ConnectionError(e, request=request)
requests.exceptions.ConnectionError: HTTPConnectionPool(host='localhost', port=8097): Max retries exceeded with url: /events (Caused by NewConnectionError('<urllib3.connection.HTTPConnection object at 0x7eff89382eb8>: Failed to establish a new connection: [Errno 111] Connection refused',))
Traceback (most recent call last):
  File "/home/beast/anaconda3/envs/srikar/lib/python3.6/site-packages/urllib3/connection.py", line 160, in _new_conn
    (self._dns_host, self.port), self.timeout, **extra_kw)
  File "/home/beast/anaconda3/envs/srikar/lib/python3.6/site-packages/urllib3/util/connection.py", line 80, in create_connection
    raise err
  File "/home/beast/anaconda3/envs/srikar/lib/python3.6/site-packages/urllib3/util/connection.py", line 70, in create_connection
    sock.connect(sa)
ConnectionRefusedError: [Errno 111] Connection refused

During handling of the above exception, another exception occurred:

Traceback (most recent call last):
  File "/home/beast/anaconda3/envs/srikar/lib/python3.6/site-packages/urllib3/connectionpool.py", line 603, in urlopen
    chunked=chunked)
  File "/home/beast/anaconda3/envs/srikar/lib/python3.6/site-packages/urllib3/connectionpool.py", line 355, in _make_request
    conn.request(method, url, **httplib_request_kw)
  File "/home/beast/anaconda3/envs/srikar/lib/python3.6/http/client.py", line 1239, in request
    self._send_request(method, url, body, headers, encode_chunked)
  File "/home/beast/anaconda3/envs/srikar/lib/python3.6/http/client.py", line 1285, in _send_request
    self.endheaders(body, encode_chunked=encode_chunked)
  File "/home/beast/anaconda3/envs/srikar/lib/python3.6/http/client.py", line 1234, in endheaders
    self._send_output(message_body, encode_chunked=encode_chunked)
  File "/home/beast/anaconda3/envs/srikar/lib/python3.6/http/client.py", line 1026, in _send_output
    self.send(msg)
  File "/home/beast/anaconda3/envs/srikar/lib/python3.6/http/client.py", line 964, in send
    self.connect()
  File "/home/beast/anaconda3/envs/srikar/lib/python3.6/site-packages/urllib3/connection.py", line 183, in connect
    conn = self._new_conn()
  File "/home/beast/anaconda3/envs/srikar/lib/python3.6/site-packages/urllib3/connection.py", line 169, in _new_conn
    self, "Failed to establish a new connection: %s" % e)
urllib3.exceptions.NewConnectionError: <urllib3.connection.HTTPConnection object at 0x7efabf391940>: Failed to establish a new connection: [Errno 111] Connection refused

During handling of the above exception, another exception occurred:

Traceback (most recent call last):
  File "/home/beast/anaconda3/envs/srikar/lib/python3.6/site-packages/requests/adapters.py", line 449, in send
    timeout=timeout
  File "/home/beast/anaconda3/envs/srikar/lib/python3.6/site-packages/urllib3/connectionpool.py", line 641, in urlopen
    _stacktrace=sys.exc_info()[2])
  File "/home/beast/anaconda3/envs/srikar/lib/python3.6/site-packages/urllib3/util/retry.py", line 399, in increment
    raise MaxRetryError(_pool, url, error or ResponseError(cause))
urllib3.exceptions.MaxRetryError: HTTPConnectionPool(host='localhost', port=8097): Max retries exceeded with url: /events (Caused by NewConnectionError('<urllib3.connection.HTTPConnection object at 0x7efabf391940>: Failed to establish a new connection: [Errno 111] Connection refused',))

During handling of the above exception, another exception occurred:

Traceback (most recent call last):
  File "/home/beast/anaconda3/envs/srikar/lib/python3.6/site-packages/visdom/__init__.py", line 548, in _send
    data=json.dumps(msg),
  File "/home/beast/anaconda3/envs/srikar/lib/python3.6/site-packages/requests/sessions.py", line 581, in post
    return self.request('POST', url, data=data, json=json, **kwargs)
  File "/home/beast/anaconda3/envs/srikar/lib/python3.6/site-packages/requests/sessions.py", line 533, in request
    resp = self.send(prep, **send_kwargs)
  File "/home/beast/anaconda3/envs/srikar/lib/python3.6/site-packages/requests/sessions.py", line 646, in send
    r = adapter.send(request, **kwargs)
  File "/home/beast/anaconda3/envs/srikar/lib/python3.6/site-packages/requests/adapters.py", line 516, in send
    raise ConnectionError(e, request=request)
requests.exceptions.ConnectionError: HTTPConnectionPool(host='localhost', port=8097): Max retries exceeded with url: /events (Caused by NewConnectionError('<urllib3.connection.HTTPConnection object at 0x7efabf391940>: Failed to establish a new connection: [Errno 111] Connection refused',))
Traceback (most recent call last):
  File "/home/beast/anaconda3/envs/srikar/lib/python3.6/site-packages/urllib3/connection.py", line 160, in _new_conn
    (self._dns_host, self.port), self.timeout, **extra_kw)
  File "/home/beast/anaconda3/envs/srikar/lib/python3.6/site-packages/urllib3/util/connection.py", line 80, in create_connection
    raise err
  File "/home/beast/anaconda3/envs/srikar/lib/python3.6/site-packages/urllib3/util/connection.py", line 70, in create_connection
    sock.connect(sa)
ConnectionRefusedError: [Errno 111] Connection refused

During handling of the above exception, another exception occurred:

Traceback (most recent call last):
  File "/home/beast/anaconda3/envs/srikar/lib/python3.6/site-packages/urllib3/connectionpool.py", line 603, in urlopen
    chunked=chunked)
  File "/home/beast/anaconda3/envs/srikar/lib/python3.6/site-packages/urllib3/connectionpool.py", line 355, in _make_request
    conn.request(method, url, **httplib_request_kw)
  File "/home/beast/anaconda3/envs/srikar/lib/python3.6/http/client.py", line 1239, in request
    self._send_request(method, url, body, headers, encode_chunked)
  File "/home/beast/anaconda3/envs/srikar/lib/python3.6/http/client.py", line 1285, in _send_request
    self.endheaders(body, encode_chunked=encode_chunked)
  File "/home/beast/anaconda3/envs/srikar/lib/python3.6/http/client.py", line 1234, in endheaders
    self._send_output(message_body, encode_chunked=encode_chunked)
  File "/home/beast/anaconda3/envs/srikar/lib/python3.6/http/client.py", line 1026, in _send_output
    self.send(msg)
  File "/home/beast/anaconda3/envs/srikar/lib/python3.6/http/client.py", line 964, in send
    self.connect()
  File "/home/beast/anaconda3/envs/srikar/lib/python3.6/site-packages/urllib3/connection.py", line 183, in connect
    conn = self._new_conn()
  File "/home/beast/anaconda3/envs/srikar/lib/python3.6/site-packages/urllib3/connection.py", line 169, in _new_conn
    self, "Failed to establish a new connection: %s" % e)
urllib3.exceptions.NewConnectionError: <urllib3.connection.HTTPConnection object at 0x7efabf374ba8>: Failed to establish a new connection: [Errno 111] Connection refused

During handling of the above exception, another exception occurred:

Traceback (most recent call last):
  File "/home/beast/anaconda3/envs/srikar/lib/python3.6/site-packages/requests/adapters.py", line 449, in send
    timeout=timeout
  File "/home/beast/anaconda3/envs/srikar/lib/python3.6/site-packages/urllib3/connectionpool.py", line 641, in urlopen
    _stacktrace=sys.exc_info()[2])
  File "/home/beast/anaconda3/envs/srikar/lib/python3.6/site-packages/urllib3/util/retry.py", line 399, in increment
    raise MaxRetryError(_pool, url, error or ResponseError(cause))
urllib3.exceptions.MaxRetryError: HTTPConnectionPool(host='localhost', port=8097): Max retries exceeded with url: /events (Caused by NewConnectionError('<urllib3.connection.HTTPConnection object at 0x7efabf374ba8>: Failed to establish a new connection: [Errno 111] Connection refused',))

During handling of the above exception, another exception occurred:

Traceback (most recent call last):
  File "/home/beast/anaconda3/envs/srikar/lib/python3.6/site-packages/visdom/__init__.py", line 548, in _send
    data=json.dumps(msg),
  File "/home/beast/anaconda3/envs/srikar/lib/python3.6/site-packages/requests/sessions.py", line 581, in post
    return self.request('POST', url, data=data, json=json, **kwargs)
  File "/home/beast/anaconda3/envs/srikar/lib/python3.6/site-packages/requests/sessions.py", line 533, in request
    resp = self.send(prep, **send_kwargs)
  File "/home/beast/anaconda3/envs/srikar/lib/python3.6/site-packages/requests/sessions.py", line 646, in send
    r = adapter.send(request, **kwargs)
  File "/home/beast/anaconda3/envs/srikar/lib/python3.6/site-packages/requests/adapters.py", line 516, in send
    raise ConnectionError(e, request=request)
requests.exceptions.ConnectionError: HTTPConnectionPool(host='localhost', port=8097): Max retries exceeded with url: /events (Caused by NewConnectionError('<urllib3.connection.HTTPConnection object at 0x7efabf374ba8>: Failed to establish a new connection: [Errno 111] Connection refused',))
Traceback (most recent call last):
  File "/home/beast/anaconda3/envs/srikar/lib/python3.6/site-packages/urllib3/connection.py", line 160, in _new_conn
    (self._dns_host, self.port), self.timeout, **extra_kw)
  File "/home/beast/anaconda3/envs/srikar/lib/python3.6/site-packages/urllib3/util/connection.py", line 80, in create_connection
    raise err
  File "/home/beast/anaconda3/envs/srikar/lib/python3.6/site-packages/urllib3/util/connection.py", line 70, in create_connection
    sock.connect(sa)
ConnectionRefusedError: [Errno 111] Connection refused

During handling of the above exception, another exception occurred:

Traceback (most recent call last):
  File "/home/beast/anaconda3/envs/srikar/lib/python3.6/site-packages/urllib3/connectionpool.py", line 603, in urlopen
    chunked=chunked)
  File "/home/beast/anaconda3/envs/srikar/lib/python3.6/site-packages/urllib3/connectionpool.py", line 355, in _make_request
    conn.request(method, url, **httplib_request_kw)
  File "/home/beast/anaconda3/envs/srikar/lib/python3.6/http/client.py", line 1239, in request
    self._send_request(method, url, body, headers, encode_chunked)
  File "/home/beast/anaconda3/envs/srikar/lib/python3.6/http/client.py", line 1285, in _send_request
    self.endheaders(body, encode_chunked=encode_chunked)
  File "/home/beast/anaconda3/envs/srikar/lib/python3.6/http/client.py", line 1234, in endheaders
    self._send_output(message_body, encode_chunked=encode_chunked)
  File "/home/beast/anaconda3/envs/srikar/lib/python3.6/http/client.py", line 1026, in _send_output
    self.send(msg)
  File "/home/beast/anaconda3/envs/srikar/lib/python3.6/http/client.py", line 964, in send
    self.connect()
  File "/home/beast/anaconda3/envs/srikar/lib/python3.6/site-packages/urllib3/connection.py", line 183, in connect
    conn = self._new_conn()
  File "/home/beast/anaconda3/envs/srikar/lib/python3.6/site-packages/urllib3/connection.py", line 169, in _new_conn
    self, "Failed to establish a new connection: %s" % e)
urllib3.exceptions.NewConnectionError: <urllib3.connection.HTTPConnection object at 0x7eff69347780>: Failed to establish a new connection: [Errno 111] Connection refused

During handling of the above exception, another exception occurred:

Traceback (most recent call last):
  File "/home/beast/anaconda3/envs/srikar/lib/python3.6/site-packages/requests/adapters.py", line 449, in send
    timeout=timeout
  File "/home/beast/anaconda3/envs/srikar/lib/python3.6/site-packages/urllib3/connectionpool.py", line 641, in urlopen
    _stacktrace=sys.exc_info()[2])
  File "/home/beast/anaconda3/envs/srikar/lib/python3.6/site-packages/urllib3/util/retry.py", line 399, in increment
    raise MaxRetryError(_pool, url, error or ResponseError(cause))
urllib3.exceptions.MaxRetryError: HTTPConnectionPool(host='localhost', port=8097): Max retries exceeded with url: /events (Caused by NewConnectionError('<urllib3.connection.HTTPConnection object at 0x7eff69347780>: Failed to establish a new connection: [Errno 111] Connection refused',))

During handling of the above exception, another exception occurred:

Traceback (most recent call last):
  File "/home/beast/anaconda3/envs/srikar/lib/python3.6/site-packages/visdom/__init__.py", line 548, in _send
    data=json.dumps(msg),
  File "/home/beast/anaconda3/envs/srikar/lib/python3.6/site-packages/requests/sessions.py", line 581, in post
    return self.request('POST', url, data=data, json=json, **kwargs)
  File "/home/beast/anaconda3/envs/srikar/lib/python3.6/site-packages/requests/sessions.py", line 533, in request
    resp = self.send(prep, **send_kwargs)
  File "/home/beast/anaconda3/envs/srikar/lib/python3.6/site-packages/requests/sessions.py", line 646, in send
    r = adapter.send(request, **kwargs)
  File "/home/beast/anaconda3/envs/srikar/lib/python3.6/site-packages/requests/adapters.py", line 516, in send
    raise ConnectionError(e, request=request)
requests.exceptions.ConnectionError: HTTPConnectionPool(host='localhost', port=8097): Max retries exceeded with url: /events (Caused by NewConnectionError('<urllib3.connection.HTTPConnection object at 0x7eff69347780>: Failed to establish a new connection: [Errno 111] Connection refused',))
Traceback (most recent call last):
  File "/home/beast/anaconda3/envs/srikar/lib/python3.6/site-packages/urllib3/connection.py", line 160, in _new_conn
    (self._dns_host, self.port), self.timeout, **extra_kw)
  File "/home/beast/anaconda3/envs/srikar/lib/python3.6/site-packages/urllib3/util/connection.py", line 80, in create_connection
    raise err
  File "/home/beast/anaconda3/envs/srikar/lib/python3.6/site-packages/urllib3/util/connection.py", line 70, in create_connection
    sock.connect(sa)
ConnectionRefusedError: [Errno 111] Connection refused

During handling of the above exception, another exception occurred:

Traceback (most recent call last):
  File "/home/beast/anaconda3/envs/srikar/lib/python3.6/site-packages/urllib3/connectionpool.py", line 603, in urlopen
    chunked=chunked)
  File "/home/beast/anaconda3/envs/srikar/lib/python3.6/site-packages/urllib3/connectionpool.py", line 355, in _make_request
    conn.request(method, url, **httplib_request_kw)
  File "/home/beast/anaconda3/envs/srikar/lib/python3.6/http/client.py", line 1239, in request
    self._send_request(method, url, body, headers, encode_chunked)
  File "/home/beast/anaconda3/envs/srikar/lib/python3.6/http/client.py", line 1285, in _send_request
    self.endheaders(body, encode_chunked=encode_chunked)
  File "/home/beast/anaconda3/envs/srikar/lib/python3.6/http/client.py", line 1234, in endheaders
    self._send_output(message_body, encode_chunked=encode_chunked)
  File "/home/beast/anaconda3/envs/srikar/lib/python3.6/http/client.py", line 1026, in _send_output
    self.send(msg)
  File "/home/beast/anaconda3/envs/srikar/lib/python3.6/http/client.py", line 964, in send
    self.connect()
  File "/home/beast/anaconda3/envs/srikar/lib/python3.6/site-packages/urllib3/connection.py", line 183, in connect
    conn = self._new_conn()
  File "/home/beast/anaconda3/envs/srikar/lib/python3.6/site-packages/urllib3/connection.py", line 169, in _new_conn
    self, "Failed to establish a new connection: %s" % e)
urllib3.exceptions.NewConnectionError: <urllib3.connection.HTTPConnection object at 0x7efabf391518>: Failed to establish a new connection: [Errno 111] Connection refused

During handling of the above exception, another exception occurred:

Traceback (most recent call last):
  File "/home/beast/anaconda3/envs/srikar/lib/python3.6/site-packages/requests/adapters.py", line 449, in send
    timeout=timeout
  File "/home/beast/anaconda3/envs/srikar/lib/python3.6/site-packages/urllib3/connectionpool.py", line 641, in urlopen
    _stacktrace=sys.exc_info()[2])
  File "/home/beast/anaconda3/envs/srikar/lib/python3.6/site-packages/urllib3/util/retry.py", line 399, in increment
    raise MaxRetryError(_pool, url, error or ResponseError(cause))
urllib3.exceptions.MaxRetryError: HTTPConnectionPool(host='localhost', port=8097): Max retries exceeded with url: /events (Caused by NewConnectionError('<urllib3.connection.HTTPConnection object at 0x7efabf391518>: Failed to establish a new connection: [Errno 111] Connection refused',))

During handling of the above exception, another exception occurred:

Traceback (most recent call last):
  File "/home/beast/anaconda3/envs/srikar/lib/python3.6/site-packages/visdom/__init__.py", line 548, in _send
    data=json.dumps(msg),
  File "/home/beast/anaconda3/envs/srikar/lib/python3.6/site-packages/requests/sessions.py", line 581, in post
    return self.request('POST', url, data=data, json=json, **kwargs)
  File "/home/beast/anaconda3/envs/srikar/lib/python3.6/site-packages/requests/sessions.py", line 533, in request
    resp = self.send(prep, **send_kwargs)
  File "/home/beast/anaconda3/envs/srikar/lib/python3.6/site-packages/requests/sessions.py", line 646, in send
    r = adapter.send(request, **kwargs)
  File "/home/beast/anaconda3/envs/srikar/lib/python3.6/site-packages/requests/adapters.py", line 516, in send
    raise ConnectionError(e, request=request)
requests.exceptions.ConnectionError: HTTPConnectionPool(host='localhost', port=8097): Max retries exceeded with url: /events (Caused by NewConnectionError('<urllib3.connection.HTTPConnection object at 0x7efabf391518>: Failed to establish a new connection: [Errno 111] Connection refused',))
Traceback (most recent call last):
  File "/home/beast/anaconda3/envs/srikar/lib/python3.6/site-packages/urllib3/connection.py", line 160, in _new_conn
    (self._dns_host, self.port), self.timeout, **extra_kw)
  File "/home/beast/anaconda3/envs/srikar/lib/python3.6/site-packages/urllib3/util/connection.py", line 80, in create_connection
    raise err
  File "/home/beast/anaconda3/envs/srikar/lib/python3.6/site-packages/urllib3/util/connection.py", line 70, in create_connection
    sock.connect(sa)
ConnectionRefusedError: [Errno 111] Connection refused

During handling of the above exception, another exception occurred:

Traceback (most recent call last):
  File "/home/beast/anaconda3/envs/srikar/lib/python3.6/site-packages/urllib3/connectionpool.py", line 603, in urlopen
    chunked=chunked)
  File "/home/beast/anaconda3/envs/srikar/lib/python3.6/site-packages/urllib3/connectionpool.py", line 355, in _make_request
    conn.request(method, url, **httplib_request_kw)
  File "/home/beast/anaconda3/envs/srikar/lib/python3.6/http/client.py", line 1239, in request
    self._send_request(method, url, body, headers, encode_chunked)
  File "/home/beast/anaconda3/envs/srikar/lib/python3.6/http/client.py", line 1285, in _send_request
    self.endheaders(body, encode_chunked=encode_chunked)
  File "/home/beast/anaconda3/envs/srikar/lib/python3.6/http/client.py", line 1234, in endheaders
    self._send_output(message_body, encode_chunked=encode_chunked)
  File "/home/beast/anaconda3/envs/srikar/lib/python3.6/http/client.py", line 1026, in _send_output
    self.send(msg)
  File "/home/beast/anaconda3/envs/srikar/lib/python3.6/http/client.py", line 964, in send
    self.connect()
  File "/home/beast/anaconda3/envs/srikar/lib/python3.6/site-packages/urllib3/connection.py", line 183, in connect
    conn = self._new_conn()
  File "/home/beast/anaconda3/envs/srikar/lib/python3.6/site-packages/urllib3/connection.py", line 169, in _new_conn
    self, "Failed to establish a new connection: %s" % e)
urllib3.exceptions.NewConnectionError: <urllib3.connection.HTTPConnection object at 0x7efabf391780>: Failed to establish a new connection: [Errno 111] Connection refused

During handling of the above exception, another exception occurred:

Traceback (most recent call last):
  File "/home/beast/anaconda3/envs/srikar/lib/python3.6/site-packages/requests/adapters.py", line 449, in send
    timeout=timeout
  File "/home/beast/anaconda3/envs/srikar/lib/python3.6/site-packages/urllib3/connectionpool.py", line 641, in urlopen
    _stacktrace=sys.exc_info()[2])
  File "/home/beast/anaconda3/envs/srikar/lib/python3.6/site-packages/urllib3/util/retry.py", line 399, in increment
    raise MaxRetryError(_pool, url, error or ResponseError(cause))
urllib3.exceptions.MaxRetryError: HTTPConnectionPool(host='localhost', port=8097): Max retries exceeded with url: /events (Caused by NewConnectionError('<urllib3.connection.HTTPConnection object at 0x7efabf391780>: Failed to establish a new connection: [Errno 111] Connection refused',))

During handling of the above exception, another exception occurred:

Traceback (most recent call last):
  File "/home/beast/anaconda3/envs/srikar/lib/python3.6/site-packages/visdom/__init__.py", line 548, in _send
    data=json.dumps(msg),
  File "/home/beast/anaconda3/envs/srikar/lib/python3.6/site-packages/requests/sessions.py", line 581, in post
    return self.request('POST', url, data=data, json=json, **kwargs)
  File "/home/beast/anaconda3/envs/srikar/lib/python3.6/site-packages/requests/sessions.py", line 533, in request
    resp = self.send(prep, **send_kwargs)
  File "/home/beast/anaconda3/envs/srikar/lib/python3.6/site-packages/requests/sessions.py", line 646, in send
    r = adapter.send(request, **kwargs)
  File "/home/beast/anaconda3/envs/srikar/lib/python3.6/site-packages/requests/adapters.py", line 516, in send
    raise ConnectionError(e, request=request)
requests.exceptions.ConnectionError: HTTPConnectionPool(host='localhost', port=8097): Max retries exceeded with url: /events (Caused by NewConnectionError('<urllib3.connection.HTTPConnection object at 0x7efabf391780>: Failed to establish a new connection: [Errno 111] Connection refused',))
Traceback (most recent call last):
  File "/home/beast/anaconda3/envs/srikar/lib/python3.6/site-packages/urllib3/connection.py", line 160, in _new_conn
    (self._dns_host, self.port), self.timeout, **extra_kw)
  File "/home/beast/anaconda3/envs/srikar/lib/python3.6/site-packages/urllib3/util/connection.py", line 80, in create_connection
    raise err
  File "/home/beast/anaconda3/envs/srikar/lib/python3.6/site-packages/urllib3/util/connection.py", line 70, in create_connection
    sock.connect(sa)
ConnectionRefusedError: [Errno 111] Connection refused

During handling of the above exception, another exception occurred:

Traceback (most recent call last):
  File "/home/beast/anaconda3/envs/srikar/lib/python3.6/site-packages/urllib3/connectionpool.py", line 603, in urlopen
    chunked=chunked)
  File "/home/beast/anaconda3/envs/srikar/lib/python3.6/site-packages/urllib3/connectionpool.py", line 355, in _make_request
    conn.request(method, url, **httplib_request_kw)
  File "/home/beast/anaconda3/envs/srikar/lib/python3.6/http/client.py", line 1239, in request
    self._send_request(method, url, body, headers, encode_chunked)
  File "/home/beast/anaconda3/envs/srikar/lib/python3.6/http/client.py", line 1285, in _send_request
    self.endheaders(body, encode_chunked=encode_chunked)
  File "/home/beast/anaconda3/envs/srikar/lib/python3.6/http/client.py", line 1234, in endheaders
    self._send_output(message_body, encode_chunked=encode_chunked)
  File "/home/beast/anaconda3/envs/srikar/lib/python3.6/http/client.py", line 1026, in _send_output
    self.send(msg)
  File "/home/beast/anaconda3/envs/srikar/lib/python3.6/http/client.py", line 964, in send
    self.connect()
  File "/home/beast/anaconda3/envs/srikar/lib/python3.6/site-packages/urllib3/connection.py", line 183, in connect
    conn = self._new_conn()
  File "/home/beast/anaconda3/envs/srikar/lib/python3.6/site-packages/urllib3/connection.py", line 169, in _new_conn
    self, "Failed to establish a new connection: %s" % e)
urllib3.exceptions.NewConnectionError: <urllib3.connection.HTTPConnection object at 0x7efabf374cc0>: Failed to establish a new connection: [Errno 111] Connection refused

During handling of the above exception, another exception occurred:

Traceback (most recent call last):
  File "/home/beast/anaconda3/envs/srikar/lib/python3.6/site-packages/requests/adapters.py", line 449, in send
    timeout=timeout
  File "/home/beast/anaconda3/envs/srikar/lib/python3.6/site-packages/urllib3/connectionpool.py", line 641, in urlopen
    _stacktrace=sys.exc_info()[2])
  File "/home/beast/anaconda3/envs/srikar/lib/python3.6/site-packages/urllib3/util/retry.py", line 399, in increment
    raise MaxRetryError(_pool, url, error or ResponseError(cause))
urllib3.exceptions.MaxRetryError: HTTPConnectionPool(host='localhost', port=8097): Max retries exceeded with url: /events (Caused by NewConnectionError('<urllib3.connection.HTTPConnection object at 0x7efabf374cc0>: Failed to establish a new connection: [Errno 111] Connection refused',))

During handling of the above exception, another exception occurred:

Traceback (most recent call last):
  File "/home/beast/anaconda3/envs/srikar/lib/python3.6/site-packages/visdom/__init__.py", line 548, in _send
    data=json.dumps(msg),
  File "/home/beast/anaconda3/envs/srikar/lib/python3.6/site-packages/requests/sessions.py", line 581, in post
    return self.request('POST', url, data=data, json=json, **kwargs)
  File "/home/beast/anaconda3/envs/srikar/lib/python3.6/site-packages/requests/sessions.py", line 533, in request
    resp = self.send(prep, **send_kwargs)
  File "/home/beast/anaconda3/envs/srikar/lib/python3.6/site-packages/requests/sessions.py", line 646, in send
    r = adapter.send(request, **kwargs)
  File "/home/beast/anaconda3/envs/srikar/lib/python3.6/site-packages/requests/adapters.py", line 516, in send
    raise ConnectionError(e, request=request)
requests.exceptions.ConnectionError: HTTPConnectionPool(host='localhost', port=8097): Max retries exceeded with url: /events (Caused by NewConnectionError('<urllib3.connection.HTTPConnection object at 0x7efabf374cc0>: Failed to establish a new connection: [Errno 111] Connection refused',))
Traceback (most recent call last):
  File "/home/beast/anaconda3/envs/srikar/lib/python3.6/site-packages/urllib3/connection.py", line 160, in _new_conn
    (self._dns_host, self.port), self.timeout, **extra_kw)
  File "/home/beast/anaconda3/envs/srikar/lib/python3.6/site-packages/urllib3/util/connection.py", line 80, in create_connection
    raise err
  File "/home/beast/anaconda3/envs/srikar/lib/python3.6/site-packages/urllib3/util/connection.py", line 70, in create_connection
    sock.connect(sa)
ConnectionRefusedError: [Errno 111] Connection refused

During handling of the above exception, another exception occurred:

Traceback (most recent call last):
  File "/home/beast/anaconda3/envs/srikar/lib/python3.6/site-packages/urllib3/connectionpool.py", line 603, in urlopen
    chunked=chunked)
  File "/home/beast/anaconda3/envs/srikar/lib/python3.6/site-packages/urllib3/connectionpool.py", line 355, in _make_request
    conn.request(method, url, **httplib_request_kw)
  File "/home/beast/anaconda3/envs/srikar/lib/python3.6/http/client.py", line 1239, in request
    self._send_request(method, url, body, headers, encode_chunked)
  File "/home/beast/anaconda3/envs/srikar/lib/python3.6/http/client.py", line 1285, in _send_request
    self.endheaders(body, encode_chunked=encode_chunked)
  File "/home/beast/anaconda3/envs/srikar/lib/python3.6/http/client.py", line 1234, in endheaders
    self._send_output(message_body, encode_chunked=encode_chunked)
  File "/home/beast/anaconda3/envs/srikar/lib/python3.6/http/client.py", line 1026, in _send_output
    self.send(msg)
  File "/home/beast/anaconda3/envs/srikar/lib/python3.6/http/client.py", line 964, in send
    self.connect()
  File "/home/beast/anaconda3/envs/srikar/lib/python3.6/site-packages/urllib3/connection.py", line 183, in connect
    conn = self._new_conn()
  File "/home/beast/anaconda3/envs/srikar/lib/python3.6/site-packages/urllib3/connection.py", line 169, in _new_conn
    self, "Failed to establish a new connection: %s" % e)
urllib3.exceptions.NewConnectionError: <urllib3.connection.HTTPConnection object at 0x7efabeb2f9e8>: Failed to establish a new connection: [Errno 111] Connection refused

During handling of the above exception, another exception occurred:

Traceback (most recent call last):
  File "/home/beast/anaconda3/envs/srikar/lib/python3.6/site-packages/requests/adapters.py", line 449, in send
    timeout=timeout
  File "/home/beast/anaconda3/envs/srikar/lib/python3.6/site-packages/urllib3/connectionpool.py", line 641, in urlopen
    _stacktrace=sys.exc_info()[2])
  File "/home/beast/anaconda3/envs/srikar/lib/python3.6/site-packages/urllib3/util/retry.py", line 399, in increment
    raise MaxRetryError(_pool, url, error or ResponseError(cause))
urllib3.exceptions.MaxRetryError: HTTPConnectionPool(host='localhost', port=8097): Max retries exceeded with url: /events (Caused by NewConnectionError('<urllib3.connection.HTTPConnection object at 0x7efabeb2f9e8>: Failed to establish a new connection: [Errno 111] Connection refused',))

During handling of the above exception, another exception occurred:

Traceback (most recent call last):
  File "/home/beast/anaconda3/envs/srikar/lib/python3.6/site-packages/visdom/__init__.py", line 548, in _send
    data=json.dumps(msg),
  File "/home/beast/anaconda3/envs/srikar/lib/python3.6/site-packages/requests/sessions.py", line 581, in post
    return self.request('POST', url, data=data, json=json, **kwargs)
  File "/home/beast/anaconda3/envs/srikar/lib/python3.6/site-packages/requests/sessions.py", line 533, in request
    resp = self.send(prep, **send_kwargs)
  File "/home/beast/anaconda3/envs/srikar/lib/python3.6/site-packages/requests/sessions.py", line 646, in send
    r = adapter.send(request, **kwargs)
  File "/home/beast/anaconda3/envs/srikar/lib/python3.6/site-packages/requests/adapters.py", line 516, in send
    raise ConnectionError(e, request=request)
requests.exceptions.ConnectionError: HTTPConnectionPool(host='localhost', port=8097): Max retries exceeded with url: /events (Caused by NewConnectionError('<urllib3.connection.HTTPConnection object at 0x7efabeb2f9e8>: Failed to establish a new connection: [Errno 111] Connection refused',))
Traceback (most recent call last):
  File "/home/beast/anaconda3/envs/srikar/lib/python3.6/site-packages/urllib3/connection.py", line 160, in _new_conn
    (self._dns_host, self.port), self.timeout, **extra_kw)
  File "/home/beast/anaconda3/envs/srikar/lib/python3.6/site-packages/urllib3/util/connection.py", line 80, in create_connection
    raise err
  File "/home/beast/anaconda3/envs/srikar/lib/python3.6/site-packages/urllib3/util/connection.py", line 70, in create_connection
    sock.connect(sa)
ConnectionRefusedError: [Errno 111] Connection refused

During handling of the above exception, another exception occurred:

Traceback (most recent call last):
  File "/home/beast/anaconda3/envs/srikar/lib/python3.6/site-packages/urllib3/connectionpool.py", line 603, in urlopen
    chunked=chunked)
  File "/home/beast/anaconda3/envs/srikar/lib/python3.6/site-packages/urllib3/connectionpool.py", line 355, in _make_request
    conn.request(method, url, **httplib_request_kw)
  File "/home/beast/anaconda3/envs/srikar/lib/python3.6/http/client.py", line 1239, in request
    self._send_request(method, url, body, headers, encode_chunked)
  File "/home/beast/anaconda3/envs/srikar/lib/python3.6/http/client.py", line 1285, in _send_request
    self.endheaders(body, encode_chunked=encode_chunked)
  File "/home/beast/anaconda3/envs/srikar/lib/python3.6/http/client.py", line 1234, in endheaders
    self._send_output(message_body, encode_chunked=encode_chunked)
  File "/home/beast/anaconda3/envs/srikar/lib/python3.6/http/client.py", line 1026, in _send_output
    self.send(msg)
  File "/home/beast/anaconda3/envs/srikar/lib/python3.6/http/client.py", line 964, in send
    self.connect()
  File "/home/beast/anaconda3/envs/srikar/lib/python3.6/site-packages/urllib3/connection.py", line 183, in connect
    conn = self._new_conn()
  File "/home/beast/anaconda3/envs/srikar/lib/python3.6/site-packages/urllib3/connection.py", line 169, in _new_conn
    self, "Failed to establish a new connection: %s" % e)
urllib3.exceptions.NewConnectionError: <urllib3.connection.HTTPConnection object at 0x7efabeb2f978>: Failed to establish a new connection: [Errno 111] Connection refused

During handling of the above exception, another exception occurred:

Traceback (most recent call last):
  File "/home/beast/anaconda3/envs/srikar/lib/python3.6/site-packages/requests/adapters.py", line 449, in send
    timeout=timeout
  File "/home/beast/anaconda3/envs/srikar/lib/python3.6/site-packages/urllib3/connectionpool.py", line 641, in urlopen
    _stacktrace=sys.exc_info()[2])
  File "/home/beast/anaconda3/envs/srikar/lib/python3.6/site-packages/urllib3/util/retry.py", line 399, in increment
    raise MaxRetryError(_pool, url, error or ResponseError(cause))
urllib3.exceptions.MaxRetryError: HTTPConnectionPool(host='localhost', port=8097): Max retries exceeded with url: /events (Caused by NewConnectionError('<urllib3.connection.HTTPConnection object at 0x7efabeb2f978>: Failed to establish a new connection: [Errno 111] Connection refused',))

During handling of the above exception, another exception occurred:

Traceback (most recent call last):
  File "/home/beast/anaconda3/envs/srikar/lib/python3.6/site-packages/visdom/__init__.py", line 548, in _send
    data=json.dumps(msg),
  File "/home/beast/anaconda3/envs/srikar/lib/python3.6/site-packages/requests/sessions.py", line 581, in post
    return self.request('POST', url, data=data, json=json, **kwargs)
  File "/home/beast/anaconda3/envs/srikar/lib/python3.6/site-packages/requests/sessions.py", line 533, in request
    resp = self.send(prep, **send_kwargs)
  File "/home/beast/anaconda3/envs/srikar/lib/python3.6/site-packages/requests/sessions.py", line 646, in send
    r = adapter.send(request, **kwargs)
  File "/home/beast/anaconda3/envs/srikar/lib/python3.6/site-packages/requests/adapters.py", line 516, in send
    raise ConnectionError(e, request=request)
requests.exceptions.ConnectionError: HTTPConnectionPool(host='localhost', port=8097): Max retries exceeded with url: /events (Caused by NewConnectionError('<urllib3.connection.HTTPConnection object at 0x7efabeb2f978>: Failed to establish a new connection: [Errno 111] Connection refused',))
Traceback (most recent call last):
  File "/home/beast/anaconda3/envs/srikar/lib/python3.6/site-packages/urllib3/connection.py", line 160, in _new_conn
    (self._dns_host, self.port), self.timeout, **extra_kw)
  File "/home/beast/anaconda3/envs/srikar/lib/python3.6/site-packages/urllib3/util/connection.py", line 80, in create_connection
    raise err
  File "/home/beast/anaconda3/envs/srikar/lib/python3.6/site-packages/urllib3/util/connection.py", line 70, in create_connection
    sock.connect(sa)
ConnectionRefusedError: [Errno 111] Connection refused

During handling of the above exception, another exception occurred:

Traceback (most recent call last):
  File "/home/beast/anaconda3/envs/srikar/lib/python3.6/site-packages/urllib3/connectionpool.py", line 603, in urlopen
    chunked=chunked)
  File "/home/beast/anaconda3/envs/srikar/lib/python3.6/site-packages/urllib3/connectionpool.py", line 355, in _make_request
    conn.request(method, url, **httplib_request_kw)
  File "/home/beast/anaconda3/envs/srikar/lib/python3.6/http/client.py", line 1239, in request
    self._send_request(method, url, body, headers, encode_chunked)
  File "/home/beast/anaconda3/envs/srikar/lib/python3.6/http/client.py", line 1285, in _send_request
    self.endheaders(body, encode_chunked=encode_chunked)
  File "/home/beast/anaconda3/envs/srikar/lib/python3.6/http/client.py", line 1234, in endheaders
    self._send_output(message_body, encode_chunked=encode_chunked)
  File "/home/beast/anaconda3/envs/srikar/lib/python3.6/http/client.py", line 1026, in _send_output
    self.send(msg)
  File "/home/beast/anaconda3/envs/srikar/lib/python3.6/http/client.py", line 964, in send
    self.connect()
  File "/home/beast/anaconda3/envs/srikar/lib/python3.6/site-packages/urllib3/connection.py", line 183, in connect
    conn = self._new_conn()
  File "/home/beast/anaconda3/envs/srikar/lib/python3.6/site-packages/urllib3/connection.py", line 169, in _new_conn
    self, "Failed to establish a new connection: %s" % e)
urllib3.exceptions.NewConnectionError: <urllib3.connection.HTTPConnection object at 0x7efabf374cf8>: Failed to establish a new connection: [Errno 111] Connection refused

During handling of the above exception, another exception occurred:

Traceback (most recent call last):
  File "/home/beast/anaconda3/envs/srikar/lib/python3.6/site-packages/requests/adapters.py", line 449, in send
    timeout=timeout
  File "/home/beast/anaconda3/envs/srikar/lib/python3.6/site-packages/urllib3/connectionpool.py", line 641, in urlopen
    _stacktrace=sys.exc_info()[2])
  File "/home/beast/anaconda3/envs/srikar/lib/python3.6/site-packages/urllib3/util/retry.py", line 399, in increment
    raise MaxRetryError(_pool, url, error or ResponseError(cause))
urllib3.exceptions.MaxRetryError: HTTPConnectionPool(host='localhost', port=8097): Max retries exceeded with url: /events (Caused by NewConnectionError('<urllib3.connection.HTTPConnection object at 0x7efabf374cf8>: Failed to establish a new connection: [Errno 111] Connection refused',))

During handling of the above exception, another exception occurred:

Traceback (most recent call last):
  File "/home/beast/anaconda3/envs/srikar/lib/python3.6/site-packages/visdom/__init__.py", line 548, in _send
    data=json.dumps(msg),
  File "/home/beast/anaconda3/envs/srikar/lib/python3.6/site-packages/requests/sessions.py", line 581, in post
    return self.request('POST', url, data=data, json=json, **kwargs)
  File "/home/beast/anaconda3/envs/srikar/lib/python3.6/site-packages/requests/sessions.py", line 533, in request
    resp = self.send(prep, **send_kwargs)
  File "/home/beast/anaconda3/envs/srikar/lib/python3.6/site-packages/requests/sessions.py", line 646, in send
    r = adapter.send(request, **kwargs)
  File "/home/beast/anaconda3/envs/srikar/lib/python3.6/site-packages/requests/adapters.py", line 516, in send
    raise ConnectionError(e, request=request)
requests.exceptions.ConnectionError: HTTPConnectionPool(host='localhost', port=8097): Max retries exceeded with url: /events (Caused by NewConnectionError('<urllib3.connection.HTTPConnection object at 0x7efabf374cf8>: Failed to establish a new connection: [Errno 111] Connection refused',))
Traceback (most recent call last):
  File "/home/beast/anaconda3/envs/srikar/lib/python3.6/site-packages/urllib3/connection.py", line 160, in _new_conn
    (self._dns_host, self.port), self.timeout, **extra_kw)
  File "/home/beast/anaconda3/envs/srikar/lib/python3.6/site-packages/urllib3/util/connection.py", line 80, in create_connection
    raise err
  File "/home/beast/anaconda3/envs/srikar/lib/python3.6/site-packages/urllib3/util/connection.py", line 70, in create_connection
    sock.connect(sa)
ConnectionRefusedError: [Errno 111] Connection refused

During handling of the above exception, another exception occurred:

Traceback (most recent call last):
  File "/home/beast/anaconda3/envs/srikar/lib/python3.6/site-packages/urllib3/connectionpool.py", line 603, in urlopen
    chunked=chunked)
  File "/home/beast/anaconda3/envs/srikar/lib/python3.6/site-packages/urllib3/connectionpool.py", line 355, in _make_request
    conn.request(method, url, **httplib_request_kw)
  File "/home/beast/anaconda3/envs/srikar/lib/python3.6/http/client.py", line 1239, in request
    self._send_request(method, url, body, headers, encode_chunked)
  File "/home/beast/anaconda3/envs/srikar/lib/python3.6/http/client.py", line 1285, in _send_request
    self.endheaders(body, encode_chunked=encode_chunked)
  File "/home/beast/anaconda3/envs/srikar/lib/python3.6/http/client.py", line 1234, in endheaders
    self._send_output(message_body, encode_chunked=encode_chunked)
  File "/home/beast/anaconda3/envs/srikar/lib/python3.6/http/client.py", line 1026, in _send_output
    self.send(msg)
  File "/home/beast/anaconda3/envs/srikar/lib/python3.6/http/client.py", line 964, in send
    self.connect()
  File "/home/beast/anaconda3/envs/srikar/lib/python3.6/site-packages/urllib3/connection.py", line 183, in connect
    conn = self._new_conn()
  File "/home/beast/anaconda3/envs/srikar/lib/python3.6/site-packages/urllib3/connection.py", line 169, in _new_conn
    self, "Failed to establish a new connection: %s" % e)
urllib3.exceptions.NewConnectionError: <urllib3.connection.HTTPConnection object at 0x7efabeb2ff60>: Failed to establish a new connection: [Errno 111] Connection refused

During handling of the above exception, another exception occurred:

Traceback (most recent call last):
  File "/home/beast/anaconda3/envs/srikar/lib/python3.6/site-packages/requests/adapters.py", line 449, in send
    timeout=timeout
  File "/home/beast/anaconda3/envs/srikar/lib/python3.6/site-packages/urllib3/connectionpool.py", line 641, in urlopen
    _stacktrace=sys.exc_info()[2])
  File "/home/beast/anaconda3/envs/srikar/lib/python3.6/site-packages/urllib3/util/retry.py", line 399, in increment
    raise MaxRetryError(_pool, url, error or ResponseError(cause))
urllib3.exceptions.MaxRetryError: HTTPConnectionPool(host='localhost', port=8097): Max retries exceeded with url: /events (Caused by NewConnectionError('<urllib3.connection.HTTPConnection object at 0x7efabeb2ff60>: Failed to establish a new connection: [Errno 111] Connection refused',))

During handling of the above exception, another exception occurred:

Traceback (most recent call last):
  File "/home/beast/anaconda3/envs/srikar/lib/python3.6/site-packages/visdom/__init__.py", line 548, in _send
    data=json.dumps(msg),
  File "/home/beast/anaconda3/envs/srikar/lib/python3.6/site-packages/requests/sessions.py", line 581, in post
    return self.request('POST', url, data=data, json=json, **kwargs)
  File "/home/beast/anaconda3/envs/srikar/lib/python3.6/site-packages/requests/sessions.py", line 533, in request
    resp = self.send(prep, **send_kwargs)
  File "/home/beast/anaconda3/envs/srikar/lib/python3.6/site-packages/requests/sessions.py", line 646, in send
    r = adapter.send(request, **kwargs)
  File "/home/beast/anaconda3/envs/srikar/lib/python3.6/site-packages/requests/adapters.py", line 516, in send
    raise ConnectionError(e, request=request)
requests.exceptions.ConnectionError: HTTPConnectionPool(host='localhost', port=8097): Max retries exceeded with url: /events (Caused by NewConnectionError('<urllib3.connection.HTTPConnection object at 0x7efabeb2ff60>: Failed to establish a new connection: [Errno 111] Connection refused',))
Traceback (most recent call last):
  File "/home/beast/anaconda3/envs/srikar/lib/python3.6/site-packages/urllib3/connection.py", line 160, in _new_conn
    (self._dns_host, self.port), self.timeout, **extra_kw)
  File "/home/beast/anaconda3/envs/srikar/lib/python3.6/site-packages/urllib3/util/connection.py", line 80, in create_connection
    raise err
  File "/home/beast/anaconda3/envs/srikar/lib/python3.6/site-packages/urllib3/util/connection.py", line 70, in create_connection
    sock.connect(sa)
ConnectionRefusedError: [Errno 111] Connection refused

During handling of the above exception, another exception occurred:

Traceback (most recent call last):
  File "/home/beast/anaconda3/envs/srikar/lib/python3.6/site-packages/urllib3/connectionpool.py", line 603, in urlopen
    chunked=chunked)
  File "/home/beast/anaconda3/envs/srikar/lib/python3.6/site-packages/urllib3/connectionpool.py", line 355, in _make_request
    conn.request(method, url, **httplib_request_kw)
  File "/home/beast/anaconda3/envs/srikar/lib/python3.6/http/client.py", line 1239, in request
    self._send_request(method, url, body, headers, encode_chunked)
  File "/home/beast/anaconda3/envs/srikar/lib/python3.6/http/client.py", line 1285, in _send_request
    self.endheaders(body, encode_chunked=encode_chunked)
  File "/home/beast/anaconda3/envs/srikar/lib/python3.6/http/client.py", line 1234, in endheaders
    self._send_output(message_body, encode_chunked=encode_chunked)
  File "/home/beast/anaconda3/envs/srikar/lib/python3.6/http/client.py", line 1026, in _send_output
    self.send(msg)
  File "/home/beast/anaconda3/envs/srikar/lib/python3.6/http/client.py", line 964, in send
    self.connect()
  File "/home/beast/anaconda3/envs/srikar/lib/python3.6/site-packages/urllib3/connection.py", line 183, in connect
    conn = self._new_conn()
  File "/home/beast/anaconda3/envs/srikar/lib/python3.6/site-packages/urllib3/connection.py", line 169, in _new_conn
    self, "Failed to establish a new connection: %s" % e)
urllib3.exceptions.NewConnectionError: <urllib3.connection.HTTPConnection object at 0x7efabeb2fcf8>: Failed to establish a new connection: [Errno 111] Connection refused

During handling of the above exception, another exception occurred:

Traceback (most recent call last):
  File "/home/beast/anaconda3/envs/srikar/lib/python3.6/site-packages/requests/adapters.py", line 449, in send
    timeout=timeout
  File "/home/beast/anaconda3/envs/srikar/lib/python3.6/site-packages/urllib3/connectionpool.py", line 641, in urlopen
    _stacktrace=sys.exc_info()[2])
  File "/home/beast/anaconda3/envs/srikar/lib/python3.6/site-packages/urllib3/util/retry.py", line 399, in increment
    raise MaxRetryError(_pool, url, error or ResponseError(cause))
urllib3.exceptions.MaxRetryError: HTTPConnectionPool(host='localhost', port=8097): Max retries exceeded with url: /events (Caused by NewConnectionError('<urllib3.connection.HTTPConnection object at 0x7efabeb2fcf8>: Failed to establish a new connection: [Errno 111] Connection refused',))

During handling of the above exception, another exception occurred:

Traceback (most recent call last):
  File "/home/beast/anaconda3/envs/srikar/lib/python3.6/site-packages/visdom/__init__.py", line 548, in _send
    data=json.dumps(msg),
  File "/home/beast/anaconda3/envs/srikar/lib/python3.6/site-packages/requests/sessions.py", line 581, in post
    return self.request('POST', url, data=data, json=json, **kwargs)
  File "/home/beast/anaconda3/envs/srikar/lib/python3.6/site-packages/requests/sessions.py", line 533, in request
    resp = self.send(prep, **send_kwargs)
  File "/home/beast/anaconda3/envs/srikar/lib/python3.6/site-packages/requests/sessions.py", line 646, in send
    r = adapter.send(request, **kwargs)
  File "/home/beast/anaconda3/envs/srikar/lib/python3.6/site-packages/requests/adapters.py", line 516, in send
    raise ConnectionError(e, request=request)
requests.exceptions.ConnectionError: HTTPConnectionPool(host='localhost', port=8097): Max retries exceeded with url: /events (Caused by NewConnectionError('<urllib3.connection.HTTPConnection object at 0x7efabeb2fcf8>: Failed to establish a new connection: [Errno 111] Connection refused',))
Traceback (most recent call last):
  File "/home/beast/anaconda3/envs/srikar/lib/python3.6/site-packages/urllib3/connection.py", line 160, in _new_conn
    (self._dns_host, self.port), self.timeout, **extra_kw)
  File "/home/beast/anaconda3/envs/srikar/lib/python3.6/site-packages/urllib3/util/connection.py", line 80, in create_connection
    raise err
  File "/home/beast/anaconda3/envs/srikar/lib/python3.6/site-packages/urllib3/util/connection.py", line 70, in create_connection
    sock.connect(sa)
ConnectionRefusedError: [Errno 111] Connection refused

During handling of the above exception, another exception occurred:

Traceback (most recent call last):
  File "/home/beast/anaconda3/envs/srikar/lib/python3.6/site-packages/urllib3/connectionpool.py", line 603, in urlopen
    chunked=chunked)
  File "/home/beast/anaconda3/envs/srikar/lib/python3.6/site-packages/urllib3/connectionpool.py", line 355, in _make_request
    conn.request(method, url, **httplib_request_kw)
  File "/home/beast/anaconda3/envs/srikar/lib/python3.6/http/client.py", line 1239, in request
    self._send_request(method, url, body, headers, encode_chunked)
  File "/home/beast/anaconda3/envs/srikar/lib/python3.6/http/client.py", line 1285, in _send_request
    self.endheaders(body, encode_chunked=encode_chunked)
  File "/home/beast/anaconda3/envs/srikar/lib/python3.6/http/client.py", line 1234, in endheaders
    self._send_output(message_body, encode_chunked=encode_chunked)
  File "/home/beast/anaconda3/envs/srikar/lib/python3.6/http/client.py", line 1026, in _send_output
    self.send(msg)
  File "/home/beast/anaconda3/envs/srikar/lib/python3.6/http/client.py", line 964, in send
    self.connect()
  File "/home/beast/anaconda3/envs/srikar/lib/python3.6/site-packages/urllib3/connection.py", line 183, in connect
    conn = self._new_conn()
  File "/home/beast/anaconda3/envs/srikar/lib/python3.6/site-packages/urllib3/connection.py", line 169, in _new_conn
    self, "Failed to establish a new connection: %s" % e)
urllib3.exceptions.NewConnectionError: <urllib3.connection.HTTPConnection object at 0x7efabf3748d0>: Failed to establish a new connection: [Errno 111] Connection refused

During handling of the above exception, another exception occurred:

Traceback (most recent call last):
  File "/home/beast/anaconda3/envs/srikar/lib/python3.6/site-packages/requests/adapters.py", line 449, in send
    timeout=timeout
  File "/home/beast/anaconda3/envs/srikar/lib/python3.6/site-packages/urllib3/connectionpool.py", line 641, in urlopen
    _stacktrace=sys.exc_info()[2])
  File "/home/beast/anaconda3/envs/srikar/lib/python3.6/site-packages/urllib3/util/retry.py", line 399, in increment
    raise MaxRetryError(_pool, url, error or ResponseError(cause))
urllib3.exceptions.MaxRetryError: HTTPConnectionPool(host='localhost', port=8097): Max retries exceeded with url: /events (Caused by NewConnectionError('<urllib3.connection.HTTPConnection object at 0x7efabf3748d0>: Failed to establish a new connection: [Errno 111] Connection refused',))

During handling of the above exception, another exception occurred:

Traceback (most recent call last):
  File "/home/beast/anaconda3/envs/srikar/lib/python3.6/site-packages/visdom/__init__.py", line 548, in _send
    data=json.dumps(msg),
  File "/home/beast/anaconda3/envs/srikar/lib/python3.6/site-packages/requests/sessions.py", line 581, in post
    return self.request('POST', url, data=data, json=json, **kwargs)
  File "/home/beast/anaconda3/envs/srikar/lib/python3.6/site-packages/requests/sessions.py", line 533, in request
    resp = self.send(prep, **send_kwargs)
  File "/home/beast/anaconda3/envs/srikar/lib/python3.6/site-packages/requests/sessions.py", line 646, in send
    r = adapter.send(request, **kwargs)
  File "/home/beast/anaconda3/envs/srikar/lib/python3.6/site-packages/requests/adapters.py", line 516, in send
    raise ConnectionError(e, request=request)
requests.exceptions.ConnectionError: HTTPConnectionPool(host='localhost', port=8097): Max retries exceeded with url: /events (Caused by NewConnectionError('<urllib3.connection.HTTPConnection object at 0x7efabf3748d0>: Failed to establish a new connection: [Errno 111] Connection refused',))
Traceback (most recent call last):
  File "/home/beast/anaconda3/envs/srikar/lib/python3.6/site-packages/urllib3/connection.py", line 160, in _new_conn
    (self._dns_host, self.port), self.timeout, **extra_kw)
  File "/home/beast/anaconda3/envs/srikar/lib/python3.6/site-packages/urllib3/util/connection.py", line 80, in create_connection
    raise err
  File "/home/beast/anaconda3/envs/srikar/lib/python3.6/site-packages/urllib3/util/connection.py", line 70, in create_connection
    sock.connect(sa)
ConnectionRefusedError: [Errno 111] Connection refused

During handling of the above exception, another exception occurred:

Traceback (most recent call last):
  File "/home/beast/anaconda3/envs/srikar/lib/python3.6/site-packages/urllib3/connectionpool.py", line 603, in urlopen
    chunked=chunked)
  File "/home/beast/anaconda3/envs/srikar/lib/python3.6/site-packages/urllib3/connectionpool.py", line 355, in _make_request
    conn.request(method, url, **httplib_request_kw)
  File "/home/beast/anaconda3/envs/srikar/lib/python3.6/http/client.py", line 1239, in request
    self._send_request(method, url, body, headers, encode_chunked)
  File "/home/beast/anaconda3/envs/srikar/lib/python3.6/http/client.py", line 1285, in _send_request
    self.endheaders(body, encode_chunked=encode_chunked)
  File "/home/beast/anaconda3/envs/srikar/lib/python3.6/http/client.py", line 1234, in endheaders
    self._send_output(message_body, encode_chunked=encode_chunked)
  File "/home/beast/anaconda3/envs/srikar/lib/python3.6/http/client.py", line 1026, in _send_output
    self.send(msg)
  File "/home/beast/anaconda3/envs/srikar/lib/python3.6/http/client.py", line 964, in send
    self.connect()
  File "/home/beast/anaconda3/envs/srikar/lib/python3.6/site-packages/urllib3/connection.py", line 183, in connect
    conn = self._new_conn()
  File "/home/beast/anaconda3/envs/srikar/lib/python3.6/site-packages/urllib3/connection.py", line 169, in _new_conn
    self, "Failed to establish a new connection: %s" % e)
urllib3.exceptions.NewConnectionError: <urllib3.connection.HTTPConnection object at 0x7efabeb2feb8>: Failed to establish a new connection: [Errno 111] Connection refused

During handling of the above exception, another exception occurred:

Traceback (most recent call last):
  File "/home/beast/anaconda3/envs/srikar/lib/python3.6/site-packages/requests/adapters.py", line 449, in send
    timeout=timeout
  File "/home/beast/anaconda3/envs/srikar/lib/python3.6/site-packages/urllib3/connectionpool.py", line 641, in urlopen
    _stacktrace=sys.exc_info()[2])
  File "/home/beast/anaconda3/envs/srikar/lib/python3.6/site-packages/urllib3/util/retry.py", line 399, in increment
    raise MaxRetryError(_pool, url, error or ResponseError(cause))
urllib3.exceptions.MaxRetryError: HTTPConnectionPool(host='localhost', port=8097): Max retries exceeded with url: /events (Caused by NewConnectionError('<urllib3.connection.HTTPConnection object at 0x7efabeb2feb8>: Failed to establish a new connection: [Errno 111] Connection refused',))

During handling of the above exception, another exception occurred:

Traceback (most recent call last):
  File "/home/beast/anaconda3/envs/srikar/lib/python3.6/site-packages/visdom/__init__.py", line 548, in _send
    data=json.dumps(msg),
  File "/home/beast/anaconda3/envs/srikar/lib/python3.6/site-packages/requests/sessions.py", line 581, in post
    return self.request('POST', url, data=data, json=json, **kwargs)
  File "/home/beast/anaconda3/envs/srikar/lib/python3.6/site-packages/requests/sessions.py", line 533, in request
    resp = self.send(prep, **send_kwargs)
  File "/home/beast/anaconda3/envs/srikar/lib/python3.6/site-packages/requests/sessions.py", line 646, in send
    r = adapter.send(request, **kwargs)
  File "/home/beast/anaconda3/envs/srikar/lib/python3.6/site-packages/requests/adapters.py", line 516, in send
    raise ConnectionError(e, request=request)
requests.exceptions.ConnectionError: HTTPConnectionPool(host='localhost', port=8097): Max retries exceeded with url: /events (Caused by NewConnectionError('<urllib3.connection.HTTPConnection object at 0x7efabeb2feb8>: Failed to establish a new connection: [Errno 111] Connection refused',))
Traceback (most recent call last):
  File "/home/beast/anaconda3/envs/srikar/lib/python3.6/site-packages/urllib3/connection.py", line 160, in _new_conn
    (self._dns_host, self.port), self.timeout, **extra_kw)
  File "/home/beast/anaconda3/envs/srikar/lib/python3.6/site-packages/urllib3/util/connection.py", line 80, in create_connection
    raise err
  File "/home/beast/anaconda3/envs/srikar/lib/python3.6/site-packages/urllib3/util/connection.py", line 70, in create_connection
    sock.connect(sa)
ConnectionRefusedError: [Errno 111] Connection refused

During handling of the above exception, another exception occurred:

Traceback (most recent call last):
  File "/home/beast/anaconda3/envs/srikar/lib/python3.6/site-packages/urllib3/connectionpool.py", line 603, in urlopen
    chunked=chunked)
  File "/home/beast/anaconda3/envs/srikar/lib/python3.6/site-packages/urllib3/connectionpool.py", line 355, in _make_request
    conn.request(method, url, **httplib_request_kw)
  File "/home/beast/anaconda3/envs/srikar/lib/python3.6/http/client.py", line 1239, in request
    self._send_request(method, url, body, headers, encode_chunked)
  File "/home/beast/anaconda3/envs/srikar/lib/python3.6/http/client.py", line 1285, in _send_request
    self.endheaders(body, encode_chunked=encode_chunked)
  File "/home/beast/anaconda3/envs/srikar/lib/python3.6/http/client.py", line 1234, in endheaders
    self._send_output(message_body, encode_chunked=encode_chunked)
  File "/home/beast/anaconda3/envs/srikar/lib/python3.6/http/client.py", line 1026, in _send_output
    self.send(msg)
  File "/home/beast/anaconda3/envs/srikar/lib/python3.6/http/client.py", line 964, in send
    self.connect()
  File "/home/beast/anaconda3/envs/srikar/lib/python3.6/site-packages/urllib3/connection.py", line 183, in connect
    conn = self._new_conn()
  File "/home/beast/anaconda3/envs/srikar/lib/python3.6/site-packages/urllib3/connection.py", line 169, in _new_conn
    self, "Failed to establish a new connection: %s" % e)
urllib3.exceptions.NewConnectionError: <urllib3.connection.HTTPConnection object at 0x7efabf3910f0>: Failed to establish a new connection: [Errno 111] Connection refused

During handling of the above exception, another exception occurred:

Traceback (most recent call last):
  File "/home/beast/anaconda3/envs/srikar/lib/python3.6/site-packages/requests/adapters.py", line 449, in send
    timeout=timeout
  File "/home/beast/anaconda3/envs/srikar/lib/python3.6/site-packages/urllib3/connectionpool.py", line 641, in urlopen
    _stacktrace=sys.exc_info()[2])
  File "/home/beast/anaconda3/envs/srikar/lib/python3.6/site-packages/urllib3/util/retry.py", line 399, in increment
    raise MaxRetryError(_pool, url, error or ResponseError(cause))
urllib3.exceptions.MaxRetryError: HTTPConnectionPool(host='localhost', port=8097): Max retries exceeded with url: /events (Caused by NewConnectionError('<urllib3.connection.HTTPConnection object at 0x7efabf3910f0>: Failed to establish a new connection: [Errno 111] Connection refused',))

During handling of the above exception, another exception occurred:

Traceback (most recent call last):
  File "/home/beast/anaconda3/envs/srikar/lib/python3.6/site-packages/visdom/__init__.py", line 548, in _send
    data=json.dumps(msg),
  File "/home/beast/anaconda3/envs/srikar/lib/python3.6/site-packages/requests/sessions.py", line 581, in post
    return self.request('POST', url, data=data, json=json, **kwargs)
  File "/home/beast/anaconda3/envs/srikar/lib/python3.6/site-packages/requests/sessions.py", line 533, in request
    resp = self.send(prep, **send_kwargs)
  File "/home/beast/anaconda3/envs/srikar/lib/python3.6/site-packages/requests/sessions.py", line 646, in send
    r = adapter.send(request, **kwargs)
  File "/home/beast/anaconda3/envs/srikar/lib/python3.6/site-packages/requests/adapters.py", line 516, in send
    raise ConnectionError(e, request=request)
requests.exceptions.ConnectionError: HTTPConnectionPool(host='localhost', port=8097): Max retries exceeded with url: /events (Caused by NewConnectionError('<urllib3.connection.HTTPConnection object at 0x7efabf3910f0>: Failed to establish a new connection: [Errno 111] Connection refused',))
Traceback (most recent call last):
  File "/home/beast/anaconda3/envs/srikar/lib/python3.6/site-packages/urllib3/connection.py", line 160, in _new_conn
    (self._dns_host, self.port), self.timeout, **extra_kw)
  File "/home/beast/anaconda3/envs/srikar/lib/python3.6/site-packages/urllib3/util/connection.py", line 80, in create_connection
    raise err
  File "/home/beast/anaconda3/envs/srikar/lib/python3.6/site-packages/urllib3/util/connection.py", line 70, in create_connection
    sock.connect(sa)
ConnectionRefusedError: [Errno 111] Connection refused

During handling of the above exception, another exception occurred:

Traceback (most recent call last):
  File "/home/beast/anaconda3/envs/srikar/lib/python3.6/site-packages/urllib3/connectionpool.py", line 603, in urlopen
    chunked=chunked)
  File "/home/beast/anaconda3/envs/srikar/lib/python3.6/site-packages/urllib3/connectionpool.py", line 355, in _make_request
    conn.request(method, url, **httplib_request_kw)
  File "/home/beast/anaconda3/envs/srikar/lib/python3.6/http/client.py", line 1239, in request
    self._send_request(method, url, body, headers, encode_chunked)
  File "/home/beast/anaconda3/envs/srikar/lib/python3.6/http/client.py", line 1285, in _send_request
    self.endheaders(body, encode_chunked=encode_chunked)
  File "/home/beast/anaconda3/envs/srikar/lib/python3.6/http/client.py", line 1234, in endheaders
    self._send_output(message_body, encode_chunked=encode_chunked)
  File "/home/beast/anaconda3/envs/srikar/lib/python3.6/http/client.py", line 1026, in _send_output
    self.send(msg)
  File "/home/beast/anaconda3/envs/srikar/lib/python3.6/http/client.py", line 964, in send
    self.connect()
  File "/home/beast/anaconda3/envs/srikar/lib/python3.6/site-packages/urllib3/connection.py", line 183, in connect
    conn = self._new_conn()
  File "/home/beast/anaconda3/envs/srikar/lib/python3.6/site-packages/urllib3/connection.py", line 169, in _new_conn
    self, "Failed to establish a new connection: %s" % e)
urllib3.exceptions.NewConnectionError: <urllib3.connection.HTTPConnection object at 0x7efabf374a58>: Failed to establish a new connection: [Errno 111] Connection refused

During handling of the above exception, another exception occurred:

Traceback (most recent call last):
  File "/home/beast/anaconda3/envs/srikar/lib/python3.6/site-packages/requests/adapters.py", line 449, in send
    timeout=timeout
  File "/home/beast/anaconda3/envs/srikar/lib/python3.6/site-packages/urllib3/connectionpool.py", line 641, in urlopen
    _stacktrace=sys.exc_info()[2])
  File "/home/beast/anaconda3/envs/srikar/lib/python3.6/site-packages/urllib3/util/retry.py", line 399, in increment
    raise MaxRetryError(_pool, url, error or ResponseError(cause))
urllib3.exceptions.MaxRetryError: HTTPConnectionPool(host='localhost', port=8097): Max retries exceeded with url: /events (Caused by NewConnectionError('<urllib3.connection.HTTPConnection object at 0x7efabf374a58>: Failed to establish a new connection: [Errno 111] Connection refused',))

During handling of the above exception, another exception occurred:

Traceback (most recent call last):
  File "/home/beast/anaconda3/envs/srikar/lib/python3.6/site-packages/visdom/__init__.py", line 548, in _send
    data=json.dumps(msg),
  File "/home/beast/anaconda3/envs/srikar/lib/python3.6/site-packages/requests/sessions.py", line 581, in post
    return self.request('POST', url, data=data, json=json, **kwargs)
  File "/home/beast/anaconda3/envs/srikar/lib/python3.6/site-packages/requests/sessions.py", line 533, in request
    resp = self.send(prep, **send_kwargs)
  File "/home/beast/anaconda3/envs/srikar/lib/python3.6/site-packages/requests/sessions.py", line 646, in send
    r = adapter.send(request, **kwargs)
  File "/home/beast/anaconda3/envs/srikar/lib/python3.6/site-packages/requests/adapters.py", line 516, in send
    raise ConnectionError(e, request=request)
requests.exceptions.ConnectionError: HTTPConnectionPool(host='localhost', port=8097): Max retries exceeded with url: /events (Caused by NewConnectionError('<urllib3.connection.HTTPConnection object at 0x7efabf374a58>: Failed to establish a new connection: [Errno 111] Connection refused',))
Traceback (most recent call last):
  File "/home/beast/anaconda3/envs/srikar/lib/python3.6/site-packages/urllib3/connection.py", line 160, in _new_conn
    (self._dns_host, self.port), self.timeout, **extra_kw)
  File "/home/beast/anaconda3/envs/srikar/lib/python3.6/site-packages/urllib3/util/connection.py", line 80, in create_connection
    raise err
  File "/home/beast/anaconda3/envs/srikar/lib/python3.6/site-packages/urllib3/util/connection.py", line 70, in create_connection
    sock.connect(sa)
ConnectionRefusedError: [Errno 111] Connection refused

During handling of the above exception, another exception occurred:

Traceback (most recent call last):
  File "/home/beast/anaconda3/envs/srikar/lib/python3.6/site-packages/urllib3/connectionpool.py", line 603, in urlopen
    chunked=chunked)
  File "/home/beast/anaconda3/envs/srikar/lib/python3.6/site-packages/urllib3/connectionpool.py", line 355, in _make_request
    conn.request(method, url, **httplib_request_kw)
  File "/home/beast/anaconda3/envs/srikar/lib/python3.6/http/client.py", line 1239, in request
    self._send_request(method, url, body, headers, encode_chunked)
  File "/home/beast/anaconda3/envs/srikar/lib/python3.6/http/client.py", line 1285, in _send_request
    self.endheaders(body, encode_chunked=encode_chunked)
  File "/home/beast/anaconda3/envs/srikar/lib/python3.6/http/client.py", line 1234, in endheaders
    self._send_output(message_body, encode_chunked=encode_chunked)
  File "/home/beast/anaconda3/envs/srikar/lib/python3.6/http/client.py", line 1026, in _send_output
    self.send(msg)
  File "/home/beast/anaconda3/envs/srikar/lib/python3.6/http/client.py", line 964, in send
    self.connect()
  File "/home/beast/anaconda3/envs/srikar/lib/python3.6/site-packages/urllib3/connection.py", line 183, in connect
    conn = self._new_conn()
  File "/home/beast/anaconda3/envs/srikar/lib/python3.6/site-packages/urllib3/connection.py", line 169, in _new_conn
    self, "Failed to establish a new connection: %s" % e)
urllib3.exceptions.NewConnectionError: <urllib3.connection.HTTPConnection object at 0x7efabeb2f588>: Failed to establish a new connection: [Errno 111] Connection refused

During handling of the above exception, another exception occurred:

Traceback (most recent call last):
  File "/home/beast/anaconda3/envs/srikar/lib/python3.6/site-packages/requests/adapters.py", line 449, in send
    timeout=timeout
  File "/home/beast/anaconda3/envs/srikar/lib/python3.6/site-packages/urllib3/connectionpool.py", line 641, in urlopen
    _stacktrace=sys.exc_info()[2])
  File "/home/beast/anaconda3/envs/srikar/lib/python3.6/site-packages/urllib3/util/retry.py", line 399, in increment
    raise MaxRetryError(_pool, url, error or ResponseError(cause))
urllib3.exceptions.MaxRetryError: HTTPConnectionPool(host='localhost', port=8097): Max retries exceeded with url: /events (Caused by NewConnectionError('<urllib3.connection.HTTPConnection object at 0x7efabeb2f588>: Failed to establish a new connection: [Errno 111] Connection refused',))

During handling of the above exception, another exception occurred:

Traceback (most recent call last):
  File "/home/beast/anaconda3/envs/srikar/lib/python3.6/site-packages/visdom/__init__.py", line 548, in _send
    data=json.dumps(msg),
  File "/home/beast/anaconda3/envs/srikar/lib/python3.6/site-packages/requests/sessions.py", line 581, in post
    return self.request('POST', url, data=data, json=json, **kwargs)
  File "/home/beast/anaconda3/envs/srikar/lib/python3.6/site-packages/requests/sessions.py", line 533, in request
    resp = self.send(prep, **send_kwargs)
  File "/home/beast/anaconda3/envs/srikar/lib/python3.6/site-packages/requests/sessions.py", line 646, in send
    r = adapter.send(request, **kwargs)
  File "/home/beast/anaconda3/envs/srikar/lib/python3.6/site-packages/requests/adapters.py", line 516, in send
    raise ConnectionError(e, request=request)
requests.exceptions.ConnectionError: HTTPConnectionPool(host='localhost', port=8097): Max retries exceeded with url: /events (Caused by NewConnectionError('<urllib3.connection.HTTPConnection object at 0x7efabeb2f588>: Failed to establish a new connection: [Errno 111] Connection refused',))
Traceback (most recent call last):
  File "/home/beast/anaconda3/envs/srikar/lib/python3.6/site-packages/urllib3/connection.py", line 160, in _new_conn
    (self._dns_host, self.port), self.timeout, **extra_kw)
  File "/home/beast/anaconda3/envs/srikar/lib/python3.6/site-packages/urllib3/util/connection.py", line 80, in create_connection
    raise err
  File "/home/beast/anaconda3/envs/srikar/lib/python3.6/site-packages/urllib3/util/connection.py", line 70, in create_connection
    sock.connect(sa)
ConnectionRefusedError: [Errno 111] Connection refused

During handling of the above exception, another exception occurred:

Traceback (most recent call last):
  File "/home/beast/anaconda3/envs/srikar/lib/python3.6/site-packages/urllib3/connectionpool.py", line 603, in urlopen
    chunked=chunked)
  File "/home/beast/anaconda3/envs/srikar/lib/python3.6/site-packages/urllib3/connectionpool.py", line 355, in _make_request
    conn.request(method, url, **httplib_request_kw)
  File "/home/beast/anaconda3/envs/srikar/lib/python3.6/http/client.py", line 1239, in request
    self._send_request(method, url, body, headers, encode_chunked)
  File "/home/beast/anaconda3/envs/srikar/lib/python3.6/http/client.py", line 1285, in _send_request
    self.endheaders(body, encode_chunked=encode_chunked)
  File "/home/beast/anaconda3/envs/srikar/lib/python3.6/http/client.py", line 1234, in endheaders
    self._send_output(message_body, encode_chunked=encode_chunked)
  File "/home/beast/anaconda3/envs/srikar/lib/python3.6/http/client.py", line 1026, in _send_output
    self.send(msg)
  File "/home/beast/anaconda3/envs/srikar/lib/python3.6/http/client.py", line 964, in send
    self.connect()
  File "/home/beast/anaconda3/envs/srikar/lib/python3.6/site-packages/urllib3/connection.py", line 183, in connect
    conn = self._new_conn()
  File "/home/beast/anaconda3/envs/srikar/lib/python3.6/site-packages/urllib3/connection.py", line 169, in _new_conn
    self, "Failed to establish a new connection: %s" % e)
urllib3.exceptions.NewConnectionError: <urllib3.connection.HTTPConnection object at 0x7efabf3918d0>: Failed to establish a new connection: [Errno 111] Connection refused

During handling of the above exception, another exception occurred:

Traceback (most recent call last):
  File "/home/beast/anaconda3/envs/srikar/lib/python3.6/site-packages/requests/adapters.py", line 449, in send
    timeout=timeout
  File "/home/beast/anaconda3/envs/srikar/lib/python3.6/site-packages/urllib3/connectionpool.py", line 641, in urlopen
    _stacktrace=sys.exc_info()[2])
  File "/home/beast/anaconda3/envs/srikar/lib/python3.6/site-packages/urllib3/util/retry.py", line 399, in increment
    raise MaxRetryError(_pool, url, error or ResponseError(cause))
urllib3.exceptions.MaxRetryError: HTTPConnectionPool(host='localhost', port=8097): Max retries exceeded with url: /events (Caused by NewConnectionError('<urllib3.connection.HTTPConnection object at 0x7efabf3918d0>: Failed to establish a new connection: [Errno 111] Connection refused',))

During handling of the above exception, another exception occurred:

Traceback (most recent call last):
  File "/home/beast/anaconda3/envs/srikar/lib/python3.6/site-packages/visdom/__init__.py", line 548, in _send
    data=json.dumps(msg),
  File "/home/beast/anaconda3/envs/srikar/lib/python3.6/site-packages/requests/sessions.py", line 581, in post
    return self.request('POST', url, data=data, json=json, **kwargs)
  File "/home/beast/anaconda3/envs/srikar/lib/python3.6/site-packages/requests/sessions.py", line 533, in request
    resp = self.send(prep, **send_kwargs)
  File "/home/beast/anaconda3/envs/srikar/lib/python3.6/site-packages/requests/sessions.py", line 646, in send
    r = adapter.send(request, **kwargs)
  File "/home/beast/anaconda3/envs/srikar/lib/python3.6/site-packages/requests/adapters.py", line 516, in send
    raise ConnectionError(e, request=request)
requests.exceptions.ConnectionError: HTTPConnectionPool(host='localhost', port=8097): Max retries exceeded with url: /events (Caused by NewConnectionError('<urllib3.connection.HTTPConnection object at 0x7efabf3918d0>: Failed to establish a new connection: [Errno 111] Connection refused',))
Traceback (most recent call last):
  File "/home/beast/anaconda3/envs/srikar/lib/python3.6/site-packages/urllib3/connection.py", line 160, in _new_conn
    (self._dns_host, self.port), self.timeout, **extra_kw)
  File "/home/beast/anaconda3/envs/srikar/lib/python3.6/site-packages/urllib3/util/connection.py", line 80, in create_connection
    raise err
  File "/home/beast/anaconda3/envs/srikar/lib/python3.6/site-packages/urllib3/util/connection.py", line 70, in create_connection
    sock.connect(sa)
ConnectionRefusedError: [Errno 111] Connection refused

During handling of the above exception, another exception occurred:

Traceback (most recent call last):
  File "/home/beast/anaconda3/envs/srikar/lib/python3.6/site-packages/urllib3/connectionpool.py", line 603, in urlopen
    chunked=chunked)
  File "/home/beast/anaconda3/envs/srikar/lib/python3.6/site-packages/urllib3/connectionpool.py", line 355, in _make_request
    conn.request(method, url, **httplib_request_kw)
  File "/home/beast/anaconda3/envs/srikar/lib/python3.6/http/client.py", line 1239, in request
    self._send_request(method, url, body, headers, encode_chunked)
  File "/home/beast/anaconda3/envs/srikar/lib/python3.6/http/client.py", line 1285, in _send_request
    self.endheaders(body, encode_chunked=encode_chunked)
  File "/home/beast/anaconda3/envs/srikar/lib/python3.6/http/client.py", line 1234, in endheaders
    self._send_output(message_body, encode_chunked=encode_chunked)
  File "/home/beast/anaconda3/envs/srikar/lib/python3.6/http/client.py", line 1026, in _send_output
    self.send(msg)
  File "/home/beast/anaconda3/envs/srikar/lib/python3.6/http/client.py", line 964, in send
    self.connect()
  File "/home/beast/anaconda3/envs/srikar/lib/python3.6/site-packages/urllib3/connection.py", line 183, in connect
    conn = self._new_conn()
  File "/home/beast/anaconda3/envs/srikar/lib/python3.6/site-packages/urllib3/connection.py", line 169, in _new_conn
    self, "Failed to establish a new connection: %s" % e)
urllib3.exceptions.NewConnectionError: <urllib3.connection.HTTPConnection object at 0x7efabf5f8f60>: Failed to establish a new connection: [Errno 111] Connection refused

During handling of the above exception, another exception occurred:

Traceback (most recent call last):
  File "/home/beast/anaconda3/envs/srikar/lib/python3.6/site-packages/requests/adapters.py", line 449, in send
    timeout=timeout
  File "/home/beast/anaconda3/envs/srikar/lib/python3.6/site-packages/urllib3/connectionpool.py", line 641, in urlopen
    _stacktrace=sys.exc_info()[2])
  File "/home/beast/anaconda3/envs/srikar/lib/python3.6/site-packages/urllib3/util/retry.py", line 399, in increment
    raise MaxRetryError(_pool, url, error or ResponseError(cause))
urllib3.exceptions.MaxRetryError: HTTPConnectionPool(host='localhost', port=8097): Max retries exceeded with url: /events (Caused by NewConnectionError('<urllib3.connection.HTTPConnection object at 0x7efabf5f8f60>: Failed to establish a new connection: [Errno 111] Connection refused',))

During handling of the above exception, another exception occurred:

Traceback (most recent call last):
  File "/home/beast/anaconda3/envs/srikar/lib/python3.6/site-packages/visdom/__init__.py", line 548, in _send
    data=json.dumps(msg),
  File "/home/beast/anaconda3/envs/srikar/lib/python3.6/site-packages/requests/sessions.py", line 581, in post
    return self.request('POST', url, data=data, json=json, **kwargs)
  File "/home/beast/anaconda3/envs/srikar/lib/python3.6/site-packages/requests/sessions.py", line 533, in request
    resp = self.send(prep, **send_kwargs)
  File "/home/beast/anaconda3/envs/srikar/lib/python3.6/site-packages/requests/sessions.py", line 646, in send
    r = adapter.send(request, **kwargs)
  File "/home/beast/anaconda3/envs/srikar/lib/python3.6/site-packages/requests/adapters.py", line 516, in send
    raise ConnectionError(e, request=request)
requests.exceptions.ConnectionError: HTTPConnectionPool(host='localhost', port=8097): Max retries exceeded with url: /events (Caused by NewConnectionError('<urllib3.connection.HTTPConnection object at 0x7efabf5f8f60>: Failed to establish a new connection: [Errno 111] Connection refused',))
Traceback (most recent call last):
  File "/home/beast/anaconda3/envs/srikar/lib/python3.6/site-packages/urllib3/connection.py", line 160, in _new_conn
    (self._dns_host, self.port), self.timeout, **extra_kw)
  File "/home/beast/anaconda3/envs/srikar/lib/python3.6/site-packages/urllib3/util/connection.py", line 80, in create_connection
    raise err
  File "/home/beast/anaconda3/envs/srikar/lib/python3.6/site-packages/urllib3/util/connection.py", line 70, in create_connection
    sock.connect(sa)
ConnectionRefusedError: [Errno 111] Connection refused

During handling of the above exception, another exception occurred:

Traceback (most recent call last):
  File "/home/beast/anaconda3/envs/srikar/lib/python3.6/site-packages/urllib3/connectionpool.py", line 603, in urlopen
    chunked=chunked)
  File "/home/beast/anaconda3/envs/srikar/lib/python3.6/site-packages/urllib3/connectionpool.py", line 355, in _make_request
    conn.request(method, url, **httplib_request_kw)
  File "/home/beast/anaconda3/envs/srikar/lib/python3.6/http/client.py", line 1239, in request
    self._send_request(method, url, body, headers, encode_chunked)
  File "/home/beast/anaconda3/envs/srikar/lib/python3.6/http/client.py", line 1285, in _send_request
    self.endheaders(body, encode_chunked=encode_chunked)
  File "/home/beast/anaconda3/envs/srikar/lib/python3.6/http/client.py", line 1234, in endheaders
    self._send_output(message_body, encode_chunked=encode_chunked)
  File "/home/beast/anaconda3/envs/srikar/lib/python3.6/http/client.py", line 1026, in _send_output
    self.send(msg)
  File "/home/beast/anaconda3/envs/srikar/lib/python3.6/http/client.py", line 964, in send
    self.connect()
  File "/home/beast/anaconda3/envs/srikar/lib/python3.6/site-packages/urllib3/connection.py", line 183, in connect
    conn = self._new_conn()
  File "/home/beast/anaconda3/envs/srikar/lib/python3.6/site-packages/urllib3/connection.py", line 169, in _new_conn
    self, "Failed to establish a new connection: %s" % e)
urllib3.exceptions.NewConnectionError: <urllib3.connection.HTTPConnection object at 0x7efabead87f0>: Failed to establish a new connection: [Errno 111] Connection refused

During handling of the above exception, another exception occurred:

Traceback (most recent call last):
  File "/home/beast/anaconda3/envs/srikar/lib/python3.6/site-packages/requests/adapters.py", line 449, in send
    timeout=timeout
  File "/home/beast/anaconda3/envs/srikar/lib/python3.6/site-packages/urllib3/connectionpool.py", line 641, in urlopen
    _stacktrace=sys.exc_info()[2])
  File "/home/beast/anaconda3/envs/srikar/lib/python3.6/site-packages/urllib3/util/retry.py", line 399, in increment
    raise MaxRetryError(_pool, url, error or ResponseError(cause))
urllib3.exceptions.MaxRetryError: HTTPConnectionPool(host='localhost', port=8097): Max retries exceeded with url: /events (Caused by NewConnectionError('<urllib3.connection.HTTPConnection object at 0x7efabead87f0>: Failed to establish a new connection: [Errno 111] Connection refused',))

During handling of the above exception, another exception occurred:

Traceback (most recent call last):
  File "/home/beast/anaconda3/envs/srikar/lib/python3.6/site-packages/visdom/__init__.py", line 548, in _send
    data=json.dumps(msg),
  File "/home/beast/anaconda3/envs/srikar/lib/python3.6/site-packages/requests/sessions.py", line 581, in post
    return self.request('POST', url, data=data, json=json, **kwargs)
  File "/home/beast/anaconda3/envs/srikar/lib/python3.6/site-packages/requests/sessions.py", line 533, in request
    resp = self.send(prep, **send_kwargs)
  File "/home/beast/anaconda3/envs/srikar/lib/python3.6/site-packages/requests/sessions.py", line 646, in send
    r = adapter.send(request, **kwargs)
  File "/home/beast/anaconda3/envs/srikar/lib/python3.6/site-packages/requests/adapters.py", line 516, in send
    raise ConnectionError(e, request=request)
requests.exceptions.ConnectionError: HTTPConnectionPool(host='localhost', port=8097): Max retries exceeded with url: /events (Caused by NewConnectionError('<urllib3.connection.HTTPConnection object at 0x7efabead87f0>: Failed to establish a new connection: [Errno 111] Connection refused',))
Traceback (most recent call last):
  File "/home/beast/anaconda3/envs/srikar/lib/python3.6/site-packages/urllib3/connection.py", line 160, in _new_conn
    (self._dns_host, self.port), self.timeout, **extra_kw)
  File "/home/beast/anaconda3/envs/srikar/lib/python3.6/site-packages/urllib3/util/connection.py", line 80, in create_connection
    raise err
  File "/home/beast/anaconda3/envs/srikar/lib/python3.6/site-packages/urllib3/util/connection.py", line 70, in create_connection
    sock.connect(sa)
ConnectionRefusedError: [Errno 111] Connection refused

During handling of the above exception, another exception occurred:

Traceback (most recent call last):
  File "/home/beast/anaconda3/envs/srikar/lib/python3.6/site-packages/urllib3/connectionpool.py", line 603, in urlopen
    chunked=chunked)
  File "/home/beast/anaconda3/envs/srikar/lib/python3.6/site-packages/urllib3/connectionpool.py", line 355, in _make_request
    conn.request(method, url, **httplib_request_kw)
  File "/home/beast/anaconda3/envs/srikar/lib/python3.6/http/client.py", line 1239, in request
    self._send_request(method, url, body, headers, encode_chunked)
  File "/home/beast/anaconda3/envs/srikar/lib/python3.6/http/client.py", line 1285, in _send_request
    self.endheaders(body, encode_chunked=encode_chunked)
  File "/home/beast/anaconda3/envs/srikar/lib/python3.6/http/client.py", line 1234, in endheaders
    self._send_output(message_body, encode_chunked=encode_chunked)
  File "/home/beast/anaconda3/envs/srikar/lib/python3.6/http/client.py", line 1026, in _send_output
    self.send(msg)
  File "/home/beast/anaconda3/envs/srikar/lib/python3.6/http/client.py", line 964, in send
    self.connect()
  File "/home/beast/anaconda3/envs/srikar/lib/python3.6/site-packages/urllib3/connection.py", line 183, in connect
    conn = self._new_conn()
  File "/home/beast/anaconda3/envs/srikar/lib/python3.6/site-packages/urllib3/connection.py", line 169, in _new_conn
    self, "Failed to establish a new connection: %s" % e)
urllib3.exceptions.NewConnectionError: <urllib3.connection.HTTPConnection object at 0x7efabf391da0>: Failed to establish a new connection: [Errno 111] Connection refused

During handling of the above exception, another exception occurred:

Traceback (most recent call last):
  File "/home/beast/anaconda3/envs/srikar/lib/python3.6/site-packages/requests/adapters.py", line 449, in send
    timeout=timeout
  File "/home/beast/anaconda3/envs/srikar/lib/python3.6/site-packages/urllib3/connectionpool.py", line 641, in urlopen
    _stacktrace=sys.exc_info()[2])
  File "/home/beast/anaconda3/envs/srikar/lib/python3.6/site-packages/urllib3/util/retry.py", line 399, in increment
    raise MaxRetryError(_pool, url, error or ResponseError(cause))
urllib3.exceptions.MaxRetryError: HTTPConnectionPool(host='localhost', port=8097): Max retries exceeded with url: /events (Caused by NewConnectionError('<urllib3.connection.HTTPConnection object at 0x7efabf391da0>: Failed to establish a new connection: [Errno 111] Connection refused',))

During handling of the above exception, another exception occurred:

Traceback (most recent call last):
  File "/home/beast/anaconda3/envs/srikar/lib/python3.6/site-packages/visdom/__init__.py", line 548, in _send
    data=json.dumps(msg),
  File "/home/beast/anaconda3/envs/srikar/lib/python3.6/site-packages/requests/sessions.py", line 581, in post
    return self.request('POST', url, data=data, json=json, **kwargs)
  File "/home/beast/anaconda3/envs/srikar/lib/python3.6/site-packages/requests/sessions.py", line 533, in request
    resp = self.send(prep, **send_kwargs)
  File "/home/beast/anaconda3/envs/srikar/lib/python3.6/site-packages/requests/sessions.py", line 646, in send
    r = adapter.send(request, **kwargs)
  File "/home/beast/anaconda3/envs/srikar/lib/python3.6/site-packages/requests/adapters.py", line 516, in send
    raise ConnectionError(e, request=request)
requests.exceptions.ConnectionError: HTTPConnectionPool(host='localhost', port=8097): Max retries exceeded with url: /events (Caused by NewConnectionError('<urllib3.connection.HTTPConnection object at 0x7efabf391da0>: Failed to establish a new connection: [Errno 111] Connection refused',))
Traceback (most recent call last):
  File "/home/beast/anaconda3/envs/srikar/lib/python3.6/site-packages/urllib3/connection.py", line 160, in _new_conn
    (self._dns_host, self.port), self.timeout, **extra_kw)
  File "/home/beast/anaconda3/envs/srikar/lib/python3.6/site-packages/urllib3/util/connection.py", line 80, in create_connection
    raise err
  File "/home/beast/anaconda3/envs/srikar/lib/python3.6/site-packages/urllib3/util/connection.py", line 70, in create_connection
    sock.connect(sa)
ConnectionRefusedError: [Errno 111] Connection refused

During handling of the above exception, another exception occurred:

Traceback (most recent call last):
  File "/home/beast/anaconda3/envs/srikar/lib/python3.6/site-packages/urllib3/connectionpool.py", line 603, in urlopen
    chunked=chunked)
  File "/home/beast/anaconda3/envs/srikar/lib/python3.6/site-packages/urllib3/connectionpool.py", line 355, in _make_request
    conn.request(method, url, **httplib_request_kw)
  File "/home/beast/anaconda3/envs/srikar/lib/python3.6/http/client.py", line 1239, in request
    self._send_request(method, url, body, headers, encode_chunked)
  File "/home/beast/anaconda3/envs/srikar/lib/python3.6/http/client.py", line 1285, in _send_request
    self.endheaders(body, encode_chunked=encode_chunked)
  File "/home/beast/anaconda3/envs/srikar/lib/python3.6/http/client.py", line 1234, in endheaders
    self._send_output(message_body, encode_chunked=encode_chunked)
  File "/home/beast/anaconda3/envs/srikar/lib/python3.6/http/client.py", line 1026, in _send_output
    self.send(msg)
  File "/home/beast/anaconda3/envs/srikar/lib/python3.6/http/client.py", line 964, in send
    self.connect()
  File "/home/beast/anaconda3/envs/srikar/lib/python3.6/site-packages/urllib3/connection.py", line 183, in connect
    conn = self._new_conn()
  File "/home/beast/anaconda3/envs/srikar/lib/python3.6/site-packages/urllib3/connection.py", line 169, in _new_conn
    self, "Failed to establish a new connection: %s" % e)
urllib3.exceptions.NewConnectionError: <urllib3.connection.HTTPConnection object at 0x7efabeb2f4e0>: Failed to establish a new connection: [Errno 111] Connection refused

During handling of the above exception, another exception occurred:

Traceback (most recent call last):
  File "/home/beast/anaconda3/envs/srikar/lib/python3.6/site-packages/requests/adapters.py", line 449, in send
    timeout=timeout
  File "/home/beast/anaconda3/envs/srikar/lib/python3.6/site-packages/urllib3/connectionpool.py", line 641, in urlopen
    _stacktrace=sys.exc_info()[2])
  File "/home/beast/anaconda3/envs/srikar/lib/python3.6/site-packages/urllib3/util/retry.py", line 399, in increment
    raise MaxRetryError(_pool, url, error or ResponseError(cause))
urllib3.exceptions.MaxRetryError: HTTPConnectionPool(host='localhost', port=8097): Max retries exceeded with url: /events (Caused by NewConnectionError('<urllib3.connection.HTTPConnection object at 0x7efabeb2f4e0>: Failed to establish a new connection: [Errno 111] Connection refused',))

During handling of the above exception, another exception occurred:

Traceback (most recent call last):
  File "/home/beast/anaconda3/envs/srikar/lib/python3.6/site-packages/visdom/__init__.py", line 548, in _send
    data=json.dumps(msg),
  File "/home/beast/anaconda3/envs/srikar/lib/python3.6/site-packages/requests/sessions.py", line 581, in post
    return self.request('POST', url, data=data, json=json, **kwargs)
  File "/home/beast/anaconda3/envs/srikar/lib/python3.6/site-packages/requests/sessions.py", line 533, in request
    resp = self.send(prep, **send_kwargs)
  File "/home/beast/anaconda3/envs/srikar/lib/python3.6/site-packages/requests/sessions.py", line 646, in send
    r = adapter.send(request, **kwargs)
  File "/home/beast/anaconda3/envs/srikar/lib/python3.6/site-packages/requests/adapters.py", line 516, in send
    raise ConnectionError(e, request=request)
requests.exceptions.ConnectionError: HTTPConnectionPool(host='localhost', port=8097): Max retries exceeded with url: /events (Caused by NewConnectionError('<urllib3.connection.HTTPConnection object at 0x7efabeb2f4e0>: Failed to establish a new connection: [Errno 111] Connection refused',))
Traceback (most recent call last):
  File "/home/beast/anaconda3/envs/srikar/lib/python3.6/site-packages/urllib3/connection.py", line 160, in _new_conn
    (self._dns_host, self.port), self.timeout, **extra_kw)
  File "/home/beast/anaconda3/envs/srikar/lib/python3.6/site-packages/urllib3/util/connection.py", line 80, in create_connection
    raise err
  File "/home/beast/anaconda3/envs/srikar/lib/python3.6/site-packages/urllib3/util/connection.py", line 70, in create_connection
    sock.connect(sa)
ConnectionRefusedError: [Errno 111] Connection refused

During handling of the above exception, another exception occurred:

Traceback (most recent call last):
  File "/home/beast/anaconda3/envs/srikar/lib/python3.6/site-packages/urllib3/connectionpool.py", line 603, in urlopen
    chunked=chunked)
  File "/home/beast/anaconda3/envs/srikar/lib/python3.6/site-packages/urllib3/connectionpool.py", line 355, in _make_request
    conn.request(method, url, **httplib_request_kw)
  File "/home/beast/anaconda3/envs/srikar/lib/python3.6/http/client.py", line 1239, in request
    self._send_request(method, url, body, headers, encode_chunked)
  File "/home/beast/anaconda3/envs/srikar/lib/python3.6/http/client.py", line 1285, in _send_request
    self.endheaders(body, encode_chunked=encode_chunked)
  File "/home/beast/anaconda3/envs/srikar/lib/python3.6/http/client.py", line 1234, in endheaders
    self._send_output(message_body, encode_chunked=encode_chunked)
  File "/home/beast/anaconda3/envs/srikar/lib/python3.6/http/client.py", line 1026, in _send_output
    self.send(msg)
  File "/home/beast/anaconda3/envs/srikar/lib/python3.6/http/client.py", line 964, in send
    self.connect()
  File "/home/beast/anaconda3/envs/srikar/lib/python3.6/site-packages/urllib3/connection.py", line 183, in connect
    conn = self._new_conn()
  File "/home/beast/anaconda3/envs/srikar/lib/python3.6/site-packages/urllib3/connection.py", line 169, in _new_conn
    self, "Failed to establish a new connection: %s" % e)
urllib3.exceptions.NewConnectionError: <urllib3.connection.HTTPConnection object at 0x7efabf3746a0>: Failed to establish a new connection: [Errno 111] Connection refused

During handling of the above exception, another exception occurred:

Traceback (most recent call last):
  File "/home/beast/anaconda3/envs/srikar/lib/python3.6/site-packages/requests/adapters.py", line 449, in send
    timeout=timeout
  File "/home/beast/anaconda3/envs/srikar/lib/python3.6/site-packages/urllib3/connectionpool.py", line 641, in urlopen
    _stacktrace=sys.exc_info()[2])
  File "/home/beast/anaconda3/envs/srikar/lib/python3.6/site-packages/urllib3/util/retry.py", line 399, in increment
    raise MaxRetryError(_pool, url, error or ResponseError(cause))
urllib3.exceptions.MaxRetryError: HTTPConnectionPool(host='localhost', port=8097): Max retries exceeded with url: /events (Caused by NewConnectionError('<urllib3.connection.HTTPConnection object at 0x7efabf3746a0>: Failed to establish a new connection: [Errno 111] Connection refused',))

During handling of the above exception, another exception occurred:

Traceback (most recent call last):
  File "/home/beast/anaconda3/envs/srikar/lib/python3.6/site-packages/visdom/__init__.py", line 548, in _send
    data=json.dumps(msg),
  File "/home/beast/anaconda3/envs/srikar/lib/python3.6/site-packages/requests/sessions.py", line 581, in post
    return self.request('POST', url, data=data, json=json, **kwargs)
  File "/home/beast/anaconda3/envs/srikar/lib/python3.6/site-packages/requests/sessions.py", line 533, in request
    resp = self.send(prep, **send_kwargs)
  File "/home/beast/anaconda3/envs/srikar/lib/python3.6/site-packages/requests/sessions.py", line 646, in send
    r = adapter.send(request, **kwargs)
  File "/home/beast/anaconda3/envs/srikar/lib/python3.6/site-packages/requests/adapters.py", line 516, in send
    raise ConnectionError(e, request=request)
requests.exceptions.ConnectionError: HTTPConnectionPool(host='localhost', port=8097): Max retries exceeded with url: /events (Caused by NewConnectionError('<urllib3.connection.HTTPConnection object at 0x7efabf3746a0>: Failed to establish a new connection: [Errno 111] Connection refused',))
Traceback (most recent call last):
  File "/home/beast/anaconda3/envs/srikar/lib/python3.6/site-packages/urllib3/connection.py", line 160, in _new_conn
    (self._dns_host, self.port), self.timeout, **extra_kw)
  File "/home/beast/anaconda3/envs/srikar/lib/python3.6/site-packages/urllib3/util/connection.py", line 80, in create_connection
    raise err
  File "/home/beast/anaconda3/envs/srikar/lib/python3.6/site-packages/urllib3/util/connection.py", line 70, in create_connection
    sock.connect(sa)
ConnectionRefusedError: [Errno 111] Connection refused

During handling of the above exception, another exception occurred:

Traceback (most recent call last):
  File "/home/beast/anaconda3/envs/srikar/lib/python3.6/site-packages/urllib3/connectionpool.py", line 603, in urlopen
    chunked=chunked)
  File "/home/beast/anaconda3/envs/srikar/lib/python3.6/site-packages/urllib3/connectionpool.py", line 355, in _make_request
    conn.request(method, url, **httplib_request_kw)
  File "/home/beast/anaconda3/envs/srikar/lib/python3.6/http/client.py", line 1239, in request
    self._send_request(method, url, body, headers, encode_chunked)
  File "/home/beast/anaconda3/envs/srikar/lib/python3.6/http/client.py", line 1285, in _send_request
    self.endheaders(body, encode_chunked=encode_chunked)
  File "/home/beast/anaconda3/envs/srikar/lib/python3.6/http/client.py", line 1234, in endheaders
    self._send_output(message_body, encode_chunked=encode_chunked)
  File "/home/beast/anaconda3/envs/srikar/lib/python3.6/http/client.py", line 1026, in _send_output
    self.send(msg)
  File "/home/beast/anaconda3/envs/srikar/lib/python3.6/http/client.py", line 964, in send
    self.connect()
  File "/home/beast/anaconda3/envs/srikar/lib/python3.6/site-packages/urllib3/connection.py", line 183, in connect
    conn = self._new_conn()
  File "/home/beast/anaconda3/envs/srikar/lib/python3.6/site-packages/urllib3/connection.py", line 169, in _new_conn
    self, "Failed to establish a new connection: %s" % e)
urllib3.exceptions.NewConnectionError: <urllib3.connection.HTTPConnection object at 0x7efabead82b0>: Failed to establish a new connection: [Errno 111] Connection refused

During handling of the above exception, another exception occurred:

Traceback (most recent call last):
  File "/home/beast/anaconda3/envs/srikar/lib/python3.6/site-packages/requests/adapters.py", line 449, in send
    timeout=timeout
  File "/home/beast/anaconda3/envs/srikar/lib/python3.6/site-packages/urllib3/connectionpool.py", line 641, in urlopen
    _stacktrace=sys.exc_info()[2])
  File "/home/beast/anaconda3/envs/srikar/lib/python3.6/site-packages/urllib3/util/retry.py", line 399, in increment
    raise MaxRetryError(_pool, url, error or ResponseError(cause))
urllib3.exceptions.MaxRetryError: HTTPConnectionPool(host='localhost', port=8097): Max retries exceeded with url: /events (Caused by NewConnectionError('<urllib3.connection.HTTPConnection object at 0x7efabead82b0>: Failed to establish a new connection: [Errno 111] Connection refused',))

During handling of the above exception, another exception occurred:

Traceback (most recent call last):
  File "/home/beast/anaconda3/envs/srikar/lib/python3.6/site-packages/visdom/__init__.py", line 548, in _send
    data=json.dumps(msg),
  File "/home/beast/anaconda3/envs/srikar/lib/python3.6/site-packages/requests/sessions.py", line 581, in post
    return self.request('POST', url, data=data, json=json, **kwargs)
  File "/home/beast/anaconda3/envs/srikar/lib/python3.6/site-packages/requests/sessions.py", line 533, in request
    resp = self.send(prep, **send_kwargs)
  File "/home/beast/anaconda3/envs/srikar/lib/python3.6/site-packages/requests/sessions.py", line 646, in send
    r = adapter.send(request, **kwargs)
  File "/home/beast/anaconda3/envs/srikar/lib/python3.6/site-packages/requests/adapters.py", line 516, in send
    raise ConnectionError(e, request=request)
requests.exceptions.ConnectionError: HTTPConnectionPool(host='localhost', port=8097): Max retries exceeded with url: /events (Caused by NewConnectionError('<urllib3.connection.HTTPConnection object at 0x7efabead82b0>: Failed to establish a new connection: [Errno 111] Connection refused',))
Traceback (most recent call last):
  File "/home/beast/anaconda3/envs/srikar/lib/python3.6/site-packages/urllib3/connection.py", line 160, in _new_conn
    (self._dns_host, self.port), self.timeout, **extra_kw)
  File "/home/beast/anaconda3/envs/srikar/lib/python3.6/site-packages/urllib3/util/connection.py", line 80, in create_connection
    raise err
  File "/home/beast/anaconda3/envs/srikar/lib/python3.6/site-packages/urllib3/util/connection.py", line 70, in create_connection
    sock.connect(sa)
ConnectionRefusedError: [Errno 111] Connection refused

During handling of the above exception, another exception occurred:

Traceback (most recent call last):
  File "/home/beast/anaconda3/envs/srikar/lib/python3.6/site-packages/urllib3/connectionpool.py", line 603, in urlopen
    chunked=chunked)
  File "/home/beast/anaconda3/envs/srikar/lib/python3.6/site-packages/urllib3/connectionpool.py", line 355, in _make_request
    conn.request(method, url, **httplib_request_kw)
  File "/home/beast/anaconda3/envs/srikar/lib/python3.6/http/client.py", line 1239, in request
    self._send_request(method, url, body, headers, encode_chunked)
  File "/home/beast/anaconda3/envs/srikar/lib/python3.6/http/client.py", line 1285, in _send_request
    self.endheaders(body, encode_chunked=encode_chunked)
  File "/home/beast/anaconda3/envs/srikar/lib/python3.6/http/client.py", line 1234, in endheaders
    self._send_output(message_body, encode_chunked=encode_chunked)
  File "/home/beast/anaconda3/envs/srikar/lib/python3.6/http/client.py", line 1026, in _send_output
    self.send(msg)
  File "/home/beast/anaconda3/envs/srikar/lib/python3.6/http/client.py", line 964, in send
    self.connect()
  File "/home/beast/anaconda3/envs/srikar/lib/python3.6/site-packages/urllib3/connection.py", line 183, in connect
    conn = self._new_conn()
  File "/home/beast/anaconda3/envs/srikar/lib/python3.6/site-packages/urllib3/connection.py", line 169, in _new_conn
    self, "Failed to establish a new connection: %s" % e)
urllib3.exceptions.NewConnectionError: <urllib3.connection.HTTPConnection object at 0x7efabead8470>: Failed to establish a new connection: [Errno 111] Connection refused

During handling of the above exception, another exception occurred:

Traceback (most recent call last):
  File "/home/beast/anaconda3/envs/srikar/lib/python3.6/site-packages/requests/adapters.py", line 449, in send
    timeout=timeout
  File "/home/beast/anaconda3/envs/srikar/lib/python3.6/site-packages/urllib3/connectionpool.py", line 641, in urlopen
    _stacktrace=sys.exc_info()[2])
  File "/home/beast/anaconda3/envs/srikar/lib/python3.6/site-packages/urllib3/util/retry.py", line 399, in increment
    raise MaxRetryError(_pool, url, error or ResponseError(cause))
urllib3.exceptions.MaxRetryError: HTTPConnectionPool(host='localhost', port=8097): Max retries exceeded with url: /events (Caused by NewConnectionError('<urllib3.connection.HTTPConnection object at 0x7efabead8470>: Failed to establish a new connection: [Errno 111] Connection refused',))

During handling of the above exception, another exception occurred:

Traceback (most recent call last):
  File "/home/beast/anaconda3/envs/srikar/lib/python3.6/site-packages/visdom/__init__.py", line 548, in _send
    data=json.dumps(msg),
  File "/home/beast/anaconda3/envs/srikar/lib/python3.6/site-packages/requests/sessions.py", line 581, in post
    return self.request('POST', url, data=data, json=json, **kwargs)
  File "/home/beast/anaconda3/envs/srikar/lib/python3.6/site-packages/requests/sessions.py", line 533, in request
    resp = self.send(prep, **send_kwargs)
  File "/home/beast/anaconda3/envs/srikar/lib/python3.6/site-packages/requests/sessions.py", line 646, in send
    r = adapter.send(request, **kwargs)
  File "/home/beast/anaconda3/envs/srikar/lib/python3.6/site-packages/requests/adapters.py", line 516, in send
    raise ConnectionError(e, request=request)
requests.exceptions.ConnectionError: HTTPConnectionPool(host='localhost', port=8097): Max retries exceeded with url: /events (Caused by NewConnectionError('<urllib3.connection.HTTPConnection object at 0x7efabead8470>: Failed to establish a new connection: [Errno 111] Connection refused',))
Traceback (most recent call last):
  File "/home/beast/anaconda3/envs/srikar/lib/python3.6/site-packages/urllib3/connection.py", line 160, in _new_conn
    (self._dns_host, self.port), self.timeout, **extra_kw)
  File "/home/beast/anaconda3/envs/srikar/lib/python3.6/site-packages/urllib3/util/connection.py", line 80, in create_connection
    raise err
  File "/home/beast/anaconda3/envs/srikar/lib/python3.6/site-packages/urllib3/util/connection.py", line 70, in create_connection
    sock.connect(sa)
ConnectionRefusedError: [Errno 111] Connection refused

During handling of the above exception, another exception occurred:

Traceback (most recent call last):
  File "/home/beast/anaconda3/envs/srikar/lib/python3.6/site-packages/urllib3/connectionpool.py", line 603, in urlopen
    chunked=chunked)
  File "/home/beast/anaconda3/envs/srikar/lib/python3.6/site-packages/urllib3/connectionpool.py", line 355, in _make_request
    conn.request(method, url, **httplib_request_kw)
  File "/home/beast/anaconda3/envs/srikar/lib/python3.6/http/client.py", line 1239, in request
    self._send_request(method, url, body, headers, encode_chunked)
  File "/home/beast/anaconda3/envs/srikar/lib/python3.6/http/client.py", line 1285, in _send_request
    self.endheaders(body, encode_chunked=encode_chunked)
  File "/home/beast/anaconda3/envs/srikar/lib/python3.6/http/client.py", line 1234, in endheaders
    self._send_output(message_body, encode_chunked=encode_chunked)
  File "/home/beast/anaconda3/envs/srikar/lib/python3.6/http/client.py", line 1026, in _send_output
    self.send(msg)
  File "/home/beast/anaconda3/envs/srikar/lib/python3.6/http/client.py", line 964, in send
    self.connect()
  File "/home/beast/anaconda3/envs/srikar/lib/python3.6/site-packages/urllib3/connection.py", line 183, in connect
    conn = self._new_conn()
  File "/home/beast/anaconda3/envs/srikar/lib/python3.6/site-packages/urllib3/connection.py", line 169, in _new_conn
    self, "Failed to establish a new connection: %s" % e)
urllib3.exceptions.NewConnectionError: <urllib3.connection.HTTPConnection object at 0x7efabf374a90>: Failed to establish a new connection: [Errno 111] Connection refused

During handling of the above exception, another exception occurred:

Traceback (most recent call last):
  File "/home/beast/anaconda3/envs/srikar/lib/python3.6/site-packages/requests/adapters.py", line 449, in send
    timeout=timeout
  File "/home/beast/anaconda3/envs/srikar/lib/python3.6/site-packages/urllib3/connectionpool.py", line 641, in urlopen
    _stacktrace=sys.exc_info()[2])
  File "/home/beast/anaconda3/envs/srikar/lib/python3.6/site-packages/urllib3/util/retry.py", line 399, in increment
    raise MaxRetryError(_pool, url, error or ResponseError(cause))
urllib3.exceptions.MaxRetryError: HTTPConnectionPool(host='localhost', port=8097): Max retries exceeded with url: /events (Caused by NewConnectionError('<urllib3.connection.HTTPConnection object at 0x7efabf374a90>: Failed to establish a new connection: [Errno 111] Connection refused',))

During handling of the above exception, another exception occurred:

Traceback (most recent call last):
  File "/home/beast/anaconda3/envs/srikar/lib/python3.6/site-packages/visdom/__init__.py", line 548, in _send
    data=json.dumps(msg),
  File "/home/beast/anaconda3/envs/srikar/lib/python3.6/site-packages/requests/sessions.py", line 581, in post
    return self.request('POST', url, data=data, json=json, **kwargs)
  File "/home/beast/anaconda3/envs/srikar/lib/python3.6/site-packages/requests/sessions.py", line 533, in request
    resp = self.send(prep, **send_kwargs)
  File "/home/beast/anaconda3/envs/srikar/lib/python3.6/site-packages/requests/sessions.py", line 646, in send
    r = adapter.send(request, **kwargs)
  File "/home/beast/anaconda3/envs/srikar/lib/python3.6/site-packages/requests/adapters.py", line 516, in send
    raise ConnectionError(e, request=request)
requests.exceptions.ConnectionError: HTTPConnectionPool(host='localhost', port=8097): Max retries exceeded with url: /events (Caused by NewConnectionError('<urllib3.connection.HTTPConnection object at 0x7efabf374a90>: Failed to establish a new connection: [Errno 111] Connection refused',))
Traceback (most recent call last):
  File "/home/beast/anaconda3/envs/srikar/lib/python3.6/site-packages/urllib3/connection.py", line 160, in _new_conn
    (self._dns_host, self.port), self.timeout, **extra_kw)
  File "/home/beast/anaconda3/envs/srikar/lib/python3.6/site-packages/urllib3/util/connection.py", line 80, in create_connection
    raise err
  File "/home/beast/anaconda3/envs/srikar/lib/python3.6/site-packages/urllib3/util/connection.py", line 70, in create_connection
    sock.connect(sa)
ConnectionRefusedError: [Errno 111] Connection refused

During handling of the above exception, another exception occurred:

Traceback (most recent call last):
  File "/home/beast/anaconda3/envs/srikar/lib/python3.6/site-packages/urllib3/connectionpool.py", line 603, in urlopen
    chunked=chunked)
  File "/home/beast/anaconda3/envs/srikar/lib/python3.6/site-packages/urllib3/connectionpool.py", line 355, in _make_request
    conn.request(method, url, **httplib_request_kw)
  File "/home/beast/anaconda3/envs/srikar/lib/python3.6/http/client.py", line 1239, in request
    self._send_request(method, url, body, headers, encode_chunked)
  File "/home/beast/anaconda3/envs/srikar/lib/python3.6/http/client.py", line 1285, in _send_request
    self.endheaders(body, encode_chunked=encode_chunked)
  File "/home/beast/anaconda3/envs/srikar/lib/python3.6/http/client.py", line 1234, in endheaders
    self._send_output(message_body, encode_chunked=encode_chunked)
  File "/home/beast/anaconda3/envs/srikar/lib/python3.6/http/client.py", line 1026, in _send_output
    self.send(msg)
  File "/home/beast/anaconda3/envs/srikar/lib/python3.6/http/client.py", line 964, in send
    self.connect()
  File "/home/beast/anaconda3/envs/srikar/lib/python3.6/site-packages/urllib3/connection.py", line 183, in connect
    conn = self._new_conn()
  File "/home/beast/anaconda3/envs/srikar/lib/python3.6/site-packages/urllib3/connection.py", line 169, in _new_conn
    self, "Failed to establish a new connection: %s" % e)
urllib3.exceptions.NewConnectionError: <urllib3.connection.HTTPConnection object at 0x7efabeb2f080>: Failed to establish a new connection: [Errno 111] Connection refused

During handling of the above exception, another exception occurred:

Traceback (most recent call last):
  File "/home/beast/anaconda3/envs/srikar/lib/python3.6/site-packages/requests/adapters.py", line 449, in send
    timeout=timeout
  File "/home/beast/anaconda3/envs/srikar/lib/python3.6/site-packages/urllib3/connectionpool.py", line 641, in urlopen
    _stacktrace=sys.exc_info()[2])
  File "/home/beast/anaconda3/envs/srikar/lib/python3.6/site-packages/urllib3/util/retry.py", line 399, in increment
    raise MaxRetryError(_pool, url, error or ResponseError(cause))
urllib3.exceptions.MaxRetryError: HTTPConnectionPool(host='localhost', port=8097): Max retries exceeded with url: /events (Caused by NewConnectionError('<urllib3.connection.HTTPConnection object at 0x7efabeb2f080>: Failed to establish a new connection: [Errno 111] Connection refused',))

During handling of the above exception, another exception occurred:

Traceback (most recent call last):
  File "/home/beast/anaconda3/envs/srikar/lib/python3.6/site-packages/visdom/__init__.py", line 548, in _send
    data=json.dumps(msg),
  File "/home/beast/anaconda3/envs/srikar/lib/python3.6/site-packages/requests/sessions.py", line 581, in post
    return self.request('POST', url, data=data, json=json, **kwargs)
  File "/home/beast/anaconda3/envs/srikar/lib/python3.6/site-packages/requests/sessions.py", line 533, in request
    resp = self.send(prep, **send_kwargs)
  File "/home/beast/anaconda3/envs/srikar/lib/python3.6/site-packages/requests/sessions.py", line 646, in send
    r = adapter.send(request, **kwargs)
  File "/home/beast/anaconda3/envs/srikar/lib/python3.6/site-packages/requests/adapters.py", line 516, in send
    raise ConnectionError(e, request=request)
requests.exceptions.ConnectionError: HTTPConnectionPool(host='localhost', port=8097): Max retries exceeded with url: /events (Caused by NewConnectionError('<urllib3.connection.HTTPConnection object at 0x7efabeb2f080>: Failed to establish a new connection: [Errno 111] Connection refused',))
Traceback (most recent call last):
  File "/home/beast/anaconda3/envs/srikar/lib/python3.6/site-packages/urllib3/connection.py", line 160, in _new_conn
    (self._dns_host, self.port), self.timeout, **extra_kw)
  File "/home/beast/anaconda3/envs/srikar/lib/python3.6/site-packages/urllib3/util/connection.py", line 80, in create_connection
    raise err
  File "/home/beast/anaconda3/envs/srikar/lib/python3.6/site-packages/urllib3/util/connection.py", line 70, in create_connection
    sock.connect(sa)
ConnectionRefusedError: [Errno 111] Connection refused

During handling of the above exception, another exception occurred:

Traceback (most recent call last):
  File "/home/beast/anaconda3/envs/srikar/lib/python3.6/site-packages/urllib3/connectionpool.py", line 603, in urlopen
    chunked=chunked)
  File "/home/beast/anaconda3/envs/srikar/lib/python3.6/site-packages/urllib3/connectionpool.py", line 355, in _make_request
    conn.request(method, url, **httplib_request_kw)
  File "/home/beast/anaconda3/envs/srikar/lib/python3.6/http/client.py", line 1239, in request
    self._send_request(method, url, body, headers, encode_chunked)
  File "/home/beast/anaconda3/envs/srikar/lib/python3.6/http/client.py", line 1285, in _send_request
    self.endheaders(body, encode_chunked=encode_chunked)
  File "/home/beast/anaconda3/envs/srikar/lib/python3.6/http/client.py", line 1234, in endheaders
    self._send_output(message_body, encode_chunked=encode_chunked)
  File "/home/beast/anaconda3/envs/srikar/lib/python3.6/http/client.py", line 1026, in _send_output
    self.send(msg)
  File "/home/beast/anaconda3/envs/srikar/lib/python3.6/http/client.py", line 964, in send
    self.connect()
  File "/home/beast/anaconda3/envs/srikar/lib/python3.6/site-packages/urllib3/connection.py", line 183, in connect
    conn = self._new_conn()
  File "/home/beast/anaconda3/envs/srikar/lib/python3.6/site-packages/urllib3/connection.py", line 169, in _new_conn
    self, "Failed to establish a new connection: %s" % e)
urllib3.exceptions.NewConnectionError: <urllib3.connection.HTTPConnection object at 0x7efabf3913c8>: Failed to establish a new connection: [Errno 111] Connection refused

During handling of the above exception, another exception occurred:

Traceback (most recent call last):
  File "/home/beast/anaconda3/envs/srikar/lib/python3.6/site-packages/requests/adapters.py", line 449, in send
    timeout=timeout
  File "/home/beast/anaconda3/envs/srikar/lib/python3.6/site-packages/urllib3/connectionpool.py", line 641, in urlopen
    _stacktrace=sys.exc_info()[2])
  File "/home/beast/anaconda3/envs/srikar/lib/python3.6/site-packages/urllib3/util/retry.py", line 399, in increment
    raise MaxRetryError(_pool, url, error or ResponseError(cause))
urllib3.exceptions.MaxRetryError: HTTPConnectionPool(host='localhost', port=8097): Max retries exceeded with url: /events (Caused by NewConnectionError('<urllib3.connection.HTTPConnection object at 0x7efabf3913c8>: Failed to establish a new connection: [Errno 111] Connection refused',))

During handling of the above exception, another exception occurred:

Traceback (most recent call last):
  File "/home/beast/anaconda3/envs/srikar/lib/python3.6/site-packages/visdom/__init__.py", line 548, in _send
    data=json.dumps(msg),
  File "/home/beast/anaconda3/envs/srikar/lib/python3.6/site-packages/requests/sessions.py", line 581, in post
    return self.request('POST', url, data=data, json=json, **kwargs)
  File "/home/beast/anaconda3/envs/srikar/lib/python3.6/site-packages/requests/sessions.py", line 533, in request
    resp = self.send(prep, **send_kwargs)
  File "/home/beast/anaconda3/envs/srikar/lib/python3.6/site-packages/requests/sessions.py", line 646, in send
    r = adapter.send(request, **kwargs)
  File "/home/beast/anaconda3/envs/srikar/lib/python3.6/site-packages/requests/adapters.py", line 516, in send
    raise ConnectionError(e, request=request)
requests.exceptions.ConnectionError: HTTPConnectionPool(host='localhost', port=8097): Max retries exceeded with url: /events (Caused by NewConnectionError('<urllib3.connection.HTTPConnection object at 0x7efabf3913c8>: Failed to establish a new connection: [Errno 111] Connection refused',))
Traceback (most recent call last):
  File "/home/beast/anaconda3/envs/srikar/lib/python3.6/site-packages/urllib3/connection.py", line 160, in _new_conn
    (self._dns_host, self.port), self.timeout, **extra_kw)
  File "/home/beast/anaconda3/envs/srikar/lib/python3.6/site-packages/urllib3/util/connection.py", line 80, in create_connection
    raise err
  File "/home/beast/anaconda3/envs/srikar/lib/python3.6/site-packages/urllib3/util/connection.py", line 70, in create_connection
    sock.connect(sa)
ConnectionRefusedError: [Errno 111] Connection refused

During handling of the above exception, another exception occurred:

Traceback (most recent call last):
  File "/home/beast/anaconda3/envs/srikar/lib/python3.6/site-packages/urllib3/connectionpool.py", line 603, in urlopen
    chunked=chunked)
  File "/home/beast/anaconda3/envs/srikar/lib/python3.6/site-packages/urllib3/connectionpool.py", line 355, in _make_request
    conn.request(method, url, **httplib_request_kw)
  File "/home/beast/anaconda3/envs/srikar/lib/python3.6/http/client.py", line 1239, in request
    self._send_request(method, url, body, headers, encode_chunked)
  File "/home/beast/anaconda3/envs/srikar/lib/python3.6/http/client.py", line 1285, in _send_request
    self.endheaders(body, encode_chunked=encode_chunked)
  File "/home/beast/anaconda3/envs/srikar/lib/python3.6/http/client.py", line 1234, in endheaders
    self._send_output(message_body, encode_chunked=encode_chunked)
  File "/home/beast/anaconda3/envs/srikar/lib/python3.6/http/client.py", line 1026, in _send_output
    self.send(msg)
  File "/home/beast/anaconda3/envs/srikar/lib/python3.6/http/client.py", line 964, in send
    self.connect()
  File "/home/beast/anaconda3/envs/srikar/lib/python3.6/site-packages/urllib3/connection.py", line 183, in connect
    conn = self._new_conn()
  File "/home/beast/anaconda3/envs/srikar/lib/python3.6/site-packages/urllib3/connection.py", line 169, in _new_conn
    self, "Failed to establish a new connection: %s" % e)
urllib3.exceptions.NewConnectionError: <urllib3.connection.HTTPConnection object at 0x7efabead85f8>: Failed to establish a new connection: [Errno 111] Connection refused

During handling of the above exception, another exception occurred:

Traceback (most recent call last):
  File "/home/beast/anaconda3/envs/srikar/lib/python3.6/site-packages/requests/adapters.py", line 449, in send
    timeout=timeout
  File "/home/beast/anaconda3/envs/srikar/lib/python3.6/site-packages/urllib3/connectionpool.py", line 641, in urlopen
    _stacktrace=sys.exc_info()[2])
  File "/home/beast/anaconda3/envs/srikar/lib/python3.6/site-packages/urllib3/util/retry.py", line 399, in increment
    raise MaxRetryError(_pool, url, error or ResponseError(cause))
urllib3.exceptions.MaxRetryError: HTTPConnectionPool(host='localhost', port=8097): Max retries exceeded with url: /events (Caused by NewConnectionError('<urllib3.connection.HTTPConnection object at 0x7efabead85f8>: Failed to establish a new connection: [Errno 111] Connection refused',))

During handling of the above exception, another exception occurred:

Traceback (most recent call last):
  File "/home/beast/anaconda3/envs/srikar/lib/python3.6/site-packages/visdom/__init__.py", line 548, in _send
    data=json.dumps(msg),
  File "/home/beast/anaconda3/envs/srikar/lib/python3.6/site-packages/requests/sessions.py", line 581, in post
    return self.request('POST', url, data=data, json=json, **kwargs)
  File "/home/beast/anaconda3/envs/srikar/lib/python3.6/site-packages/requests/sessions.py", line 533, in request
    resp = self.send(prep, **send_kwargs)
  File "/home/beast/anaconda3/envs/srikar/lib/python3.6/site-packages/requests/sessions.py", line 646, in send
    r = adapter.send(request, **kwargs)
  File "/home/beast/anaconda3/envs/srikar/lib/python3.6/site-packages/requests/adapters.py", line 516, in send
    raise ConnectionError(e, request=request)
requests.exceptions.ConnectionError: HTTPConnectionPool(host='localhost', port=8097): Max retries exceeded with url: /events (Caused by NewConnectionError('<urllib3.connection.HTTPConnection object at 0x7efabead85f8>: Failed to establish a new connection: [Errno 111] Connection refused',))
Traceback (most recent call last):
  File "/home/beast/anaconda3/envs/srikar/lib/python3.6/site-packages/urllib3/connection.py", line 160, in _new_conn
    (self._dns_host, self.port), self.timeout, **extra_kw)
  File "/home/beast/anaconda3/envs/srikar/lib/python3.6/site-packages/urllib3/util/connection.py", line 80, in create_connection
    raise err
  File "/home/beast/anaconda3/envs/srikar/lib/python3.6/site-packages/urllib3/util/connection.py", line 70, in create_connection
    sock.connect(sa)
ConnectionRefusedError: [Errno 111] Connection refused

During handling of the above exception, another exception occurred:

Traceback (most recent call last):
  File "/home/beast/anaconda3/envs/srikar/lib/python3.6/site-packages/urllib3/connectionpool.py", line 603, in urlopen
    chunked=chunked)
  File "/home/beast/anaconda3/envs/srikar/lib/python3.6/site-packages/urllib3/connectionpool.py", line 355, in _make_request
    conn.request(method, url, **httplib_request_kw)
  File "/home/beast/anaconda3/envs/srikar/lib/python3.6/http/client.py", line 1239, in request
    self._send_request(method, url, body, headers, encode_chunked)
  File "/home/beast/anaconda3/envs/srikar/lib/python3.6/http/client.py", line 1285, in _send_request
    self.endheaders(body, encode_chunked=encode_chunked)
  File "/home/beast/anaconda3/envs/srikar/lib/python3.6/http/client.py", line 1234, in endheaders
    self._send_output(message_body, encode_chunked=encode_chunked)
  File "/home/beast/anaconda3/envs/srikar/lib/python3.6/http/client.py", line 1026, in _send_output
    self.send(msg)
  File "/home/beast/anaconda3/envs/srikar/lib/python3.6/http/client.py", line 964, in send
    self.connect()
  File "/home/beast/anaconda3/envs/srikar/lib/python3.6/site-packages/urllib3/connection.py", line 183, in connect
    conn = self._new_conn()
  File "/home/beast/anaconda3/envs/srikar/lib/python3.6/site-packages/urllib3/connection.py", line 169, in _new_conn
    self, "Failed to establish a new connection: %s" % e)
urllib3.exceptions.NewConnectionError: <urllib3.connection.HTTPConnection object at 0x7efabead84e0>: Failed to establish a new connection: [Errno 111] Connection refused

During handling of the above exception, another exception occurred:

Traceback (most recent call last):
  File "/home/beast/anaconda3/envs/srikar/lib/python3.6/site-packages/requests/adapters.py", line 449, in send
    timeout=timeout
  File "/home/beast/anaconda3/envs/srikar/lib/python3.6/site-packages/urllib3/connectionpool.py", line 641, in urlopen
    _stacktrace=sys.exc_info()[2])
  File "/home/beast/anaconda3/envs/srikar/lib/python3.6/site-packages/urllib3/util/retry.py", line 399, in increment
    raise MaxRetryError(_pool, url, error or ResponseError(cause))
urllib3.exceptions.MaxRetryError: HTTPConnectionPool(host='localhost', port=8097): Max retries exceeded with url: /events (Caused by NewConnectionError('<urllib3.connection.HTTPConnection object at 0x7efabead84e0>: Failed to establish a new connection: [Errno 111] Connection refused',))

During handling of the above exception, another exception occurred:

Traceback (most recent call last):
  File "/home/beast/anaconda3/envs/srikar/lib/python3.6/site-packages/visdom/__init__.py", line 548, in _send
    data=json.dumps(msg),
  File "/home/beast/anaconda3/envs/srikar/lib/python3.6/site-packages/requests/sessions.py", line 581, in post
    return self.request('POST', url, data=data, json=json, **kwargs)
  File "/home/beast/anaconda3/envs/srikar/lib/python3.6/site-packages/requests/sessions.py", line 533, in request
    resp = self.send(prep, **send_kwargs)
  File "/home/beast/anaconda3/envs/srikar/lib/python3.6/site-packages/requests/sessions.py", line 646, in send
    r = adapter.send(request, **kwargs)
  File "/home/beast/anaconda3/envs/srikar/lib/python3.6/site-packages/requests/adapters.py", line 516, in send
    raise ConnectionError(e, request=request)
requests.exceptions.ConnectionError: HTTPConnectionPool(host='localhost', port=8097): Max retries exceeded with url: /events (Caused by NewConnectionError('<urllib3.connection.HTTPConnection object at 0x7efabead84e0>: Failed to establish a new connection: [Errno 111] Connection refused',))
Traceback (most recent call last):
  File "/home/beast/anaconda3/envs/srikar/lib/python3.6/site-packages/urllib3/connection.py", line 160, in _new_conn
    (self._dns_host, self.port), self.timeout, **extra_kw)
  File "/home/beast/anaconda3/envs/srikar/lib/python3.6/site-packages/urllib3/util/connection.py", line 80, in create_connection
    raise err
  File "/home/beast/anaconda3/envs/srikar/lib/python3.6/site-packages/urllib3/util/connection.py", line 70, in create_connection
    sock.connect(sa)
ConnectionRefusedError: [Errno 111] Connection refused

During handling of the above exception, another exception occurred:

Traceback (most recent call last):
  File "/home/beast/anaconda3/envs/srikar/lib/python3.6/site-packages/urllib3/connectionpool.py", line 603, in urlopen
    chunked=chunked)
  File "/home/beast/anaconda3/envs/srikar/lib/python3.6/site-packages/urllib3/connectionpool.py", line 355, in _make_request
    conn.request(method, url, **httplib_request_kw)
  File "/home/beast/anaconda3/envs/srikar/lib/python3.6/http/client.py", line 1239, in request
    self._send_request(method, url, body, headers, encode_chunked)
  File "/home/beast/anaconda3/envs/srikar/lib/python3.6/http/client.py", line 1285, in _send_request
    self.endheaders(body, encode_chunked=encode_chunked)
  File "/home/beast/anaconda3/envs/srikar/lib/python3.6/http/client.py", line 1234, in endheaders
    self._send_output(message_body, encode_chunked=encode_chunked)
  File "/home/beast/anaconda3/envs/srikar/lib/python3.6/http/client.py", line 1026, in _send_output
    self.send(msg)
  File "/home/beast/anaconda3/envs/srikar/lib/python3.6/http/client.py", line 964, in send
    self.connect()
  File "/home/beast/anaconda3/envs/srikar/lib/python3.6/site-packages/urllib3/connection.py", line 183, in connect
    conn = self._new_conn()
  File "/home/beast/anaconda3/envs/srikar/lib/python3.6/site-packages/urllib3/connection.py", line 169, in _new_conn
    self, "Failed to establish a new connection: %s" % e)
urllib3.exceptions.NewConnectionError: <urllib3.connection.HTTPConnection object at 0x7efabead89e8>: Failed to establish a new connection: [Errno 111] Connection refused

During handling of the above exception, another exception occurred:

Traceback (most recent call last):
  File "/home/beast/anaconda3/envs/srikar/lib/python3.6/site-packages/requests/adapters.py", line 449, in send
    timeout=timeout
  File "/home/beast/anaconda3/envs/srikar/lib/python3.6/site-packages/urllib3/connectionpool.py", line 641, in urlopen
    _stacktrace=sys.exc_info()[2])
  File "/home/beast/anaconda3/envs/srikar/lib/python3.6/site-packages/urllib3/util/retry.py", line 399, in increment
    raise MaxRetryError(_pool, url, error or ResponseError(cause))
urllib3.exceptions.MaxRetryError: HTTPConnectionPool(host='localhost', port=8097): Max retries exceeded with url: /events (Caused by NewConnectionError('<urllib3.connection.HTTPConnection object at 0x7efabead89e8>: Failed to establish a new connection: [Errno 111] Connection refused',))

During handling of the above exception, another exception occurred:

Traceback (most recent call last):
  File "/home/beast/anaconda3/envs/srikar/lib/python3.6/site-packages/visdom/__init__.py", line 548, in _send
    data=json.dumps(msg),
  File "/home/beast/anaconda3/envs/srikar/lib/python3.6/site-packages/requests/sessions.py", line 581, in post
    return self.request('POST', url, data=data, json=json, **kwargs)
  File "/home/beast/anaconda3/envs/srikar/lib/python3.6/site-packages/requests/sessions.py", line 533, in request
    resp = self.send(prep, **send_kwargs)
  File "/home/beast/anaconda3/envs/srikar/lib/python3.6/site-packages/requests/sessions.py", line 646, in send
    r = adapter.send(request, **kwargs)
  File "/home/beast/anaconda3/envs/srikar/lib/python3.6/site-packages/requests/adapters.py", line 516, in send
    raise ConnectionError(e, request=request)
requests.exceptions.ConnectionError: HTTPConnectionPool(host='localhost', port=8097): Max retries exceeded with url: /events (Caused by NewConnectionError('<urllib3.connection.HTTPConnection object at 0x7efabead89e8>: Failed to establish a new connection: [Errno 111] Connection refused',))
Traceback (most recent call last):
  File "/home/beast/anaconda3/envs/srikar/lib/python3.6/site-packages/urllib3/connection.py", line 160, in _new_conn
    (self._dns_host, self.port), self.timeout, **extra_kw)
  File "/home/beast/anaconda3/envs/srikar/lib/python3.6/site-packages/urllib3/util/connection.py", line 80, in create_connection
    raise err
  File "/home/beast/anaconda3/envs/srikar/lib/python3.6/site-packages/urllib3/util/connection.py", line 70, in create_connection
    sock.connect(sa)
ConnectionRefusedError: [Errno 111] Connection refused

During handling of the above exception, another exception occurred:

Traceback (most recent call last):
  File "/home/beast/anaconda3/envs/srikar/lib/python3.6/site-packages/urllib3/connectionpool.py", line 603, in urlopen
    chunked=chunked)
  File "/home/beast/anaconda3/envs/srikar/lib/python3.6/site-packages/urllib3/connectionpool.py", line 355, in _make_request
    conn.request(method, url, **httplib_request_kw)
  File "/home/beast/anaconda3/envs/srikar/lib/python3.6/http/client.py", line 1239, in request
    self._send_request(method, url, body, headers, encode_chunked)
  File "/home/beast/anaconda3/envs/srikar/lib/python3.6/http/client.py", line 1285, in _send_request
    self.endheaders(body, encode_chunked=encode_chunked)
  File "/home/beast/anaconda3/envs/srikar/lib/python3.6/http/client.py", line 1234, in endheaders
    self._send_output(message_body, encode_chunked=encode_chunked)
  File "/home/beast/anaconda3/envs/srikar/lib/python3.6/http/client.py", line 1026, in _send_output
    self.send(msg)
  File "/home/beast/anaconda3/envs/srikar/lib/python3.6/http/client.py", line 964, in send
    self.connect()
  File "/home/beast/anaconda3/envs/srikar/lib/python3.6/site-packages/urllib3/connection.py", line 183, in connect
    conn = self._new_conn()
  File "/home/beast/anaconda3/envs/srikar/lib/python3.6/site-packages/urllib3/connection.py", line 169, in _new_conn
    self, "Failed to establish a new connection: %s" % e)
urllib3.exceptions.NewConnectionError: <urllib3.connection.HTTPConnection object at 0x7efabead8ac8>: Failed to establish a new connection: [Errno 111] Connection refused

During handling of the above exception, another exception occurred:

Traceback (most recent call last):
  File "/home/beast/anaconda3/envs/srikar/lib/python3.6/site-packages/requests/adapters.py", line 449, in send
    timeout=timeout
  File "/home/beast/anaconda3/envs/srikar/lib/python3.6/site-packages/urllib3/connectionpool.py", line 641, in urlopen
    _stacktrace=sys.exc_info()[2])
  File "/home/beast/anaconda3/envs/srikar/lib/python3.6/site-packages/urllib3/util/retry.py", line 399, in increment
    raise MaxRetryError(_pool, url, error or ResponseError(cause))
urllib3.exceptions.MaxRetryError: HTTPConnectionPool(host='localhost', port=8097): Max retries exceeded with url: /events (Caused by NewConnectionError('<urllib3.connection.HTTPConnection object at 0x7efabead8ac8>: Failed to establish a new connection: [Errno 111] Connection refused',))

During handling of the above exception, another exception occurred:

Traceback (most recent call last):
  File "/home/beast/anaconda3/envs/srikar/lib/python3.6/site-packages/visdom/__init__.py", line 548, in _send
    data=json.dumps(msg),
  File "/home/beast/anaconda3/envs/srikar/lib/python3.6/site-packages/requests/sessions.py", line 581, in post
    return self.request('POST', url, data=data, json=json, **kwargs)
  File "/home/beast/anaconda3/envs/srikar/lib/python3.6/site-packages/requests/sessions.py", line 533, in request
    resp = self.send(prep, **send_kwargs)
  File "/home/beast/anaconda3/envs/srikar/lib/python3.6/site-packages/requests/sessions.py", line 646, in send
    r = adapter.send(request, **kwargs)
  File "/home/beast/anaconda3/envs/srikar/lib/python3.6/site-packages/requests/adapters.py", line 516, in send
    raise ConnectionError(e, request=request)
requests.exceptions.ConnectionError: HTTPConnectionPool(host='localhost', port=8097): Max retries exceeded with url: /events (Caused by NewConnectionError('<urllib3.connection.HTTPConnection object at 0x7efabead8ac8>: Failed to establish a new connection: [Errno 111] Connection refused',))
Traceback (most recent call last):
  File "/home/beast/anaconda3/envs/srikar/lib/python3.6/site-packages/ray/worker.py", line 1034, in _get_next_task_from_raylet
    task = self.raylet_client.get_task()
  File "python/ray/_raylet.pyx", line 245, in ray._raylet.RayletClient.get_task
  File "python/ray/_raylet.pyx", line 60, in ray._raylet.check_status
Exception: [RayletClient] Raylet connection closed.

During handling of the above exception, another exception occurred:

Traceback (most recent call last):
  File "/home/beast/anaconda3/envs/srikar/lib/python3.6/site-packages/ray/workers/default_worker.py", line 98, in <module>
    ray.worker.global_worker.main_loop()
  File "/home/beast/anaconda3/envs/srikar/lib/python3.6/site-packages/ray/worker.py", line 1051, in main_loop
    task = self._get_next_task_from_raylet()
  File "/home/beast/anaconda3/envs/srikar/lib/python3.6/site-packages/ray/worker.py", line 1034, in _get_next_task_from_raylet
    task = self.raylet_client.get_task()
KeyboardInterrupt
