Ray worker pid: 27770
Traceback (most recent call last):
  File "/home/beast/anaconda3/envs/srikar/lib/python3.6/site-packages/ray/worker.py", line 1034, in _get_next_task_from_raylet
    task = self.raylet_client.get_task()
  File "python/ray/_raylet.pyx", line 245, in ray._raylet.RayletClient.get_task
  File "python/ray/_raylet.pyx", line 60, in ray._raylet.check_status
Exception: [RayletClient] Raylet connection closed.

During handling of the above exception, another exception occurred:

Traceback (most recent call last):
  File "/home/beast/anaconda3/envs/srikar/lib/python3.6/site-packages/ray/workers/default_worker.py", line 98, in <module>
    ray.worker.global_worker.main_loop()
  File "/home/beast/anaconda3/envs/srikar/lib/python3.6/site-packages/ray/worker.py", line 1051, in main_loop
    task = self._get_next_task_from_raylet()
  File "/home/beast/anaconda3/envs/srikar/lib/python3.6/site-packages/ray/worker.py", line 1034, in _get_next_task_from_raylet
    task = self.raylet_client.get_task()
KeyboardInterrupt
Exception in thread ray_import_thread:
Traceback (most recent call last):
  File "/home/beast/anaconda3/envs/srikar/lib/python3.6/site-packages/redis/connection.py", line 185, in _read_from_socket
    raise socket.error(SERVER_CLOSED_CONNECTION_ERROR)
OSError: Connection closed by server.

During handling of the above exception, another exception occurred:

Traceback (most recent call last):
  File "/home/beast/anaconda3/envs/srikar/lib/python3.6/threading.py", line 916, in _bootstrap_inner
    self.run()
  File "/home/beast/anaconda3/envs/srikar/lib/python3.6/threading.py", line 864, in run
    self._target(*self._args, **self._kwargs)
  File "/home/beast/anaconda3/envs/srikar/lib/python3.6/site-packages/ray/import_thread.py", line 69, in _run
    msg = import_pubsub_client.get_message()
  File "/home/beast/anaconda3/envs/srikar/lib/python3.6/site-packages/redis/client.py", line 3135, in get_message
    response = self.parse_response(block=False, timeout=timeout)
  File "/home/beast/anaconda3/envs/srikar/lib/python3.6/site-packages/redis/client.py", line 3036, in parse_response
    return self._execute(connection, connection.read_response)
  File "/home/beast/anaconda3/envs/srikar/lib/python3.6/site-packages/redis/client.py", line 3013, in _execute
    return command(*args)
  File "/home/beast/anaconda3/envs/srikar/lib/python3.6/site-packages/redis/connection.py", line 637, in read_response
    response = self._parser.read_response()
  File "/home/beast/anaconda3/envs/srikar/lib/python3.6/site-packages/redis/connection.py", line 290, in read_response
    response = self._buffer.readline()
  File "/home/beast/anaconda3/envs/srikar/lib/python3.6/site-packages/redis/connection.py", line 224, in readline
    self._read_from_socket()
  File "/home/beast/anaconda3/envs/srikar/lib/python3.6/site-packages/redis/connection.py", line 199, in _read_from_socket
    (e.args,))
redis.exceptions.ConnectionError: Error while reading from socket: ('Connection closed by server.',)

