Ray worker pid: 47197
/home/beast/anaconda3/envs/srikar/lib/python3.6/site-packages/numpy/core/fromnumeric.py:3118: RuntimeWarning: Mean of empty slice.
  out=out, **kwargs)
/home/beast/anaconda3/envs/srikar/lib/python3.6/site-packages/numpy/core/_methods.py:85: RuntimeWarning: invalid value encountered in double_scalars
  ret = ret.dtype.type(ret / rcount)
Traceback (most recent call last):
  File "/home/beast/anaconda3/envs/srikar/lib/python3.6/site-packages/ray/worker.py", line 2322, in wait
    worker.current_task_id,
  File "python/ray/_raylet.pyx", line 269, in ray._raylet.RayletClient.wait
  File "python/ray/_raylet.pyx", line 60, in ray._raylet.check_status
Exception: [RayletClient] Raylet connection closed.

During handling of the above exception, another exception occurred:

Traceback (most recent call last):
  File "/home/beast/anaconda3/envs/srikar/lib/python3.6/site-packages/ray/workers/default_worker.py", line 98, in <module>
    ray.worker.global_worker.main_loop()
  File "/home/beast/anaconda3/envs/srikar/lib/python3.6/site-packages/ray/worker.py", line 1052, in main_loop
    self._wait_for_and_process_task(task)
  File "/home/beast/anaconda3/envs/srikar/lib/python3.6/site-packages/ray/worker.py", line 1003, in _wait_for_and_process_task
    self._process_task(task, execution_info)
  File "/home/beast/anaconda3/envs/srikar/lib/python3.6/site-packages/ray/worker.py", line 908, in _process_task
    self.actors[key], *arguments)
  File "/home/beast/anaconda3/envs/srikar/lib/python3.6/site-packages/ray/function_manager.py", line 792, in actor_method_executor
    method_returns = method(actor, *args)
  File "/home/beast/srikar/apex/rl/algos/td3.py", line 220, in collect_experience
    [self.learner_id.increment_episode_count.remote()], num_returns=1)
  File "/home/beast/anaconda3/envs/srikar/lib/python3.6/site-packages/ray/worker.py", line 2322, in wait
    worker.current_task_id,
KeyboardInterrupt
