Traceback (most recent call last):
  File "/home/beast/anaconda3/envs/srikar/lib/python3.6/site-packages/redis/connection.py", line 182, in _read_from_socket
    data = recv(self._sock, socket_read_size)
  File "/home/beast/anaconda3/envs/srikar/lib/python3.6/site-packages/redis/_compat.py", line 58, in recv
    return sock.recv(*args, **kwargs)
TimeoutError: [Errno 110] Connection timed out

During handling of the above exception, another exception occurred:

Traceback (most recent call last):
  File "/home/beast/anaconda3/envs/srikar/lib/python3.6/site-packages/ray/monitor.py", line 381, in <module>
    monitor.run()
  File "/home/beast/anaconda3/envs/srikar/lib/python3.6/site-packages/ray/monitor.py", line 327, in run
    self._run()
  File "/home/beast/anaconda3/envs/srikar/lib/python3.6/site-packages/ray/monitor.py", line 310, in _run
    self.update_raylet_map()
  File "/home/beast/anaconda3/envs/srikar/lib/python3.6/site-packages/ray/monitor.py", line 253, in update_raylet_map
    all_raylet_nodes = ray.nodes()
  File "/home/beast/anaconda3/envs/srikar/lib/python3.6/site-packages/ray/state.py", line 991, in nodes
    return state.client_table()
  File "/home/beast/anaconda3/envs/srikar/lib/python3.6/site-packages/ray/state.py", line 386, in client_table
    return _parse_client_table(self.redis_client)
  File "/home/beast/anaconda3/envs/srikar/lib/python3.6/site-packages/ray/state.py", line 36, in _parse_client_table
    NIL_CLIENT_ID)
  File "/home/beast/anaconda3/envs/srikar/lib/python3.6/site-packages/redis/client.py", line 775, in execute_command
    return self.parse_response(connection, command_name, **options)
  File "/home/beast/anaconda3/envs/srikar/lib/python3.6/site-packages/redis/client.py", line 789, in parse_response
    response = connection.read_response()
  File "/home/beast/anaconda3/envs/srikar/lib/python3.6/site-packages/redis/connection.py", line 637, in read_response
    response = self._parser.read_response()
  File "/home/beast/anaconda3/envs/srikar/lib/python3.6/site-packages/redis/connection.py", line 290, in read_response
    response = self._buffer.readline()
  File "/home/beast/anaconda3/envs/srikar/lib/python3.6/site-packages/redis/connection.py", line 224, in readline
    self._read_from_socket()
  File "/home/beast/anaconda3/envs/srikar/lib/python3.6/site-packages/redis/connection.py", line 199, in _read_from_socket
    (e.args,))
redis.exceptions.ConnectionError: Error while reading from socket: (110, 'Connection timed out')

During handling of the above exception, another exception occurred:

Traceback (most recent call last):
  File "/home/beast/anaconda3/envs/srikar/lib/python3.6/site-packages/redis/connection.py", line 492, in connect
    sock = self._connect()
  File "/home/beast/anaconda3/envs/srikar/lib/python3.6/site-packages/redis/connection.py", line 550, in _connect
    raise err
  File "/home/beast/anaconda3/envs/srikar/lib/python3.6/site-packages/redis/connection.py", line 538, in _connect
    sock.connect(socket_address)
OSError: [Errno 113] No route to host

During handling of the above exception, another exception occurred:

Traceback (most recent call last):
  File "/home/beast/anaconda3/envs/srikar/lib/python3.6/site-packages/ray/monitor.py", line 390, in <module>
    redis_client, ray_constants.MONITOR_DIED_ERROR, message)
  File "/home/beast/anaconda3/envs/srikar/lib/python3.6/site-packages/ray/utils.py", line 100, in push_error_to_driver_through_redis
    error_data)
  File "/home/beast/anaconda3/envs/srikar/lib/python3.6/site-packages/redis/client.py", line 772, in execute_command
    connection = pool.get_connection(command_name, **options)
  File "/home/beast/anaconda3/envs/srikar/lib/python3.6/site-packages/redis/connection.py", line 994, in get_connection
    connection.connect()
  File "/home/beast/anaconda3/envs/srikar/lib/python3.6/site-packages/redis/connection.py", line 497, in connect
    raise ConnectionError(self._error_message(e))
redis.exceptions.ConnectionError: Error 113 connecting to 192.168.2.30:59160. No route to host.
